Workbook

Sheet 📋 НАВИГАЦИЯ
A1: ФИНАНСОВАЯ МОДЕЛЬ — КОФЕЙНЯ: КОФЕ С СОБОЙ
A2: Город: Актобе | Горизонт: 36 месяцев (3 года) | Дата: 04.04.2026
B3: СОДЕРЖАНИЕ
A5: 1 | B5: 📖 КАК ЧИТАТЬ МОДЕЛЬ | C5: Объяснение модели для начинающих
A6: 2 | B6: ⚙️ ПАРАМЕТРЫ | C6: Все ваши входные данные (жёлтые ячейки)
A7: 3 | B7: 📊 ДОПУЩЕНИЯ | C7: Сезонность, инфляция, налоговый каскад
A8: 4 | B8: 🎯 ДАШБОРД | C8: Ключевые показатели + автодиагностика
A9: 5 | B9: 📈 P&L | C9: Помесячный отчёт о прибылях и убытках
A10: 6 | B10: 💰 CASH FLOW | C10: Движение денежных средств
A11: 7 | B11: 📋 КРЕДИТ | C11: График погашения кредита
A12: 8 | B12: 📑 БАЛАНС | C12: Квартальный баланс
A13: 9 | B13: 🔄 СЦЕНАРИИ | C13: 5 сценариев чувствительности
A14: 10 | B14: ✅ ПРОВЕРКА | C14: 10 автоматических проверок
A15: 11 | B15: 🔥 СТРЕСС-ТЕСТ
B16: ИНСТРУКЦИЯ
A17: 1 | B17: Откройте ⚙️ ПАРАМЕТРЫ — введите данные в жёлтые ячейки
A18: 2 | B18: Настройте 📊 ДОПУЩЕНИЯ — сезонность под ваш регион
A19: 3 | B19: Результаты на 🎯 ДАШБОРДЕ — автоматически
A20: 4 | B20: 📈 P&L и 💰 CASH FLOW — помесячная детализация
A21: 5 | B21: 🔄 ЧУВСТВИТЕЛЬНОСТЬ — стресс-тест параметров
A22: 6 | B22: ✅ ПРОВЕРКА — все формулы должны показать OK
A23: 7 | B23: 🔥 СТРЕСС-ТЕСТ — 4 сценария стресс-тестирования
B26: Сформировано: ZEREK — аналитика для предпринимателей КЗ | 04.04.2026 | @zerekai_bot

Sheet 📖 КАК ЧИТАТЬ МОДЕЛЬ
B1: КАК ПОЛЬЗОВАТЬСЯ ЭТОЙ МОДЕЛЬЮ
B2: 📌 Модель полностью автоматическая. Вам нужно только заполнить жёлтые ячейки — всё остальное пересчитается.
A4: 1️⃣ | B4: ЗАПОЛНИТЕ ⚙️ ПАРАМЕТРЫ
B5: Все жёлтые ячейки — это ваши данные. Средний чек, аренда, зарплаты, стартовые вложения. Меняйте их под свой бизнес.
A7: 2️⃣ | B7: НАСТРОЙТЕ 📊 ДОПУЩЕНИЯ
B8: Сезонность и ramp-up (выход на мощность). Если не уверены — оставьте как есть, значения по умолчанию реалистичны.
A10: 3️⃣ | B10: СМОТРИТЕ 🎯 ДАШБОРД
B11: Главные цифры: окупаемость, прибыль, риски. Всё пересчитывается автоматически при изменении параметров.
A13: 4️⃣ | B13: ЧТО ОЗНАЧАЮТ ПОКАЗАТЕЛИ
B14: • NPV > 0 → проект создаёт стоимость (хорошо)
B15: • IRR > 20% → доходность выше банковского депозита (отлично)
B16: • Окупаемость < 18 мес → быстро вернёте вложения
B17: • Точка безубыточности → минимум клиентов, чтобы не работать в убыток
B18: • Запас прочности → на сколько % может упасть выручка, прежде чем убытки
A20: 5️⃣ | B20: СТРЕСС-ТЕСТ 🔥
B21: Показывает, что будет если дела пойдут хуже ожиданий.
B22: Если даже в «жёстком» сценарии бизнес прибыльный — вы в безопасности.
A24: 6️⃣ | B24: ДИСКЛЕЙМЕР
B25: Модель — аналитический инструмент, не гарантия результата.
B26: Реальные цифры могут отличаться от прогноза. ZEREK не несёт ответственности за бизнес-решения.
B28: ZEREK Financial Model | @zerekai_bot | zerek.cc

Sheet ⚙️ ПАРАМЕТРЫ
A1: ПАРАМЕТРЫ МОДЕЛИ — КОФЕЙНЯ: КОФЕ С СОБОЙ
A2: 📌 Правило: меняйте только жёлтые ячейки. Синий текст = введённое число. Чёрный текст = формула (не трогать). Все листы пересчитываются автоматически.
A3: 0. ОБЩИЕ ПАРАМЕТРЫ
B4: Параметр | C4: Значение | D4: Ед. | E4: Пояснение (дисклеймер)
B5: Форма собственности | C5: ИП | E5: 💡 ИП: свободный вывод. ТОО: дивиденды (5% ИПН)
B6: Налоговый режим | C6: УСН | E6: 💡 УСН: 2-4% от оборота. Порог: 600 000 МРП
B7: Плательщик НДС | C7: Нет | E7: 💡 Автоматически «Да» при выручке > 10 000 МРП
B8: Ставка налога (маслихат) | C8: 0.03 | D8: % | E8: 💡 Ставка маслихата. Актобе: 3%
B9: Горизонт модели | C9: 36 | D9: мес | E9: 💡 36 мес = 3 года. Стандарт для МСБ
A10: 1. ВЫРУЧКА
B11: Параметр | C11: Значение | D11: Ед. | E11: Пояснение (дисклеймер)
B12: Средний чек (корзина) | C12: 1400 | D12: ₸ | E12: 💡 Вся покупка 1 клиента целиком
B13: Клиентов в день (на полной мощности) | C13: 70 | D13: чел/день | E13: 💡 Трафик после ramp-up
B14: Рабочих дней в месяце | C14: 30 | D14: дней | E14: 💡 Общепит = 30, офис = 22
B15: Рост трафика в год | C15: 0.07 | D15: % | E15: 💡 5-10% для МСБ
B16: Рост среднего чека в год | C16: 0.08 | D16: % | E16: 💡 Инфляция + допродажи ≈ 8%
A17: 2. ПРЯМЫЕ РАСХОДЫ
B18: Параметр | C18: Значение | D18: Ед. | E18: Пояснение (дисклеймер)
B19: Себестоимость (% от выручки) | C19: 0.35 | D19: % | E19: 💡 Общепит: 30-40%, услуги: 5-15%
B20: Потери и списания (% от выручки) | C20: 0.03 | D20: % | E20: 💡 Брак, просрочка. Общепит: 3-5%
A21: 3. ПОСТОЯННЫЕ РАСХОДЫ
B22: Параметр | C22: Значение | D22: Ед. | E22: Пояснение (дисклеймер)
B23: Аренда помещения | C23: 70000 | D23: ₸/мес | E23: 💡 Актобе: ~3000-5000 ₸/м²
B24: Площадь помещения | C24: 6 | D24: м² | E24: 💡 Типовая площадь для формата
B25: ФОТ Gross (оклад сотрудников) | C25: 200000 | D25: ₸/мес | E25: 💡 Gross = до удержаний
B26: Количество сотрудников | C26: 2 | D26: чел | E26: 💡 Штат на полную мощность
B27: Коммунальные | C27: 15000 | D27: ₸/мес | E27: 💡 Свет, вода, отопление
B28: Маркетинг | C28: 50000 | D28: ₸/мес | E28: 💡 Instagram, 2ГИС, акции
B29: Расходники | C29: 3500 | D29: ₸/мес | E29: 💡 Мелочи вне себестоимости
B30: Софт / касса / CRM | C30: 5000 | D30: ₸/мес | E30: 💡 Kaspi касса, iiko, Poster
B31: Прочие расходы | C31: 10000 | D31: ₸/мес | E31: 💡 Транспорт, связь, непредвиденные
B32: Рост аренды в год | C32: ='📊 ДОПУЩЕНИЯ'!C9 -> 0.1 | D32: % | E32: 💡 ← Ссылка на ДОПУЩЕНИЯ. Меняйте там.
B33: Рост ФОТ в год | C33: ='📊 ДОПУЩЕНИЯ'!C10 -> 0.08 | D33: % | E33: 💡 ← Ссылка на ДОПУЩЕНИЯ. Меняйте там.
B34: Инфляция прочих расходов | C34: ='📊 ДОПУЩЕНИЯ'!C12 -> 0.08 | D34: % | E34: 💡 ← Ссылка на ДОПУЩЕНИЯ. Меняйте там.
A35: 4. СТАРТОВЫЕ ИНВЕСТИЦИИ
B36: Параметр | C36: Значение | D36: Ед. | E36: Пояснение (дисклеймер)
B37: CAPEX (оборудование + ремонт) | C37: 1500000 | D37: ₸ | E37: 💡 Оборудование + ремонт + мебель
B38: Депозит за аренду | C38: 2 | D38: мес | E38: 💡 Залог. Обычно 2-3 мес
B39: Оборотный капитал (резерв) | C39: 1000000 | D39: ₸ | E39: 💡 Резерв на 2-3 мес расходов
B40: Срок амортизации | C40: 7 | D40: лет | E40: 💡 Линейная. Оборудование: 5-7 лет
...

Sheet 📊 ДОПУЩЕНИЯ
A1: ДОПУЩЕНИЯ МОДЕЛИ
A2: 📌 Сезонные коэффициенты: 1.00 = норма, 1.10 = на 10% выше, 0.85 = на 15% ниже. Казахстан — резко континентальный климат: жаркое лето, холодная зима.
A3: СЕЗОННОСТЬ ТРАФИКА
B4: Месяц | C4: Янв | D4: Фев | E4: Мар | F4: Апр | G4: Май | H4: Июн | I4: Июл | J4: Авг | K4: Сен | L4: Окт | M4: Ноя | N4: Дек
B5: Коэффициент | C5: 0.85 | D5: 0.85 | E5: 0.9 | F5: 1 | G5: 1.05 | H5: 1.1 | I5: 1.1 | J5: 1.05 | K5: 1 | L5: 0.95 | M5: 0.95 | N5: 1.2
B6: 💡 Коэффициенты умножаются на базовый трафик. 1.15 в декабре = праздничный спрос +15%. 0.85 зимой = холод, меньше пешеходов.
A7: ИНФЛЯЦИЯ ПО СТАТЬЯМ
B8: Статья | C8: Рост/год | D8: Пояснение
B9: Аренда | C9: 0.1 | D9: 💡 Арендодатели КЗ индексируют ежегодно. Зависит от договора
B10: ФОТ | C10: 0.08 | D10: 💡 Рост зарплат. В КЗ ~8% в год
B11: Продукты/материалы | C11: 0.12 | D11: 💡 Продовольственная инфляция в КЗ выше общей: 10-15%
B12: Коммунальные | C12: 0.08 | D12: 💡 Тарифы регулируются, растут медленнее
B13: Маркетинг | C13: 0.05 | D13: 💡 Цифровая реклама дорожает медленнее
A15: RAMP-UP (ВЫХОД НА МОЩНОСТЬ)
B16: Месяц модели | C16: М1 | D16: М2 | E16: М3 | F16: М4 | G16: М5 | H16: М6 | I16: М7 | J16: М8 | K16: М9 | L16: М10 | M16: М11 | N16: М12
B17: Год 1 (% от мощности) | C17: 0.4 | D17: 0.7 | E17: 1 | F17: 1 | G17: 1 | H17: 1 | I17: 1 | J17: 1 | K17: 1 | L17: 1 | M17: 1 | N17: 1
B18: Год 2 (% от мощности) | C18: 1 | D18: 1 | E18: 1 | F18: 1 | G18: 1 | H18: 1 | I18: 1 | J18: 1 | K18: 1 | L18: 1 | M18: 1 | N18: 1
B19: Год 3 (% от мощности) | C19: 1 | D19: 1 | E19: 1 | F19: 1 | G19: 1 | H19: 1 | I19: 1 | J19: 1 | K19: 1 | L19: 1 | M19: 1 | N19: 1
B20: 💡 Ramp-up = % от полной мощности. М1=40% → 28 клиентов из 70 возможных. 100% = полная мощность. Год 2-3 можно оставить 100% или задать плавный рост.
A23: НАЛОГОВАЯ СИСТЕМА РК (2026)
A24: СПРАВОЧНЫЕ ДАННЫЕ
B25: Параметр | C25: Значение | D25: Ед. | E25: Примечание
B26: МРП (2026) | C26: 4325 | D26: ₸ | E26: Месячный расчётный показатель (Закон о бюджете)
B27: Порог НДС | C27: =C26*10000 -> 43250000 | D27: ₸ | E27: = 10 000 × МРП. ОУР: превышение → обязат. НДС
B28: Лимит выручки УСН | C28: =C26*600000 -> 2595000000 | D28: ₸ | E28: = 600 000 × МРП. Макс. оборот для УСН
B29: Порог прогр. шкалы ИПН | C29: =C26*230000 -> 994750000 | D29: ₸ | E29: = 230 000 × МРП. До порога 10%, свыше 15%
A31: ЗАРПЛАТНЫЕ НАЛОГИ И ОТЧИСЛЕНИЯ
B32: Удержания с работника (внутри Gross)
B33: ИПН | C33: 0.1 | E33: 10% от оклада (ст. 320 НК РК)
B34: ОПВ | C34: 0.1 | E34: 10% от оклада в ЕНПФ
B35: ВОСМС | C35: 0.02 | E35: 2% от оклада
B36: Налоги работодателя (сверх оклада)
B37: ОСМС | C37: 0.03 | E37: 3% от оклада
B38: ОПВР | C38: 0.035 | E38: 3.5% от оклада (с 2024)
B39: СО | C39: 0.035 | E39: 3.5% от оклада
B40: СН | C40: 0.095 | E40: 9.5% − СО при ОУР. На УСН = 0
A42: КОРПОРАТИВНЫЕ НАЛОГИ
B43: Ставка УСН (НК макс.) | C43: 0.04 | E43: 4% от оборота (ст. 687)
B44: Ставка НДС | C44: 0.16 | E44: 16% с 2025 (ст. 422 НК)
B45: КПН (ТОО на ОУР) | C45: 0.2 | E45: 20% от дохода (ст. 313 НК)
...

Sheet 🎯 ДАШБОРД
A1: ДАШБОРД — КОФЕЙНЯ: КОФЕ С СОБОЙ (Актобе)
A2: Дата: 04.04.2026 | Горизонт: 36 мес | Все показатели обновляются автоматически
A3: КЛЮЧЕВЫЕ ИНВЕСТИЦИОННЫЕ ПОКАЗАТЕЛИ
B4: NPV | C4: IRR | D4: Окупаемость | E4: ROI
B5: =NPV('⚙️ ПАРАМЕТРЫ'!C52/12,'💰 CASH FLOW'!C25:AL25)+'💰 CASH FLOW'!B25 -> 31863328 | C5: =IFERROR(IRR('💰 CASH FLOW'!B25:AL25),0) -> 0.31820615 | D5: {=IFERROR(MATCH(1,('💰 CASH FLOW'!C26:AL26>=0)*1,0),">36")} -> 4 | E5: =IFERROR(SUM('💰 CASH FLOW'!C25:AL25)/(-'💰 CASH FLOW'!B25),0) -> 18.025752
B6: Чистая приведённая стоимость проекта. NPV > 0 → проект выгоден | C6: Месячная доходность проекта. Сравните с WACC/12 (1.7%/мес) | D6: Через сколько месяцев вернёте вложения (все инвестиции) | E6: Прибыль за 3 года / все инвестиции. >100% = вложения вернулись
A8: СВОДНЫЙ P&L ЗА 3 ГОДА
B9: Показатель | C9: Итого 36 мес | D9: ₸/мес (средн.) | E9: % от выручки
B10: Выручка | C10: =SUM('📈 P&L'!C12:AL12) -> 120485040 | D10: =IFERROR(C10/36,"") -> 3346806.7 | E10: =IFERROR(C10/SUM('📈 P&L'!C12:AL12),"") -> 1
B11: ▸ Себестоимость | C11: =SUM('📈 P&L'!C14:AL14) -> 42169764 | D11: =IFERROR(C11/36,"") -> 1171382.3 | E11: =IFERROR(C11/SUM('📈 P&L'!C12:AL12),"") -> 0.35
B12: ▸ Потери | C12: =SUM('📈 P&L'!C15:AL15) -> 3614553 | D12: =IFERROR(C12/36,"") -> 100404.25 | E12: =IFERROR(C12/SUM('📈 P&L'!C12:AL12),"") -> 0.030000015
B13: Валовая прибыль | C13: =SUM('📈 P&L'!C16:AL16) -> 74700723 | D13: =IFERROR(C13/36,"") -> 2075020.1 | E13: =IFERROR(C13/SUM('📈 P&L'!C12:AL12),"") -> 0.61999999
B14: ▸ ФОТ | C14: =SUM('📈 P&L'!C18:AL18) -> 15582720 | D14: =IFERROR(C14/36,"") -> 432853.33 | E14: =IFERROR(C14/SUM('📈 P&L'!C12:AL12),"") -> 0.12933324
B15: ▸ Аренда | C15: =SUM('📈 P&L'!C24:AL24) -> 2780400 | D15: =IFERROR(C15/36,"") -> 77233.333 | E15: =IFERROR(C15/SUM('📈 P&L'!C12:AL12),"") -> 0.023076724
B16: ▸ Прочие пост. | C16: =SUM('📈 P&L'!C25:AL25)+SUM('📈 P&L'!C26:AL26)+SUM('📈 P&L'!C27:AL27)+SUM('📈 P&L'!C28:AL28)+SUM('📈 P&L'!C29:AL29) -> 3201924 | D16: =IFERROR(C16/36,"") -> 88942.333 | E16: =IFERROR(C16/SUM('📈 P&L'!C12:AL12),"") -> 0.026575283
B17: EBITDA | C17: =SUM('📈 P&L'!C31:AL31) -> 51577395 | D17: =IFERROR(C17/36,"") -> 1432705.4 | E17: =IFERROR(C17/SUM('📈 P&L'!C12:AL12),"") -> 0.42808132
B18: Налог | C18: =SUM('📈 P&L'!C35:AL35) -> 3614553 | D18: =IFERROR(C18/36,"") -> 100404.25 | E18: =IFERROR(C18/SUM('📈 P&L'!C12:AL12),"") -> 0.030000015
B19: ЧИСТАЯ ПРИБЫЛЬ | C19: =SUM('📈 P&L'!C38:AL38) -> 46945134 | D19: =IFERROR(C19/36,"") -> 1304031.5 | E19: =IFERROR(C19/SUM('📈 P&L'!C12:AL12),"") -> 0.38963454
A21: АВТОМАТИЧЕСКИЙ ВЫВОД
B22: =IF(B5>0,"✅ NPV положительный — проект создаёт стоимость.","❌ NPV отрицательный — проект разрушает стоимость.") -> ✅ NPV положительный — проект создаёт стоимость.
B23: =IF(C5>'⚙️ ПАРАМЕТРЫ'!C52/12,"✅ IRR выше WACC — проект привлекателен для инвестора.","⚠️ IRR ниже WACC — доходность не покрывает риски.") -> ✅ IRR выше WACC — проект привлекателен для инвестора.
B24: =IF(D5<=18,"✅ Окупаемость до 18 мес — отличный показатель.",IF(D5<=30,"⚠️ Окупаемость 18-30 мес — приемлемо.","❌ Окупаемость >30 мес — высокий риск.")) -> ✅ Окупаемость до 18 мес — отличный показатель.
A26: ДОПОЛНИТЕЛЬНЫЕ МЕТРИКИ
B27: Стартовые вложения (ИТОГО) | C27: ='⚙️ ПАРАМЕТРЫ'!C41 -> 2640000 | D27: ₸
B28: Точка безубыточности | C28: ='🔥 СТРЕСС-ТЕСТ'!C59 -> 26 | D28: клиентов/день
B29: Запас ликвидности (мин. ДС) | C29: =MIN('💰 CASH FLOW'!C22:AL22) -> -1577850.5 | D29: ₸
B30: Кассовый разрыв? | C30: =IF(MIN('💰 CASH FLOW'!C22:AL22)<0,"ДА 🔴","НЕТ ✅") -> ДА 🔴
B31: Главный риск (макс. негативный фактор) | C31: =INDEX('🔥 СТРЕСС-ТЕСТ'!B46:B50,MATCH(MIN('🔥 СТРЕСС-ТЕСТ'!E46:E50),'🔥 СТРЕСС-ТЕСТ'!E46:E50,0)) -> Трафик − 20%
B32: Главный драйвер роста | C32: =INDEX('🔥 СТРЕСС-ТЕСТ'!B46:B50,MATCH(MAX('🔥 СТРЕСС-ТЕСТ'!E46:E50),'🔥 СТРЕСС-ТЕСТ'!E46:E50,0)) -> Аренда + 20%
A34: ДИАГНОЗ МОДЕЛИ
B35: =IF(AND(B5>0,D5<=24,C30="НЕТ ✅"),"✅ Проект жизнеспособен. NPV+, окупаемость в норме, разрывов нет.","❌ Есть зоны риска — см. ниже.") -> ❌ Есть зоны риска — см. ниже.
B36: =IF(D5>30,"❌ Окупаемость > 30 мес → снизьте CAPEX или поднимите чек.",IF(D5>18,"⚠️ Окупаемость "&D5&" мес → ищите допродажи и лояльность.","✅ Окупаемость "&D5&" мес — норма.")) -> ✅ Окупаемость 4 мес — норма.
B37: =IF(IFERROR(AVERAGE('📈 P&L'!O24:Z24)/AVERAGE('📈 P&L'!O12:Z12),0)>0.25,"⚠️ Аренда > 25% выручки → торгуйтесь или меняйте локацию.","✅ Аренда в норме.") -> ✅ Аренда в норме.
B38: =IF(IFERROR(C17/C10,0)<0.1,"⚠️ EBITDA < 10% → режьте постоянные или поднимайте чек.","✅ EBITDA маржа здоровая.") -> ✅ EBITDA маржа здоровая.
B39: =IF(C30="ДА 🔴","❌ Кассовый разрыв! → добавьте "&TEXT(ABS(C29),"# ##0")&" ₸ оборотки.","✅ Разрывов нет. Мин. остаток: "&TEXT(C29,"# ##0")&" ₸.") -> ❌ Кассовый разрыв! → добавьте 1 577 850 ₸ оборотки.
A41: ZEREK | 04.04.2026

Sheet 📈 P&L
A1: ОТЧЁТ О ПРИБЫЛЯХ И УБЫТКАХ — КОФЕЙНЯ: КОФЕ С СОБОЙ (Актобе)
A2: 📌 Помесячно, 36 мес. Формулы → ⚙️ ПАРАМЕТРЫ и 📊 ДОПУЩЕНИЯ.
B3: Статья / Период | C3: М1 | D3: М2 | E3: М3 | F3: М4 | G3: М5 | H3: М6 | I3: М7 | J3: М8 | K3: М9 | L3: М10 | M3: М11 | N3: М12 | O3: М13 | P3: М14 | Q3: М15 | R3: М16 | S3: М17 | T3: М18 | U3: М19 | V3: М20 | W3: М21 | X3: М22 | Y3: М23 | Z3: М24 | AA3: М25 | AB3: М26 | AC3: М27 | AD3: М28 | AE3: М29 | AF3: М30 | AG3: М31 | AH3: М32 | AI3: М33 | AJ3: М34 | AK3: М35 | AL3: М36
B4: Кал. месяц | C4: =MOD(1-1+3,12)+1 -> 4 | D4: =MOD(2-1+3,12)+1 -> 5 | E4: =MOD(3-1+3,12)+1 -> 6 | F4: =MOD(4-1+3,12)+1 -> 7 | G4: =MOD(5-1+3,12)+1 -> 8 | H4: =MOD(6-1+3,12)+1 -> 9 | I4: =MOD(7-1+3,12)+1 -> 10 | J4: =MOD(8-1+3,12)+1 -> 11 | K4: =MOD(9-1+3,12)+1 -> 12 | L4: =MOD(10-1+3,12)+1 -> 1 | M4: =MOD(11-1+3,12)+1 -> 2 | N4: =MOD(12-1+3,12)+1 -> 3 | O4: =MOD(13-1+3,12)+1 -> 4 | P4: =MOD(14-1+3,12)+1 -> 5 | Q4: =MOD(15-1+3,12)+1 -> 6 | R4: =MOD(16-1+3,12)+1 -> 7 | S4: =MOD(17-1+3,12)+1 -> 8 | T4: =MOD(18-1+3,12)+1 -> 9 | U4: =MOD(19-1+3,12)+1 -> 10 | V4: =MOD(20-1+3,12)+1 -> 11 | W4: =MOD(21-1+3,12)+1 -> 12 | X4: =MOD(22-1+3,12)+1 -> 1 | Y4: =MOD(23-1+3,12)+1 -> 2 | Z4: =MOD(24-1+3,12)+1 -> 3 | AA4: =MOD(25-1+3,12)+1 -> 4 | AB4: =MOD(26-1+3,12)+1 -> 5 | AC4: =MOD(27-1+3,12)+1 -> 6 | AD4: =MOD(28-1+3,12)+1 -> 7 | AE4: =MOD(29-1+3,12)+1 -> 8 | AF4: =MOD(30-1+3,12)+1 -> 9 | AG4: =MOD(31-1+3,12)+1 -> 10 | AH4: =MOD(32-1+3,12)+1 -> 11 | AI4: =MOD(33-1+3,12)+1 -> 12 | AJ4: =MOD(34-1+3,12)+1 -> 1 | AK4: =MOD(35-1+3,12)+1 -> 2 | AL4: =MOD(36-1+3,12)+1 -> 3
B5: Сез. коэфф. | C5: =INDEX('📊 ДОПУЩЕНИЯ'!$C$5:$N$5,1,C4) -> 1 | D5: =INDEX('📊 ДОПУЩЕНИЯ'!$C$5:$N$5,1,D4) -> 1.05 | E5: =INDEX('📊 ДОПУЩЕНИЯ'!$C$5:$N$5,1,E4) -> 1.1 | F5: =INDEX('📊 ДОПУЩЕНИЯ'!$C$5:$N$5,1,F4) -> 1.1 | G5: =INDEX('📊 ДОПУЩЕНИЯ'!$C$5:$N$5,1,G4) -> 1.05 | H5: =INDEX('📊 ДОПУЩЕНИЯ'!$C$5:$N$5,1,H4) -> 1 | I5: =INDEX('📊 ДОПУЩЕНИЯ'!$C$5:$N$5,1,I4) -> 0.95 | J5: =INDEX('📊 ДОПУЩЕНИЯ'!$C$5:$N$5,1,J4) -> 0.95 | ... AL5: =INDEX('📊 ДОПУЩЕНИЯ'!$C$5:$N$5,1,AL4) -> 0.9
B6: Ramp-up | C6: {=INDEX('📊 ДОПУЩЕНИЯ'!$C$17:$N$19,INT((COLUMN()-3)/12)+1,MOD(COLUMN()-3,12)+1)} -> 0.4 | D6: {=INDEX('📊 ДОПУЩЕНИЯ'!$C$17:$N$19,INT((COLUMN()-3)/12)+1,MOD(COLUMN()-3,12)+1)} -> 0.7 | E6: {=INDEX('📊 ДОПУЩЕНИЯ'!$C$17:$N$19,INT((COLUMN()-3)/12)+1,MOD(COLUMN()-3,12)+1)} -> 1 | F6: {=INDEX('📊 ДОПУЩЕНИЯ'!$C$17:$N$19,INT((COLUMN()-3)/12)+1,MOD(COLUMN()-3,12)+1)} -> 1 | G6: {=INDEX('📊 ДОПУЩЕНИЯ'!$C$17:$N$19,INT((COLUMN()-3)/12)+1,MOD(COLUMN()-3,12)+1)} -> 1 | H6: {=INDEX('📊 ДОПУЩЕНИЯ'!$C$17:$N$19,INT((COLUMN()-3)/12)+1,MOD(COLUMN()-3,12)+1)} -> 1 | I6: {=INDEX('📊 ДОПУЩЕНИЯ'!$C$17:$N$19,INT((COLUMN()-3)/12)+1,MOD(COLUMN()-3,12)+1)} -> 1 | J6: {=INDEX('📊 ДОПУЩЕНИЯ'!$C$17:$N$19,INT((COLUMN()-3)/12)+1,MOD(COLUMN()-3,12)+1)} -> 1 | ... AL6: {=INDEX('📊 ДОПУЩЕНИЯ'!$C$17:$N$19,INT((COLUMN()-3)/12)+1,MOD(COLUMN()-3,12)+1)} -> 1
B7: ВЫРУЧКА
B8: Множитель роста трафика | C8: =(1+'⚙️ ПАРАМЕТРЫ'!$C$15)^INT((1-1)/12) -> 1 | D8: =(1+'⚙️ ПАРАМЕТРЫ'!$C$15)^INT((2-1)/12) -> 1 | E8: =(1+'⚙️ ПАРАМЕТРЫ'!$C$15)^INT((3-1)/12) -> 1 | F8: =(1+'⚙️ ПАРАМЕТРЫ'!$C$15)^INT((4-1)/12) -> 1 | G8: =(1+'⚙️ ПАРАМЕТРЫ'!$C$15)^INT((5-1)/12) -> 1 | H8: =(1+'⚙️ ПАРАМЕТРЫ'!$C$15)^INT((6-1)/12) -> 1 | I8: =(1+'⚙️ ПАРАМЕТРЫ'!$C$15)^INT((7-1)/12) -> 1 | J8: =(1+'⚙️ ПАРАМЕТРЫ'!$C$15)^INT((8-1)/12) -> 1 | K8: =(1+'⚙️ ПАРАМЕТРЫ'!$C$15)^INT((9-1)/12) -> 1 | L8: =(1+'⚙️ ПАРАМЕТРЫ'!$C$15)^INT((10-1)/12) -> 1 | M8: =(1+'⚙️ ПАРАМЕТРЫ'!$C$15)^INT((11-1)/12) -> 1 | N8: =(1+'⚙️ ПАРАМЕТРЫ'!$C$15)^INT((12-1)/12) -> 1 | O8: =(1+'⚙️ ПАРАМЕТРЫ'!$C$15)^INT((13-1)/12) -> 1.07 | P8: =(1+'⚙️ ПАРАМЕТРЫ'!$C$15)^INT((14-1)/12) -> 1.07 | Q8: =(1+'⚙️ ПАРАМЕТРЫ'!$C$15)^INT((15-1)/12) -> 1.07 | R8: =(1+'⚙️ ПАРАМЕТРЫ'!$C$15)^INT((16-1)/12) -> 1.07 | S8: =(1+'⚙️ ПАРАМЕТРЫ'!$C$15)^INT((17-1)/12) -> 1.07 | T8: =(1+'⚙️ ПАРАМЕТРЫ'!$C$15)^INT((18-1)/12) -> 1.07 | U8: =(1+'⚙️ ПАРАМЕТРЫ'!$C$15)^INT((19-1)/12) -> 1.07 | V8: =(1+'⚙️ ПАРАМЕТРЫ'!$C$15)^INT((20-1)/12) -> 1.07 | W8: =(1+'⚙️ ПАРАМЕТРЫ'!$C$15)^INT((21-1)/12) -> 1.07 | X8: =(1+'⚙️ ПАРАМЕТРЫ'!$C$15)^INT((22-1)/12) -> 1.07 | Y8: =(1+'⚙️ ПАРАМЕТРЫ'!$C$15)^INT((23-1)/12) -> 1.07 | Z8: =(1+'⚙️ ПАРАМЕТРЫ'!$C$15)^INT((24-1)/12) -> 1.07 | AA8: =(1+'⚙️ ПАРАМЕТРЫ'!$C$15)^INT((25-1)/12) -> 1.1449 | AB8: =(1+'⚙️ ПАРАМЕТРЫ'!$C$15)^INT((26-1)/12) -> 1.1449 | AC8: =(1+'⚙️ ПАРАМЕТРЫ'!$C$15)^INT((27-1)/12) -> 1.1449 | AD8: =(1+'⚙️ ПАРАМЕТРЫ'!$C$15)^INT((28-1)/12) -> 1.1449 | AE8: =(1+'⚙️ ПАРАМЕТРЫ'!$C$15)^INT((29-1)/12) -> 1.1449 | AF8: =(1+'⚙️ ПАРАМЕТРЫ'!$C$15)^INT((30-1)/12) -> 1.1449 | AG8: =(1+'⚙️ ПАРАМЕТРЫ'!$C$15)^INT((31-1)/12) -> 1.1449 | AH8: =(1+'⚙️ ПАРАМЕТРЫ'!$C$15)^INT((32-1)/12) -> 1.1449 | AI8: =(1+'⚙️ ПАРАМЕТРЫ'!$C$15)^INT((33-1)/12) -> 1.1449 | AJ8: =(1+'⚙️ ПАРАМЕТРЫ'!$C$15)^INT((34-1)/12) -> 1.1449 | AK8: =(1+'⚙️ ПАРАМЕТРЫ'!$C$15)^INT((35-1)/12) -> 1.1449 | AL8: =(1+'⚙️ ПАРАМЕТРЫ'!$C$15)^INT((36-1)/12) -> 1.1449
B9: Множитель роста чека | C9: =(1+'⚙️ ПАРАМЕТРЫ'!$C$16)^INT((1-1)/12) -> 1 | D9: =(1+'⚙️ ПАРАМЕТРЫ'!$C$16)^INT((2-1)/12) -> 1 | E9: =(1+'⚙️ ПАРАМЕТРЫ'!$C$16)^INT((3-1)/12) -> 1 | F9: =(1+'⚙️ ПАРАМЕТРЫ'!$C$16)^INT((4-1)/12) -> 1 | G9: =(1+'⚙️ ПАРАМЕТРЫ'!$C$16)^INT((5-1)/12) -> 1 | H9: =(1+'⚙️ ПАРАМЕТРЫ'!$C$16)^INT((6-1)/12) -> 1 | I9: =(1+'⚙️ ПАРАМЕТРЫ'!$C$16)^INT((7-1)/12) -> 1 | J9: =(1+'⚙️ ПАРАМЕТРЫ'!$C$16)^INT((8-1)/12) -> 1 | K9: =(1+'⚙️ ПАРАМЕТРЫ'!$C$16)^INT((9-1)/12) -> 1 | L9: =(1+'⚙️ ПАРАМЕТРЫ'!$C$16)^INT((10-1)/12) -> 1 | M9: =(1+'⚙️ ПАРАМЕТРЫ'!$C$16)^INT((11-1)/12) -> 1 | N9: =(1+'⚙️ ПАРАМЕТРЫ'!$C$16)^INT((12-1)/12) -> 1 | O9: =(1+'⚙️ ПАРАМЕТРЫ'!$C$16)^INT((13-1)/12) -> 1.08 | P9: =(1+'⚙️ ПАРАМЕТРЫ'!$C$16)^INT((14-1)/12) -> 1.08 | Q9: =(1+'⚙️ ПАРАМЕТРЫ'!$C$16)^INT((15-1)/12) -> 1.08 | R9: =(1+'⚙️ ПАРАМЕТРЫ'!$C$16)^INT((16-1)/12) -> 1.08 | S9: =(1+'⚙️ ПАРАМЕТРЫ'!$C$16)^INT((17-1)/12) -> 1.08 | T9: =(1+'⚙️ ПАРАМЕТРЫ'!$C$16)^INT((18-1)/12) -> 1.08 | U9: =(1+'⚙️ ПАРАМЕТРЫ'!$C$16)^INT((19-1)/12) -> 1.08 | V9: =(1+'⚙️ ПАРАМЕТРЫ'!$C$16)^INT((20-1)/12) -> 1.08 | W9: =(1+'⚙️ ПАРАМЕТРЫ'!$C$16)^INT((21-1)/12) -> 1.08 | X9: =(1+'⚙️ ПАРАМЕТРЫ'!$C$16)^INT((22-1)/12) -> 1.08 | Y9: =(1+'⚙️ ПАРАМЕТРЫ'!$C$16)^INT((23-1)/12) -> 1.08 | Z9: =(1+'⚙️ ПАРАМЕТРЫ'!$C$16)^INT((24-1)/12) -> 1.08 | AA9: =(1+'⚙️ ПАРАМЕТРЫ'!$C$16)^INT((25-1)/12) -> 1.1664 | AB9: =(1+'⚙️ ПАРАМЕТРЫ'!$C$16)^INT((26-1)/12) -> 1.1664 | AC9: =(1+'⚙️ ПАРАМЕТРЫ'!$C$16)^INT((27-1)/12) -> 1.1664 | AD9: =(1+'⚙️ ПАРАМЕТРЫ'!$C$16)^INT((28-1)/12) -> 1.1664 | AE9: =(1+'⚙️ ПАРАМЕТРЫ'!$C$16)^INT((29-1)/12) -> 1.1664 | AF9: =(1+'⚙️ ПАРАМЕТРЫ'!$C$16)^INT((30-1)/12) -> 1.1664 | AG9: =(1+'⚙️ ПАРАМЕТРЫ'!$C$16)^INT((31-1)/12) -> 1.1664 | AH9: =(1+'⚙️ ПАРАМЕТРЫ'!$C$16)^INT((32-1)/12) -> 1.1664 | AI9: =(1+'⚙️ ПАРАМЕТРЫ'!$C$16)^INT((33-1)/12) -> 1.1664 | AJ9: =(1+'⚙️ ПАРАМЕТРЫ'!$C$16)^INT((34-1)/12) -> 1.1664 | AK9: =(1+'⚙️ ПАРАМЕТРЫ'!$C$16)^INT((35-1)/12) -> 1.1664 | AL9: =(1+'⚙️ ПАРАМЕТРЫ'!$C$16)^INT((36-1)/12) -> 1.1664
B10: Клиентов/день | C10: =ROUND('⚙️ ПАРАМЕТРЫ'!$C$13*C5*C6*C8,0) -> 28 | D10: =ROUND('⚙️ ПАРАМЕТРЫ'!$C$13*D5*D6*D8,0) -> 51 | E10: =ROUND('⚙️ ПАРАМЕТРЫ'!$C$13*E5*E6*E8,0) -> 77 | F10: =ROUND('⚙️ ПАРАМЕТРЫ'!$C$13*F5*F6*F8,0) -> 77 | G10: =ROUND('⚙️ ПАРАМЕТРЫ'!$C$13*G5*G6*G8,0) -> 74 | H10: =ROUND('⚙️ ПАРАМЕТРЫ'!$C$13*H5*H6*H8,0) -> 70 | I10: =ROUND('⚙️ ПАРАМЕТРЫ'!$C$13*I5*I6*I8,0) -> 67 | J10: =ROUND('⚙️ ПАРАМЕТРЫ'!$C$13*J5*J6*J8,0) -> 67 | ... AL10: =ROUND('⚙️ ПАРАМЕТРЫ'!$C$13*AL5*AL6*AL8,0) -> 72
B11: Средний чек | C11: =ROUND('⚙️ ПАРАМЕТРЫ'!$C$12*C9,0) -> 1400 | D11: =ROUND('⚙️ ПАРАМЕТРЫ'!$C$12*D9,0) -> 1400 | E11: =ROUND('⚙️ ПАРАМЕТРЫ'!$C$12*E9,0) -> 1400 | F11: =ROUND('⚙️ ПАРАМЕТРЫ'!$C$12*F9,0) -> 1400 | G11: =ROUND('⚙️ ПАРАМЕТРЫ'!$C$12*G9,0) -> 1400 | H11: =ROUND('⚙️ ПАРАМЕТРЫ'!$C$12*H9,0) -> 1400 | I11: =ROUND('⚙️ ПАРАМЕТРЫ'!$C$12*I9,0) -> 1400 | J11: =ROUND('⚙️ ПАРАМЕТРЫ'!$C$12*J9,0) -> 1400 | ... AL11: =ROUND('⚙️ ПАРАМЕТРЫ'!$C$12*AL9,0) -> 1633
B12: ВЫРУЧКА | C12: =C10*C11*'⚙️ ПАРАМЕТРЫ'!$C$14 -> 1176000 | D12: =D10*D11*'⚙️ ПАРАМЕТРЫ'!$C$14 -> 2142000 | E12: =E10*E11*'⚙️ ПАРАМЕТРЫ'!$C$14 -> 3234000 | F12: =F10*F11*'⚙️ ПАРАМЕТРЫ'!$C$14 -> 3234000 | G12: =G10*G11*'⚙️ ПАРАМЕТРЫ'!$C$14 -> 3108000 | H12: =H10*H11*'⚙️ ПАРАМЕТРЫ'!$C$14 -> 2940000 | I12: =I10*I11*'⚙️ ПАРАМЕТРЫ'!$C$14 -> 2814000 | J12: =J10*J11*'⚙️ ПАРАМЕТРЫ'!$C$14 -> 2814000 | ... AL12: =AL10*AL11*'⚙️ ПАРАМЕТРЫ'!$C$14 -> 3527280
B13: ПРЯМЫЕ РАСХОДЫ
B14: Себестоимость | C14: =ROUND(C12*'⚙️ ПАРАМЕТРЫ'!$C$19,0) -> 411600 | D14: =ROUND(D12*'⚙️ ПАРАМЕТРЫ'!$C$19,0) -> 749700 | E14: =ROUND(E12*'⚙️ ПАРАМЕТРЫ'!$C$19,0) -> 1131900 | F14: =ROUND(F12*'⚙️ ПАРАМЕТРЫ'!$C$19,0) -> 1131900 | G14: =ROUND(G12*'⚙️ ПАРАМЕТРЫ'!$C$19,0) -> 1087800 | H14: =ROUND(H12*'⚙️ ПАРАМЕТРЫ'!$C$19,0) -> 1029000 | I14: =ROUND(I12*'⚙️ ПАРАМЕТРЫ'!$C$19,0) -> 984900 | J14: =ROUND(J12*'⚙️ ПАРАМЕТРЫ'!$C$19,0) -> 984900 | ... AL14: =ROUND(AL12*'⚙️ ПАРАМЕТРЫ'!$C$19,0) -> 1234548
B15: Потери/списания | C15: =ROUND(C12*'⚙️ ПАРАМЕТРЫ'!$C$20,0) -> 35280 | D15: =ROUND(D12*'⚙️ ПАРАМЕТРЫ'!$C$20,0) -> 64260 | E15: =ROUND(E12*'⚙️ ПАРАМЕТРЫ'!$C$20,0) -> 97020 | F15: =ROUND(F12*'⚙️ ПАРАМЕТРЫ'!$C$20,0) -> 97020 | G15: =ROUND(G12*'⚙️ ПАРАМЕТРЫ'!$C$20,0) -> 93240 | H15: =ROUND(H12*'⚙️ ПАРАМЕТРЫ'!$C$20,0) -> 88200 | I15: =ROUND(I12*'⚙️ ПАРАМЕТРЫ'!$C$20,0) -> 84420 | J15: =ROUND(J12*'⚙️ ПАРАМЕТРЫ'!$C$20,0) -> 84420 | ... AL15: =ROUND(AL12*'⚙️ ПАРАМЕТРЫ'!$C$20,0) -> 105818
B16: ВАЛОВАЯ ПРИБЫЛЬ | C16: =C12-C14-C15 -> 729120 | D16: =D12-D14-D15 -> 1328040 | E16: =E12-E14-E15 -> 2005080 | F16: =F12-F14-F15 -> 2005080 | G16: =G12-G14-G15 -> 1926960 | H16: =H12-H14-H15 -> 1822800 | I16: =I12-I14-I15 -> 1744680 | J16: =J12-J14-J15 -> 1744680 | ... AL16: =AL12-AL14-AL15 -> 2186914
B17: ПОСТОЯННЫЕ РАСХОДЫ
B18: ФОТ (Gross оклад) | C18: =ROUND('⚙️ ПАРАМЕТРЫ'!$C$25*'⚙️ ПАРАМЕТРЫ'!$C$26*(1+'📊 ДОПУЩЕНИЯ'!$C$10)^INT((1-1)/12),0) -> 400000 | D18: =ROUND('⚙️ ПАРАМЕТРЫ'!$C$25*'⚙️ ПАРАМЕТРЫ'!$C$26*(1+'📊 ДОПУЩЕНИЯ'!$C$10)^INT((2-1)/12),0) -> 400000 | E18: =ROUND('⚙️ ПАРАМЕТРЫ'!$C$25*'⚙️ ПАРАМЕТРЫ'!$C$26*(1+'📊 ДОПУЩЕНИЯ'!$C$10)^INT((3-1)/12),0) -> 400000 | F18: =ROUND('⚙️ ПАРАМЕТРЫ'!$C$25*'⚙️ ПАРАМЕТРЫ'!$C$26*(1+'📊 ДОПУЩЕНИЯ'!$C$10)^INT((4-1)/12),0) -> 400000 | G18: =ROUND('⚙️ ПАРАМЕТРЫ'!$C$25*'⚙️ ПАРАМЕТРЫ'!$C$26*(1+'📊 ДОПУЩЕНИЯ'!$C$10)^INT((5-1)/12),0) -> 400000 | H18: =ROUND('⚙️ ПАРАМЕТРЫ'!$C$25*'⚙️ ПАРАМЕТРЫ'!$C$26*(1+'📊 ДОПУЩЕНИЯ'!$C$10)^INT((6-1)/12),0) -> 400000 | I18: =ROUND('⚙️ ПАРАМЕТРЫ'!$C$25*'⚙️ ПАРАМЕТРЫ'!$C$26*(1+'📊 ДОПУЩЕНИЯ'!$C$10)^INT((7-1)/12),0) -> 400000 | J18: =ROUND('⚙️ ПАРАМЕТРЫ'!$C$25*'⚙️ ПАРАМЕТРЫ'!$C$26*(1+'📊 ДОПУЩЕНИЯ'!$C$10)^INT((8-1)/12),0) -> 400000 | K18: =ROUND('⚙️ ПАРАМЕТРЫ'!$C$25*'⚙️ ПАРАМЕТРЫ'!$C$26*(1+'📊 ДОПУЩЕНИЯ'!$C$10)^INT((9-1)/12),0) -> 400000 | L18: =ROUND('⚙️ ПАРАМЕТРЫ'!$C$25*'⚙️ ПАРАМЕТРЫ'!$C$26*(1+'📊 ДОПУЩЕНИЯ'!$C$10)^INT((10-1)/12),0) -> 400000 | M18: =ROUND('⚙️ ПАРАМЕТРЫ'!$C$25*'⚙️ ПАРАМЕТРЫ'!$C$26*(1+'📊 ДОПУЩЕНИЯ'!$C$10)^INT((11-1)/12),0) -> 400000 | N18: =ROUND('⚙️ ПАРАМЕТРЫ'!$C$25*'⚙️ ПАРАМЕТРЫ'!$C$26*(1+'📊 ДОПУЩЕНИЯ'!$C$10)^INT((12-1)/12),0) -> 400000 | O18: =ROUND('⚙️ ПАРАМЕТРЫ'!$C$25*'⚙️ ПАРАМЕТРЫ'!$C$26*(1+'📊 ДОПУЩЕНИЯ'!$C$10)^INT((13-1)/12),0) -> 432000 | P18: =ROUND('⚙️ ПАРАМЕТРЫ'!$C$25*'⚙️ ПАРАМЕТРЫ'!$C$26*(1+'📊 ДОПУЩЕНИЯ'!$C$10)^INT((14-1)/12),0) -> 432000 | Q18: =ROUND('⚙️ ПАРАМЕТРЫ'!$C$25*'⚙️ ПАРАМЕТРЫ'!$C$26*(1+'📊 ДОПУЩЕНИЯ'!$C$10)^INT((15-1)/12),0) -> 432000 | R18: =ROUND('⚙️ ПАРАМЕТРЫ'!$C$25*'⚙️ ПАРАМЕТРЫ'!$C$26*(1+'📊 ДОПУЩЕНИЯ'!$C$10)^INT((16-1)/12),0) -> 432000 | S18: =ROUND('⚙️ ПАРАМЕТРЫ'!$C$25*'⚙️ ПАРАМЕТРЫ'!$C$26*(1+'📊 ДОПУЩЕНИЯ'!$C$10)^INT((17-1)/12),0) -> 432000 | T18: =ROUND('⚙️ ПАРАМЕТРЫ'!$C$25*'⚙️ ПАРАМЕТРЫ'!$C$26*(1+'📊 ДОПУЩЕНИЯ'!$C$10)^INT((18-1)/12),0) -> 432000 | U18: =ROUND('⚙️ ПАРАМЕТРЫ'!$C$25*'⚙️ ПАРАМЕТРЫ'!$C$26*(1+'📊 ДОПУЩЕНИЯ'!$C$10)^INT((19-1)/12),0) -> 432000 | V18: =ROUND('⚙️ ПАРАМЕТРЫ'!$C$25*'⚙️ ПАРАМЕТРЫ'!$C$26*(1+'📊 ДОПУЩЕНИЯ'!$C$10)^INT((20-1)/12),0) -> 432000 | W18: =ROUND('⚙️ ПАРАМЕТРЫ'!$C$25*'⚙️ ПАРАМЕТРЫ'!$C$26*(1+'📊 ДОПУЩЕНИЯ'!$C$10)^INT((21-1)/12),0) -> 432000 | X18: =ROUND('⚙️ ПАРАМЕТРЫ'!$C$25*'⚙️ ПАРАМЕТРЫ'!$C$26*(1+'📊 ДОПУЩЕНИЯ'!$C$10)^INT((22-1)/12),0) -> 432000 | Y18: =ROUND('⚙️ ПАРАМЕТРЫ'!$C$25*'⚙️ ПАРАМЕТРЫ'!$C$26*(1+'📊 ДОПУЩЕНИЯ'!$C$10)^INT((23-1)/12),0) -> 432000 | Z18: =ROUND('⚙️ ПАРАМЕТРЫ'!$C$25*'⚙️ ПАРАМЕТРЫ'!$C$26*(1+'📊 ДОПУЩЕНИЯ'!$C$10)^INT((24-1)/12),0) -> 432000 | AA18: =ROUND('⚙️ ПАРАМЕТРЫ'!$C$25*'⚙️ ПАРАМЕТРЫ'!$C$26*(1+'📊 ДОПУЩЕНИЯ'!$C$10)^INT((25-1)/12),0) -> 466560 | AB18: =ROUND('⚙️ ПАРАМЕТРЫ'!$C$25*'⚙️ ПАРАМЕТРЫ'!$C$26*(1+'📊 ДОПУЩЕНИЯ'!$C$10)^INT((26-1)/12),0) -> 466560 | AC18: =ROUND('⚙️ ПАРАМЕТРЫ'!$C$25*'⚙️ ПАРАМЕТРЫ'!$C$26*(1+'📊 ДОПУЩЕНИЯ'!$C$10)^INT((27-1)/12),0) -> 466560 | AD18: =ROUND('⚙️ ПАРАМЕТРЫ'!$C$25*'⚙️ ПАРАМЕТРЫ'!$C$26*(1+'📊 ДОПУЩЕНИЯ'!$C$10)^INT((28-1)/12),0) -> 466560 | AE18: =ROUND('⚙️ ПАРАМЕТРЫ'!$C$25*'⚙️ ПАРАМЕТРЫ'!$C$26*(1+'📊 ДОПУЩЕНИЯ'!$C$10)^INT((29-1)/12),0) -> 466560 | AF18: =ROUND('⚙️ ПАРАМЕТРЫ'!$C$25*'⚙️ ПАРАМЕТРЫ'!$C$26*(1+'📊 ДОПУЩЕНИЯ'!$C$10)^INT((30-1)/12),0) -> 466560 | AG18: =ROUND('⚙️ ПАРАМЕТРЫ'!$C$25*'⚙️ ПАРАМЕТРЫ'!$C$26*(1+'📊 ДОПУЩЕНИЯ'!$C$10)^INT((31-1)/12),0) -> 466560 | AH18: =ROUND('⚙️ ПАРАМЕТРЫ'!$C$25*'⚙️ ПАРАМЕТРЫ'!$C$26*(1+'📊 ДОПУЩЕНИЯ'!$C$10)^INT((32-1)/12),0) -> 466560 | AI18: =ROUND('⚙️ ПАРАМЕТРЫ'!$C$25*'⚙️ ПАРАМЕТРЫ'!$C$26*(1+'📊 ДОПУЩЕНИЯ'!$C$10)^INT((33-1)/12),0) -> 466560 | AJ18: =ROUND('⚙️ ПАРАМЕТРЫ'!$C$25*'⚙️ ПАРАМЕТРЫ'!$C$26*(1+'📊 ДОПУЩЕНИЯ'!$C$10)^INT((34-1)/12),0) -> 466560 | AK18: =ROUND('⚙️ ПАРАМЕТРЫ'!$C$25*'⚙️ ПАРАМЕТРЫ'!$C$26*(1+'📊 ДОПУЩЕНИЯ'!$C$10)^INT((35-1)/12),0) -> 466560 | AL18: =ROUND('⚙️ ПАРАМЕТРЫ'!$C$25*'⚙️ ПАРАМЕТРЫ'!$C$26*(1+'📊 ДОПУЩЕНИЯ'!$C$10)^INT((36-1)/12),0) -> 466560
B19: ОСМС (3%) | C19: =ROUND(C18*'📊 ДОПУЩЕНИЯ'!$C$37,0) -> 12000 | D19: =ROUND(D18*'📊 ДОПУЩЕНИЯ'!$C$37,0) -> 12000 | E19: =ROUND(E18*'📊 ДОПУЩЕНИЯ'!$C$37,0) -> 12000 | F19: =ROUND(F18*'📊 ДОПУЩЕНИЯ'!$C$37,0) -> 12000 | G19: =ROUND(G18*'📊 ДОПУЩЕНИЯ'!$C$37,0) -> 12000 | H19: =ROUND(H18*'📊 ДОПУЩЕНИЯ'!$C$37,0) -> 12000 | I19: =ROUND(I18*'📊 ДОПУЩЕНИЯ'!$C$37,0) -> 12000 | J19: =ROUND(J18*'📊 ДОПУЩЕНИЯ'!$C$37,0) -> 12000 | ... AL19: =ROUND(AL18*'📊 ДОПУЩЕНИЯ'!$C$37,0) -> 13997
B20: ОПВР (3.5%) | C20: =ROUND(C18*'📊 ДОПУЩЕНИЯ'!$C$38,0) -> 14000 | D20: =ROUND(D18*'📊 ДОПУЩЕНИЯ'!$C$38,0) -> 14000 | E20: =ROUND(E18*'📊 ДОПУЩЕНИЯ'!$C$38,0) -> 14000 | F20: =ROUND(F18*'📊 ДОПУЩЕНИЯ'!$C$38,0) -> 14000 | G20: =ROUND(G18*'📊 ДОПУЩЕНИЯ'!$C$38,0) -> 14000 | H20: =ROUND(H18*'📊 ДОПУЩЕНИЯ'!$C$38,0) -> 14000 | I20: =ROUND(I18*'📊 ДОПУЩЕНИЯ'!$C$38,0) -> 14000 | J20: =ROUND(J18*'📊 ДОПУЩЕНИЯ'!$C$38,0) -> 14000 | ... AL20: =ROUND(AL18*'📊 ДОПУЩЕНИЯ'!$C$38,0) -> 16330
B21: СО (3.5%) | C21: =ROUND(C18*'📊 ДОПУЩЕНИЯ'!$C$39,0) -> 14000 | D21: =ROUND(D18*'📊 ДОПУЩЕНИЯ'!$C$39,0) -> 14000 | E21: =ROUND(E18*'📊 ДОПУЩЕНИЯ'!$C$39,0) -> 14000 | F21: =ROUND(F18*'📊 ДОПУЩЕНИЯ'!$C$39,0) -> 14000 | G21: =ROUND(G18*'📊 ДОПУЩЕНИЯ'!$C$39,0) -> 14000 | H21: =ROUND(H18*'📊 ДОПУЩЕНИЯ'!$C$39,0) -> 14000 | I21: =ROUND(I18*'📊 ДОПУЩЕНИЯ'!$C$39,0) -> 14000 | J21: =ROUND(J18*'📊 ДОПУЩЕНИЯ'!$C$39,0) -> 14000 | ... AL21: =ROUND(AL18*'📊 ДОПУЩЕНИЯ'!$C$39,0) -> 16330
B22: СН (9.5%−СО) | C22: =IF('📊 ДОПУЩЕНИЯ'!$C$55="УСН",0,ROUND(C18*MAX('📊 ДОПУЩЕНИЯ'!$C$40-'📊 ДОПУЩЕНИЯ'!$C$39,0),0)) -> 0 | D22: =IF('📊 ДОПУЩЕНИЯ'!$C$55="УСН",0,ROUND(D18*MAX('📊 ДОПУЩЕНИЯ'!$C$40-'📊 ДОПУЩЕНИЯ'!$C$39,0),0)) -> 0 | E22: =IF('📊 ДОПУЩЕНИЯ'!$C$55="УСН",0,ROUND(E18*MAX('📊 ДОПУЩЕНИЯ'!$C$40-'📊 ДОПУЩЕНИЯ'!$C$39,0),0)) -> 0 | F22: =IF('📊 ДОПУЩЕНИЯ'!$C$55="УСН",0,ROUND(F18*MAX('📊 ДОПУЩЕНИЯ'!$C$40-'📊 ДОПУЩЕНИЯ'!$C$39,0),0)) -> 0 | G22: =IF('📊 ДОПУЩЕНИЯ'!$C$55="УСН",0,ROUND(G18*MAX('📊 ДОПУЩЕНИЯ'!$C$40-'📊 ДОПУЩЕНИЯ'!$C$39,0),0)) -> 0 | H22: =IF('📊 ДОПУЩЕНИЯ'!$C$55="УСН",0,ROUND(H18*MAX('📊 ДОПУЩЕНИЯ'!$C$40-'📊 ДОПУЩЕНИЯ'!$C$39,0),0)) -> 0 | I22: =IF('📊 ДОПУЩЕНИЯ'!$C$55="УСН",0,ROUND(I18*MAX('📊 ДОПУЩЕНИЯ'!$C$40-'📊 ДОПУЩЕНИЯ'!$C$39,0),0)) -> 0 | J22: =IF('📊 ДОПУЩЕНИЯ'!$C$55="УСН",0,ROUND(J18*MAX('📊 ДОПУЩЕНИЯ'!$C$40-'📊 ДОПУЩЕНИЯ'!$C$39,0),0)) -> 0 | ... AL22: =IF('📊 ДОПУЩЕНИЯ'!$C$55="УСН",0,ROUND(AL18*MAX('📊 ДОПУЩЕНИЯ'!$C$40-'📊 ДОПУЩЕНИЯ'!$C$39,0),0)) -> 0
B23: Итого налоги работодателя | C23: =C19+C20+C21+C22 -> 40000 | D23: =D19+D20+D21+D22 -> 40000 | E23: =E19+E20+E21+E22 -> 40000 | F23: =F19+F20+F21+F22 -> 40000 | G23: =G19+G20+G21+G22 -> 40000 | H23: =H19+H20+H21+H22 -> 40000 | I23: =I19+I20+I21+I22 -> 40000 | J23: =J19+J20+J21+J22 -> 40000 | ... AL23: =AL19+AL20+AL21+AL22 -> 46657
B24: Аренда | C24: =ROUND('⚙️ ПАРАМЕТРЫ'!$C$23*(1+'📊 ДОПУЩЕНИЯ'!$C$9)^INT((1-1)/12),0) -> 70000 | D24: =ROUND('⚙️ ПАРАМЕТРЫ'!$C$23*(1+'📊 ДОПУЩЕНИЯ'!$C$9)^INT((2-1)/12),0) -> 70000 | E24: =ROUND('⚙️ ПАРАМЕТРЫ'!$C$23*(1+'📊 ДОПУЩЕНИЯ'!$C$9)^INT((3-1)/12),0) -> 70000 | F24: =ROUND('⚙️ ПАРАМЕТРЫ'!$C$23*(1+'📊 ДОПУЩЕНИЯ'!$C$9)^INT((4-1)/12),0) -> 70000 | G24: =ROUND('⚙️ ПАРАМЕТРЫ'!$C$23*(1+'📊 ДОПУЩЕНИЯ'!$C$9)^INT((5-1)/12),0) -> 70000 | H24: =ROUND('⚙️ ПАРАМЕТРЫ'!$C$23*(1+'📊 ДОПУЩЕНИЯ'!$C$9)^INT((6-1)/12),0) -> 70000 | I24: =ROUND('⚙️ ПАРАМЕТРЫ'!$C$23*(1+'📊 ДОПУЩЕНИЯ'!$C$9)^INT((7-1)/12),0) -> 70000 | J24: =ROUND('⚙️ ПАРАМЕТРЫ'!$C$23*(1+'📊 ДОПУЩЕНИЯ'!$C$9)^INT((8-1)/12),0) -> 70000 | K24: =ROUND('⚙️ ПАРАМЕТРЫ'!$C$23*(1+'📊 ДОПУЩЕНИЯ'!$C$9)^INT((9-1)/12),0) -> 70000 | L24: =ROUND('⚙️ ПАРАМЕТРЫ'!$C$23*(1+'📊 ДОПУЩЕНИЯ'!$C$9)^INT((10-1)/12),0) -> 70000 | M24: =ROUND('⚙️ ПАРАМЕТРЫ'!$C$23*(1+'📊 ДОПУЩЕНИЯ'!$C$9)^INT((11-1)/12),0) -> 70000 | N24: =ROUND('⚙️ ПАРАМЕТРЫ'!$C$23*(1+'📊 ДОПУЩЕНИЯ'!$C$9)^INT((12-1)/12),0) -> 70000 | O24: =ROUND('⚙️ ПАРАМЕТРЫ'!$C$23*(1+'📊 ДОПУЩЕНИЯ'!$C$9)^INT((13-1)/12),0) -> 77000 | P24: =ROUND('⚙️ ПАРАМЕТРЫ'!$C$23*(1+'📊 ДОПУЩЕНИЯ'!$C$9)^INT((14-1)/12),0) -> 77000 | Q24: =ROUND('⚙️ ПАРАМЕТРЫ'!$C$23*(1+'📊 ДОПУЩЕНИЯ'!$C$9)^INT((15-1)/12),0) -> 77000 | R24: =ROUND('⚙️ ПАРАМЕТРЫ'!$C$23*(1+'📊 ДОПУЩЕНИЯ'!$C$9)^INT((16-1)/12),0) -> 77000 | S24: =ROUND('⚙️ ПАРАМЕТРЫ'!$C$23*(1+'📊 ДОПУЩЕНИЯ'!$C$9)^INT((17-1)/12),0) -> 77000 | T24: =ROUND('⚙️ ПАРАМЕТРЫ'!$C$23*(1+'📊 ДОПУЩЕНИЯ'!$C$9)^INT((18-1)/12),0) -> 77000 | U24: =ROUND('⚙️ ПАРАМЕТРЫ'!$C$23*(1+'📊 ДОПУЩЕНИЯ'!$C$9)^INT((19-1)/12),0) -> 77000 | V24: =ROUND('⚙️ ПАРАМЕТРЫ'!$C$23*(1+'📊 ДОПУЩЕНИЯ'!$C$9)^INT((20-1)/12),0) -> 77000 | W24: =ROUND('⚙️ ПАРАМЕТРЫ'!$C$23*(1+'📊 ДОПУЩЕНИЯ'!$C$9)^INT((21-1)/12),0) -> 77000 | X24: =ROUND('⚙️ ПАРАМЕТРЫ'!$C$23*(1+'📊 ДОПУЩЕНИЯ'!$C$9)^INT((22-1)/12),0) -> 77000 | Y24: =ROUND('⚙️ ПАРАМЕТРЫ'!$C$23*(1+'📊 ДОПУЩЕНИЯ'!$C$9)^INT((23-1)/12),0) -> 77000 | Z24: =ROUND('⚙️ ПАРАМЕТРЫ'!$C$23*(1+'📊 ДОПУЩЕНИЯ'!$C$9)^INT((24-1)/12),0) -> 77000 | AA24: =ROUND('⚙️ ПАРАМЕТРЫ'!$C$23*(1+'📊 ДОПУЩЕНИЯ'!$C$9)^INT((25-1)/12),0) -> 84700 | AB24: =ROUND('⚙️ ПАРАМЕТРЫ'!$C$23*(1+'📊 ДОПУЩЕНИЯ'!$C$9)^INT((26-1)/12),0) -> 84700 | AC24: =ROUND('⚙️ ПАРАМЕТРЫ'!$C$23*(1+'📊 ДОПУЩЕНИЯ'!$C$9)^INT((27-1)/12),0) -> 84700 | AD24: =ROUND('⚙️ ПАРАМЕТРЫ'!$C$23*(1+'📊 ДОПУЩЕНИЯ'!$C$9)^INT((28-1)/12),0) -> 84700 | AE24: =ROUND('⚙️ ПАРАМЕТРЫ'!$C$23*(1+'📊 ДОПУЩЕНИЯ'!$C$9)^INT((29-1)/12),0) -> 84700 | AF24: =ROUND('⚙️ ПАРАМЕТРЫ'!$C$23*(1+'📊 ДОПУЩЕНИЯ'!$C$9)^INT((30-1)/12),0) -> 84700 | AG24: =ROUND('⚙️ ПАРАМЕТРЫ'!$C$23*(1+'📊 ДОПУЩЕНИЯ'!$C$9)^INT((31-1)/12),0) -> 84700 | AH24: =ROUND('⚙️ ПАРАМЕТРЫ'!$C$23*(1+'📊 ДОПУЩЕНИЯ'!$C$9)^INT((32-1)/12),0) -> 84700 | AI24: =ROUND('⚙️ ПАРАМЕТРЫ'!$C$23*(1+'📊 ДОПУЩЕНИЯ'!$C$9)^INT((33-1)/12),0) -> 84700 | AJ24: =ROUND('⚙️ ПАРАМЕТРЫ'!$C$23*(1+'📊 ДОПУЩЕНИЯ'!$C$9)^INT((34-1)/12),0) -> 84700 | AK24: =ROUND('⚙️ ПАРАМЕТРЫ'!$C$23*(1+'📊 ДОПУЩЕНИЯ'!$C$9)^INT((35-1)/12),0) -> 84700 | AL24: =ROUND('⚙️ ПАРАМЕТРЫ'!$C$23*(1+'📊 ДОПУЩЕНИЯ'!$C$9)^INT((36-1)/12),0) -> 84700
B25: Коммунальные | C25: =ROUND('⚙️ ПАРАМЕТРЫ'!$C$27*(1+'📊 ДОПУЩЕНИЯ'!$C$12)^INT((1-1)/12),0) -> 15000 | D25: =ROUND('⚙️ ПАРАМЕТРЫ'!$C$27*(1+'📊 ДОПУЩЕНИЯ'!$C$12)^INT((2-1)/12),0) -> 15000 | E25: =ROUND('⚙️ ПАРАМЕТРЫ'!$C$27*(1+'📊 ДОПУЩЕНИЯ'!$C$12)^INT((3-1)/12),0) -> 15000 | F25: =ROUND('⚙️ ПАРАМЕТРЫ'!$C$27*(1+'📊 ДОПУЩЕНИЯ'!$C$12)^INT((4-1)/12),0) -> 15000 | G25: =ROUND('⚙️ ПАРАМЕТРЫ'!$C$27*(1+'📊 ДОПУЩЕНИЯ'!$C$12)^INT((5-1)/12),0) -> 15000 | H25: =ROUND('⚙️ ПАРАМЕТРЫ'!$C$27*(1+'📊 ДОПУЩЕНИЯ'!$C$12)^INT((6-1)/12),0) -> 15000 | I25: =ROUND('⚙️ ПАРАМЕТРЫ'!$C$27*(1+'📊 ДОПУЩЕНИЯ'!$C$12)^INT((7-1)/12),0) -> 15000 | J25: =ROUND('⚙️ ПАРАМЕТРЫ'!$C$27*(1+'📊 ДОПУЩЕНИЯ'!$C$12)^INT((8-1)/12),0) -> 15000 | K25: =ROUND('⚙️ ПАРАМЕТРЫ'!$C$27*(1+'📊 ДОПУЩЕНИЯ'!$C$12)^INT((9-1)/12),0) -> 15000 | L25: =ROUND('⚙️ ПАРАМЕТРЫ'!$C$27*(1+'📊 ДОПУЩЕНИЯ'!$C$12)^INT((10-1)/12),0) -> 15000 | M25: =ROUND('⚙️ ПАРАМЕТРЫ'!$C$27*(1+'📊 ДОПУЩЕНИЯ'!$C$12)^INT((11-1)/12),0) -> 15000 | N25: =ROUND('⚙️ ПАРАМЕТРЫ'!$C$27*(1+'📊 ДОПУЩЕНИЯ'!$C$12)^INT((12-1)/12),0) -> 15000 | O25: =ROUND('⚙️ ПАРАМЕТРЫ'!$C$27*(1+'📊 ДОПУЩЕНИЯ'!$C$12)^INT((13-1)/12),0) -> 16200 | P25: =ROUND('⚙️ ПАРАМЕТРЫ'!$C$27*(1+'📊 ДОПУЩЕНИЯ'!$C$12)^INT((14-1)/12),0) -> 16200 | Q25: =ROUND('⚙️ ПАРАМЕТРЫ'!$C$27*(1+'📊 ДОПУЩЕНИЯ'!$C$12)^INT((15-1)/12),0) -> 16200 | R25: =ROUND('⚙️ ПАРАМЕТРЫ'!$C$27*(1+'📊 ДОПУЩЕНИЯ'!$C$12)^INT((16-1)/12),0) -> 16200 | S25: =ROUND('⚙️ ПАРАМЕТРЫ'!$C$27*(1+'📊 ДОПУЩЕНИЯ'!$C$12)^INT((17-1)/12),0) -> 16200 | T25: =ROUND('⚙️ ПАРАМЕТРЫ'!$C$27*(1+'📊 ДОПУЩЕНИЯ'!$C$12)^INT((18-1)/12),0) -> 16200 | U25: =ROUND('⚙️ ПАРАМЕТРЫ'!$C$27*(1+'📊 ДОПУЩЕНИЯ'!$C$12)^INT((19-1)/12),0) -> 16200 | V25: =ROUND('⚙️ ПАРАМЕТРЫ'!$C$27*(1+'📊 ДОПУЩЕНИЯ'!$C$12)^INT((20-1)/12),0) -> 16200 | W25: =ROUND('⚙️ ПАРАМЕТРЫ'!$C$27*(1+'📊 ДОПУЩЕНИЯ'!$C$12)^INT((21-1)/12),0) -> 16200 | X25: =ROUND('⚙️ ПАРАМЕТРЫ'!$C$27*(1+'📊 ДОПУЩЕНИЯ'!$C$12)^INT((22-1)/12),0) -> 16200 | Y25: =ROUND('⚙️ ПАРАМЕТРЫ'!$C$27*(1+'📊 ДОПУЩЕНИЯ'!$C$12)^INT((23-1)/12),0) -> 16200 | Z25: =ROUND('⚙️ ПАРАМЕТРЫ'!$C$27*(1+'📊 ДОПУЩЕНИЯ'!$C$12)^INT((24-1)/12),0) -> 16200 | AA25: =ROUND('⚙️ ПАРАМЕТРЫ'!$C$27*(1+'📊 ДОПУЩЕНИЯ'!$C$12)^INT((25-1)/12),0) -> 17496 | AB25: =ROUND('⚙️ ПАРАМЕТРЫ'!$C$27*(1+'📊 ДОПУЩЕНИЯ'!$C$12)^INT((26-1)/12),0) -> 17496 | AC25: =ROUND('⚙️ ПАРАМЕТРЫ'!$C$27*(1+'📊 ДОПУЩЕНИЯ'!$C$12)^INT((27-1)/12),0) -> 17496 | AD25: =ROUND('⚙️ ПАРАМЕТРЫ'!$C$27*(1+'📊 ДОПУЩЕНИЯ'!$C$12)^INT((28-1)/12),0) -> 17496 | AE25: =ROUND('⚙️ ПАРАМЕТРЫ'!$C$27*(1+'📊 ДОПУЩЕНИЯ'!$C$12)^INT((29-1)/12),0) -> 17496 | AF25: =ROUND('⚙️ ПАРАМЕТРЫ'!$C$27*(1+'📊 ДОПУЩЕНИЯ'!$C$12)^INT((30-1)/12),0) -> 17496 | AG25: =ROUND('⚙️ ПАРАМЕТРЫ'!$C$27*(1+'📊 ДОПУЩЕНИЯ'!$C$12)^INT((31-1)/12),0) -> 17496 | AH25: =ROUND('⚙️ ПАРАМЕТРЫ'!$C$27*(1+'📊 ДОПУЩЕНИЯ'!$C$12)^INT((32-1)/12),0) -> 17496 | AI25: =ROUND('⚙️ ПАРАМЕТРЫ'!$C$27*(1+'📊 ДОПУЩЕНИЯ'!$C$12)^INT((33-1)/12),0) -> 17496 | AJ25: =ROUND('⚙️ ПАРАМЕТРЫ'!$C$27*(1+'📊 ДОПУЩЕНИЯ'!$C$12)^INT((34-1)/12),0) -> 17496 | AK25: =ROUND('⚙️ ПАРАМЕТРЫ'!$C$27*(1+'📊 ДОПУЩЕНИЯ'!$C$12)^INT((35-1)/12),0) -> 17496 | AL25: =ROUND('⚙️ ПАРАМЕТРЫ'!$C$27*(1+'📊 ДОПУЩЕНИЯ'!$C$12)^INT((36-1)/12),0) -> 17496
B26: Маркетинг | C26: =ROUND('⚙️ ПАРАМЕТРЫ'!$C$28*(1+'📊 ДОПУЩЕНИЯ'!$C$13)^INT((1-1)/12),0) -> 50000 | D26: =ROUND('⚙️ ПАРАМЕТРЫ'!$C$28*(1+'📊 ДОПУЩЕНИЯ'!$C$13)^INT((2-1)/12),0) -> 50000 | E26: =ROUND('⚙️ ПАРАМЕТРЫ'!$C$28*(1+'📊 ДОПУЩЕНИЯ'!$C$13)^INT((3-1)/12),0) -> 50000 | F26: =ROUND('⚙️ ПАРАМЕТРЫ'!$C$28*(1+'📊 ДОПУЩЕНИЯ'!$C$13)^INT((4-1)/12),0) -> 50000 | G26: =ROUND('⚙️ ПАРАМЕТРЫ'!$C$28*(1+'📊 ДОПУЩЕНИЯ'!$C$13)^INT((5-1)/12),0) -> 50000 | H26: =ROUND('⚙️ ПАРАМЕТРЫ'!$C$28*(1+'📊 ДОПУЩЕНИЯ'!$C$13)^INT((6-1)/12),0) -> 50000 | I26: =ROUND('⚙️ ПАРАМЕТРЫ'!$C$28*(1+'📊 ДОПУЩЕНИЯ'!$C$13)^INT((7-1)/12),0) -> 50000 | J26: =ROUND('⚙️ ПАРАМЕТРЫ'!$C$28*(1+'📊 ДОПУЩЕНИЯ'!$C$13)^INT((8-1)/12),0) -> 50000 | K26: =ROUND('⚙️ ПАРАМЕТРЫ'!$C$28*(1+'📊 ДОПУЩЕНИЯ'!$C$13)^INT((9-1)/12),0) -> 50000 | L26: =ROUND('⚙️ ПАРАМЕТРЫ'!$C$28*(1+'📊 ДОПУЩЕНИЯ'!$C$13)^INT((10-1)/12),0) -> 50000 | M26: =ROUND('⚙️ ПАРАМЕТРЫ'!$C$28*(1+'📊 ДОПУЩЕНИЯ'!$C$13)^INT((11-1)/12),0) -> 50000 | N26: =ROUND('⚙️ ПАРАМЕТРЫ'!$C$28*(1+'📊 ДОПУЩЕНИЯ'!$C$13)^INT((12-1)/12),0) -> 50000 | O26: =ROUND('⚙️ ПАРАМЕТРЫ'!$C$28*(1+'📊 ДОПУЩЕНИЯ'!$C$13)^INT((13-1)/12),0) -> 52500 | P26: =ROUND('⚙️ ПАРАМЕТРЫ'!$C$28*(1+'📊 ДОПУЩЕНИЯ'!$C$13)^INT((14-1)/12),0) -> 52500 | Q26: =ROUND('⚙️ ПАРАМЕТРЫ'!$C$28*(1+'📊 ДОПУЩЕНИЯ'!$C$13)^INT((15-1)/12),0) -> 52500 | R26: =ROUND('⚙️ ПАРАМЕТРЫ'!$C$28*(1+'📊 ДОПУЩЕНИЯ'!$C$13)^INT((16-1)/12),0) -> 52500 | S26: =ROUND('⚙️ ПАРАМЕТРЫ'!$C$28*(1+'📊 ДОПУЩЕНИЯ'!$C$13)^INT((17-1)/12),0) -> 52500 | T26: =ROUND('⚙️ ПАРАМЕТРЫ'!$C$28*(1+'📊 ДОПУЩЕНИЯ'!$C$13)^INT((18-1)/12),0) -> 52500 | U26: =ROUND('⚙️ ПАРАМЕТРЫ'!$C$28*(1+'📊 ДОПУЩЕНИЯ'!$C$13)^INT((19-1)/12),0) -> 52500 | V26: =ROUND('⚙️ ПАРАМЕТРЫ'!$C$28*(1+'📊 ДОПУЩЕНИЯ'!$C$13)^INT((20-1)/12),0) -> 52500 | W26: =ROUND('⚙️ ПАРАМЕТРЫ'!$C$28*(1+'📊 ДОПУЩЕНИЯ'!$C$13)^INT((21-1)/12),0) -> 52500 | X26: =ROUND('⚙️ ПАРАМЕТРЫ'!$C$28*(1+'📊 ДОПУЩЕНИЯ'!$C$13)^INT((22-1)/12),0) -> 52500 | Y26: =ROUND('⚙️ ПАРАМЕТРЫ'!$C$28*(1+'📊 ДОПУЩЕНИЯ'!$C$13)^INT((23-1)/12),0) -> 52500 | Z26: =ROUND('⚙️ ПАРАМЕТРЫ'!$C$28*(1+'📊 ДОПУЩЕНИЯ'!$C$13)^INT((24-1)/12),0) -> 52500 | AA26: =ROUND('⚙️ ПАРАМЕТРЫ'!$C$28*(1+'📊 ДОПУЩЕНИЯ'!$C$13)^INT((25-1)/12),0) -> 55125 | AB26: =ROUND('⚙️ ПАРАМЕТРЫ'!$C$28*(1+'📊 ДОПУЩЕНИЯ'!$C$13)^INT((26-1)/12),0) -> 55125 | AC26: =ROUND('⚙️ ПАРАМЕТРЫ'!$C$28*(1+'📊 ДОПУЩЕНИЯ'!$C$13)^INT((27-1)/12),0) -> 55125 | AD26: =ROUND('⚙️ ПАРАМЕТРЫ'!$C$28*(1+'📊 ДОПУЩЕНИЯ'!$C$13)^INT((28-1)/12),0) -> 55125 | AE26: =ROUND('⚙️ ПАРАМЕТРЫ'!$C$28*(1+'📊 ДОПУЩЕНИЯ'!$C$13)^INT((29-1)/12),0) -> 55125 | AF26: =ROUND('⚙️ ПАРАМЕТРЫ'!$C$28*(1+'📊 ДОПУЩЕНИЯ'!$C$13)^INT((30-1)/12),0) -> 55125 | AG26: =ROUND('⚙️ ПАРАМЕТРЫ'!$C$28*(1+'📊 ДОПУЩЕНИЯ'!$C$13)^INT((31-1)/12),0) -> 55125 | AH26: =ROUND('⚙️ ПАРАМЕТРЫ'!$C$28*(1+'📊 ДОПУЩЕНИЯ'!$C$13)^INT((32-1)/12),0) -> 55125 | AI26: =ROUND('⚙️ ПАРАМЕТРЫ'!$C$28*(1+'📊 ДОПУЩЕНИЯ'!$C$13)^INT((33-1)/12),0) -> 55125 | AJ26: =ROUND('⚙️ ПАРАМЕТРЫ'!$C$28*(1+'📊 ДОПУЩЕНИЯ'!$C$13)^INT((34-1)/12),0) -> 55125 | AK26: =ROUND('⚙️ ПАРАМЕТРЫ'!$C$28*(1+'📊 ДОПУЩЕНИЯ'!$C$13)^INT((35-1)/12),0) -> 55125 | AL26: =ROUND('⚙️ ПАРАМЕТРЫ'!$C$28*(1+'📊 ДОПУЩЕНИЯ'!$C$13)^INT((36-1)/12),0) -> 55125
B27: Расходники | C27: =ROUND('⚙️ ПАРАМЕТРЫ'!$C$29*(1+'📊 ДОПУЩЕНИЯ'!$C$11)^INT((1-1)/12),0) -> 3500 | D27: =ROUND('⚙️ ПАРАМЕТРЫ'!$C$29*(1+'📊 ДОПУЩЕНИЯ'!$C$11)^INT((2-1)/12),0) -> 3500 | E27: =ROUND('⚙️ ПАРАМЕТРЫ'!$C$29*(1+'📊 ДОПУЩЕНИЯ'!$C$11)^INT((3-1)/12),0) -> 3500 | F27: =ROUND('⚙️ ПАРАМЕТРЫ'!$C$29*(1+'📊 ДОПУЩЕНИЯ'!$C$11)^INT((4-1)/12),0) -> 3500 | G27: =ROUND('⚙️ ПАРАМЕТРЫ'!$C$29*(1+'📊 ДОПУЩЕНИЯ'!$C$11)^INT((5-1)/12),0) -> 3500 | H27: =ROUND('⚙️ ПАРАМЕТРЫ'!$C$29*(1+'📊 ДОПУЩЕНИЯ'!$C$11)^INT((6-1)/12),0) -> 3500 | I27: =ROUND('⚙️ ПАРАМЕТРЫ'!$C$29*(1+'📊 ДОПУЩЕНИЯ'!$C$11)^INT((7-1)/12),0) -> 3500 | J27: =ROUND('⚙️ ПАРАМЕТРЫ'!$C$29*(1+'📊 ДОПУЩЕНИЯ'!$C$11)^INT((8-1)/12),0) -> 3500 | K27: =ROUND('⚙️ ПАРАМЕТРЫ'!$C$29*(1+'📊 ДОПУЩЕНИЯ'!$C$11)^INT((9-1)/12),0) -> 3500 | L27: =ROUND('⚙️ ПАРАМЕТРЫ'!$C$29*(1+'📊 ДОПУЩЕНИЯ'!$C$11)^INT((10-1)/12),0) -> 3500 | M27: =ROUND('⚙️ ПАРАМЕТРЫ'!$C$29*(1+'📊 ДОПУЩЕНИЯ'!$C$11)^INT((11-1)/12),0) -> 3500 | N27: =ROUND('⚙️ ПАРАМЕТРЫ'!$C$29*(1+'📊 ДОПУЩЕНИЯ'!$C$11)^INT((12-1)/12),0) -> 3500 | O27: =ROUND('⚙️ ПАРАМЕТРЫ'!$C$29*(1+'📊 ДОПУЩЕНИЯ'!$C$11)^INT((13-1)/12),0) -> 3920 | P27: =ROUND('⚙️ ПАРАМЕТРЫ'!$C$29*(1+'📊 ДОПУЩЕНИЯ'!$C$11)^INT((14-1)/12),0) -> 3920 | Q27: =ROUND('⚙️ ПАРАМЕТРЫ'!$C$29*(1+'📊 ДОПУЩЕНИЯ'!$C$11)^INT((15-1)/12),0) -> 3920 | R27: =ROUND('⚙️ ПАРАМЕТРЫ'!$C$29*(1+'📊 ДОПУЩЕНИЯ'!$C$11)^INT((16-1)/12),0) -> 3920 | S27: =ROUND('⚙️ ПАРАМЕТРЫ'!$C$29*(1+'📊 ДОПУЩЕНИЯ'!$C$11)^INT((17-1)/12),0) -> 3920 | T27: =ROUND('⚙️ ПАРАМЕТРЫ'!$C$29*(1+'📊 ДОПУЩЕНИЯ'!$C$11)^INT((18-1)/12),0) -> 3920 | U27: =ROUND('⚙️ ПАРАМЕТРЫ'!$C$29*(1+'📊 ДОПУЩЕНИЯ'!$C$11)^INT((19-1)/12),0) -> 3920 | V27: =ROUND('⚙️ ПАРАМЕТРЫ'!$C$29*(1+'📊 ДОПУЩЕНИЯ'!$C$11)^INT((20-1)/12),0) -> 3920 | W27: =ROUND('⚙️ ПАРАМЕТРЫ'!$C$29*(1+'📊 ДОПУЩЕНИЯ'!$C$11)^INT((21-1)/12),0) -> 3920 | X27: =ROUND('⚙️ ПАРАМЕТРЫ'!$C$29*(1+'📊 ДОПУЩЕНИЯ'!$C$11)^INT((22-1)/12),0) -> 3920 | Y27: =ROUND('⚙️ ПАРАМЕТРЫ'!$C$29*(1+'📊 ДОПУЩЕНИЯ'!$C$11)^INT((23-1)/12),0) -> 3920 | Z27: =ROUND('⚙️ ПАРАМЕТРЫ'!$C$29*(1+'📊 ДОПУЩЕНИЯ'!$C$11)^INT((24-1)/12),0) -> 3920 | AA27: =ROUND('⚙️ ПАРАМЕТРЫ'!$C$29*(1+'📊 ДОПУЩЕНИЯ'!$C$11)^INT((25-1)/12),0) -> 4390 | AB27: =ROUND('⚙️ ПАРАМЕТРЫ'!$C$29*(1+'📊 ДОПУЩЕНИЯ'!$C$11)^INT((26-1)/12),0) -> 4390 | AC27: =ROUND('⚙️ ПАРАМЕТРЫ'!$C$29*(1+'📊 ДОПУЩЕНИЯ'!$C$11)^INT((27-1)/12),0) -> 4390 | AD27: =ROUND('⚙️ ПАРАМЕТРЫ'!$C$29*(1+'📊 ДОПУЩЕНИЯ'!$C$11)^INT((28-1)/12),0) -> 4390 | AE27: =ROUND('⚙️ ПАРАМЕТРЫ'!$C$29*(1+'📊 ДОПУЩЕНИЯ'!$C$11)^INT((29-1)/12),0) -> 4390 | AF27: =ROUND('⚙️ ПАРАМЕТРЫ'!$C$29*(1+'📊 ДОПУЩЕНИЯ'!$C$11)^INT((30-1)/12),0) -> 4390 | AG27: =ROUND('⚙️ ПАРАМЕТРЫ'!$C$29*(1+'📊 ДОПУЩЕНИЯ'!$C$11)^INT((31-1)/12),0) -> 4390 | AH27: =ROUND('⚙️ ПАРАМЕТРЫ'!$C$29*(1+'📊 ДОПУЩЕНИЯ'!$C$11)^INT((32-1)/12),0) -> 4390 | AI27: =ROUND('⚙️ ПАРАМЕТРЫ'!$C$29*(1+'📊 ДОПУЩЕНИЯ'!$C$11)^INT((33-1)/12),0) -> 4390 | AJ27: =ROUND('⚙️ ПАРАМЕТРЫ'!$C$29*(1+'📊 ДОПУЩЕНИЯ'!$C$11)^INT((34-1)/12),0) -> 4390 | AK27: =ROUND('⚙️ ПАРАМЕТРЫ'!$C$29*(1+'📊 ДОПУЩЕНИЯ'!$C$11)^INT((35-1)/12),0) -> 4390 | AL27: =ROUND('⚙️ ПАРАМЕТРЫ'!$C$29*(1+'📊 ДОПУЩЕНИЯ'!$C$11)^INT((36-1)/12),0) -> 4390
B28: Софт/касса | C28: =ROUND('⚙️ ПАРАМЕТРЫ'!$C$30*(1+'📊 ДОПУЩЕНИЯ'!$C$12)^INT((1-1)/12),0) -> 5000 | D28: =ROUND('⚙️ ПАРАМЕТРЫ'!$C$30*(1+'📊 ДОПУЩЕНИЯ'!$C$12)^INT((2-1)/12),0) -> 5000 | E28: =ROUND('⚙️ ПАРАМЕТРЫ'!$C$30*(1+'📊 ДОПУЩЕНИЯ'!$C$12)^INT((3-1)/12),0) -> 5000 | F28: =ROUND('⚙️ ПАРАМЕТРЫ'!$C$30*(1+'📊 ДОПУЩЕНИЯ'!$C$12)^INT((4-1)/12),0) -> 5000 | G28: =ROUND('⚙️ ПАРАМЕТРЫ'!$C$30*(1+'📊 ДОПУЩЕНИЯ'!$C$12)^INT((5-1)/12),0) -> 5000 | H28: =ROUND('⚙️ ПАРАМЕТРЫ'!$C$30*(1+'📊 ДОПУЩЕНИЯ'!$C$12)^INT((6-1)/12),0) -> 5000 | I28: =ROUND('⚙️ ПАРАМЕТРЫ'!$C$30*(1+'📊 ДОПУЩЕНИЯ'!$C$12)^INT((7-1)/12),0) -> 5000 | J28: =ROUND('⚙️ ПАРАМЕТРЫ'!$C$30*(1+'📊 ДОПУЩЕНИЯ'!$C$12)^INT((8-1)/12),0) -> 5000 | K28: =ROUND('⚙️ ПАРАМЕТРЫ'!$C$30*(1+'📊 ДОПУЩЕНИЯ'!$C$12)^INT((9-1)/12),0) -> 5000 | L28: =ROUND('⚙️ ПАРАМЕТРЫ'!$C$30*(1+'📊 ДОПУЩЕНИЯ'!$C$12)^INT((10-1)/12),0) -> 5000 | M28: =ROUND('⚙️ ПАРАМЕТРЫ'!$C$30*(1+'📊 ДОПУЩЕНИЯ'!$C$12)^INT((11-1)/12),0) -> 5000 | N28: =ROUND('⚙️ ПАРАМЕТРЫ'!$C$30*(1+'📊 ДОПУЩЕНИЯ'!$C$12)^INT((12-1)/12),0) -> 5000 | O28: =ROUND('⚙️ ПАРАМЕТРЫ'!$C$30*(1+'📊 ДОПУЩЕНИЯ'!$C$12)^INT((13-1)/12),0) -> 5400 | P28: =ROUND('⚙️ ПАРАМЕТРЫ'!$C$30*(1+'📊 ДОПУЩЕНИЯ'!$C$12)^INT((14-1)/12),0) -> 5400 | Q28: =ROUND('⚙️ ПАРАМЕТРЫ'!$C$30*(1+'📊 ДОПУЩЕНИЯ'!$C$12)^INT((15-1)/12),0) -> 5400 | R28: =ROUND('⚙️ ПАРАМЕТРЫ'!$C$30*(1+'📊 ДОПУЩЕНИЯ'!$C$12)^INT((16-1)/12),0) -> 5400 | S28: =ROUND('⚙️ ПАРАМЕТРЫ'!$C$30*(1+'📊 ДОПУЩЕНИЯ'!$C$12)^INT((17-1)/12),0) -> 5400 | T28: =ROUND('⚙️ ПАРАМЕТРЫ'!$C$30*(1+'📊 ДОПУЩЕНИЯ'!$C$12)^INT((18-1)/12),0) -> 5400 | U28: =ROUND('⚙️ ПАРАМЕТРЫ'!$C$30*(1+'📊 ДОПУЩЕНИЯ'!$C$12)^INT((19-1)/12),0) -> 5400 | V28: =ROUND('⚙️ ПАРАМЕТРЫ'!$C$30*(1+'📊 ДОПУЩЕНИЯ'!$C$12)^INT((20-1)/12),0) -> 5400 | W28: =ROUND('⚙️ ПАРАМЕТРЫ'!$C$30*(1+'📊 ДОПУЩЕНИЯ'!$C$12)^INT((21-1)/12),0) -> 5400 | X28: =ROUND('⚙️ ПАРАМЕТРЫ'!$C$30*(1+'📊 ДОПУЩЕНИЯ'!$C$12)^INT((22-1)/12),0) -> 5400 | Y28: =ROUND('⚙️ ПАРАМЕТРЫ'!$C$30*(1+'📊 ДОПУЩЕНИЯ'!$C$12)^INT((23-1)/12),0) -> 5400 | Z28: =ROUND('⚙️ ПАРАМЕТРЫ'!$C$30*(1+'📊 ДОПУЩЕНИЯ'!$C$12)^INT((24-1)/12),0) -> 5400 | AA28: =ROUND('⚙️ ПАРАМЕТРЫ'!$C$30*(1+'📊 ДОПУЩЕНИЯ'!$C$12)^INT((25-1)/12),0) -> 5832 | AB28: =ROUND('⚙️ ПАРАМЕТРЫ'!$C$30*(1+'📊 ДОПУЩЕНИЯ'!$C$12)^INT((26-1)/12),0) -> 5832 | AC28: =ROUND('⚙️ ПАРАМЕТРЫ'!$C$30*(1+'📊 ДОПУЩЕНИЯ'!$C$12)^INT((27-1)/12),0) -> 5832 | AD28: =ROUND('⚙️ ПАРАМЕТРЫ'!$C$30*(1+'📊 ДОПУЩЕНИЯ'!$C$12)^INT((28-1)/12),0) -> 5832 | AE28: =ROUND('⚙️ ПАРАМЕТРЫ'!$C$30*(1+'📊 ДОПУЩЕНИЯ'!$C$12)^INT((29-1)/12),0) -> 5832 | AF28: =ROUND('⚙️ ПАРАМЕТРЫ'!$C$30*(1+'📊 ДОПУЩЕНИЯ'!$C$12)^INT((30-1)/12),0) -> 5832 | AG28: =ROUND('⚙️ ПАРАМЕТРЫ'!$C$30*(1+'📊 ДОПУЩЕНИЯ'!$C$12)^INT((31-1)/12),0) -> 5832 | AH28: =ROUND('⚙️ ПАРАМЕТРЫ'!$C$30*(1+'📊 ДОПУЩЕНИЯ'!$C$12)^INT((32-1)/12),0) -> 5832 | AI28: =ROUND('⚙️ ПАРАМЕТРЫ'!$C$30*(1+'📊 ДОПУЩЕНИЯ'!$C$12)^INT((33-1)/12),0) -> 5832 | AJ28: =ROUND('⚙️ ПАРАМЕТРЫ'!$C$30*(1+'📊 ДОПУЩЕНИЯ'!$C$12)^INT((34-1)/12),0) -> 5832 | AK28: =ROUND('⚙️ ПАРАМЕТРЫ'!$C$30*(1+'📊 ДОПУЩЕНИЯ'!$C$12)^INT((35-1)/12),0) -> 5832 | AL28: =ROUND('⚙️ ПАРАМЕТРЫ'!$C$30*(1+'📊 ДОПУЩЕНИЯ'!$C$12)^INT((36-1)/12),0) -> 5832
B29: Прочие | C29: =ROUND('⚙️ ПАРАМЕТРЫ'!$C$31*(1+'📊 ДОПУЩЕНИЯ'!$C$12)^INT((1-1)/12),0) -> 10000 | D29: =ROUND('⚙️ ПАРАМЕТРЫ'!$C$31*(1+'📊 ДОПУЩЕНИЯ'!$C$12)^INT((2-1)/12),0) -> 10000 | E29: =ROUND('⚙️ ПАРАМЕТРЫ'!$C$31*(1+'📊 ДОПУЩЕНИЯ'!$C$12)^INT((3-1)/12),0) -> 10000 | F29: =ROUND('⚙️ ПАРАМЕТРЫ'!$C$31*(1+'📊 ДОПУЩЕНИЯ'!$C$12)^INT((4-1)/12),0) -> 10000 | G29: =ROUND('⚙️ ПАРАМЕТРЫ'!$C$31*(1+'📊 ДОПУЩЕНИЯ'!$C$12)^INT((5-1)/12),0) -> 10000 | H29: =ROUND('⚙️ ПАРАМЕТРЫ'!$C$31*(1+'📊 ДОПУЩЕНИЯ'!$C$12)^INT((6-1)/12),0) -> 10000 | I29: =ROUND('⚙️ ПАРАМЕТРЫ'!$C$31*(1+'📊 ДОПУЩЕНИЯ'!$C$12)^INT((7-1)/12),0) -> 10000 | J29: =ROUND('⚙️ ПАРАМЕТРЫ'!$C$31*(1+'📊 ДОПУЩЕНИЯ'!$C$12)^INT((8-1)/12),0) -> 10000 | K29: =ROUND('⚙️ ПАРАМЕТРЫ'!$C$31*(1+'📊 ДОПУЩЕНИЯ'!$C$12)^INT((9-1)/12),0) -> 10000 | L29: =ROUND('⚙️ ПАРАМЕТРЫ'!$C$31*(1+'📊 ДОПУЩЕНИЯ'!$C$12)^INT((10-1)/12),0) -> 10000 | M29: =ROUND('⚙️ ПАРАМЕТРЫ'!$C$31*(1+'📊 ДОПУЩЕНИЯ'!$C$12)^INT((11-1)/12),0) -> 10000 | N29: =ROUND('⚙️ ПАРАМЕТРЫ'!$C$31*(1+'📊 ДОПУЩЕНИЯ'!$C$12)^INT((12-1)/12),0) -> 10000 | O29: =ROUND('⚙️ ПАРАМЕТРЫ'!$C$31*(1+'📊 ДОПУЩЕНИЯ'!$C$12)^INT((13-1)/12),0) -> 10800 | P29: =ROUND('⚙️ ПАРАМЕТРЫ'!$C$31*(1+'📊 ДОПУЩЕНИЯ'!$C$12)^INT((14-1)/12),0) -> 10800 | Q29: =ROUND('⚙️ ПАРАМЕТРЫ'!$C$31*(1+'📊 ДОПУЩЕНИЯ'!$C$12)^INT((15-1)/12),0) -> 10800 | R29: =ROUND('⚙️ ПАРАМЕТРЫ'!$C$31*(1+'📊 ДОПУЩЕНИЯ'!$C$12)^INT((16-1)/12),0) -> 10800 | S29: =ROUND('⚙️ ПАРАМЕТРЫ'!$C$31*(1+'📊 ДОПУЩЕНИЯ'!$C$12)^INT((17-1)/12),0) -> 10800 | T29: =ROUND('⚙️ ПАРАМЕТРЫ'!$C$31*(1+'📊 ДОПУЩЕНИЯ'!$C$12)^INT((18-1)/12),0) -> 10800 | U29: =ROUND('⚙️ ПАРАМЕТРЫ'!$C$31*(1+'📊 ДОПУЩЕНИЯ'!$C$12)^INT((19-1)/12),0) -> 10800 | V29: =ROUND('⚙️ ПАРАМЕТРЫ'!$C$31*(1+'📊 ДОПУЩЕНИЯ'!$C$12)^INT((20-1)/12),0) -> 10800 | W29: =ROUND('⚙️ ПАРАМЕТРЫ'!$C$31*(1+'📊 ДОПУЩЕНИЯ'!$C$12)^INT((21-1)/12),0) -> 10800 | X29: =ROUND('⚙️ ПАРАМЕТРЫ'!$C$31*(1+'📊 ДОПУЩЕНИЯ'!$C$12)^INT((22-1)/12),0) -> 10800 | Y29: =ROUND('⚙️ ПАРАМЕТРЫ'!$C$31*(1+'📊 ДОПУЩЕНИЯ'!$C$12)^INT((23-1)/12),0) -> 10800 | Z29: =ROUND('⚙️ ПАРАМЕТРЫ'!$C$31*(1+'📊 ДОПУЩЕНИЯ'!$C$12)^INT((24-1)/12),0) -> 10800 | AA29: =ROUND('⚙️ ПАРАМЕТРЫ'!$C$31*(1+'📊 ДОПУЩЕНИЯ'!$C$12)^INT((25-1)/12),0) -> 11664 | AB29: =ROUND('⚙️ ПАРАМЕТРЫ'!$C$31*(1+'📊 ДОПУЩЕНИЯ'!$C$12)^INT((26-1)/12),0) -> 11664 | AC29: =ROUND('⚙️ ПАРАМЕТРЫ'!$C$31*(1+'📊 ДОПУЩЕНИЯ'!$C$12)^INT((27-1)/12),0) -> 11664 | AD29: =ROUND('⚙️ ПАРАМЕТРЫ'!$C$31*(1+'📊 ДОПУЩЕНИЯ'!$C$12)^INT((28-1)/12),0) -> 11664 | AE29: =ROUND('⚙️ ПАРАМЕТРЫ'!$C$31*(1+'📊 ДОПУЩЕНИЯ'!$C$12)^INT((29-1)/12),0) -> 11664 | AF29: =ROUND('⚙️ ПАРАМЕТРЫ'!$C$31*(1+'📊 ДОПУЩЕНИЯ'!$C$12)^INT((30-1)/12),0) -> 11664 | AG29: =ROUND('⚙️ ПАРАМЕТРЫ'!$C$31*(1+'📊 ДОПУЩЕНИЯ'!$C$12)^INT((31-1)/12),0) -> 11664 | AH29: =ROUND('⚙️ ПАРАМЕТРЫ'!$C$31*(1+'📊 ДОПУЩЕНИЯ'!$C$12)^INT((32-1)/12),0) -> 11664 | AI29: =ROUND('⚙️ ПАРАМЕТРЫ'!$C$31*(1+'📊 ДОПУЩЕНИЯ'!$C$12)^INT((33-1)/12),0) -> 11664 | AJ29: =ROUND('⚙️ ПАРАМЕТРЫ'!$C$31*(1+'📊 ДОПУЩЕНИЯ'!$C$12)^INT((34-1)/12),0) -> 11664 | AK29: =ROUND('⚙️ ПАРАМЕТРЫ'!$C$31*(1+'📊 ДОПУЩЕНИЯ'!$C$12)^INT((35-1)/12),0) -> 11664 | AL29: =ROUND('⚙️ ПАРАМЕТРЫ'!$C$31*(1+'📊 ДОПУЩЕНИЯ'!$C$12)^INT((36-1)/12),0) -> 11664
B30: Итого постоянные | C30: =C18+C23+C24+C25+C26+C27+C28+C29 -> 593500 | D30: =D18+D23+D24+D25+D26+D27+D28+D29 -> 593500 | E30: =E18+E23+E24+E25+E26+E27+E28+E29 -> 593500 | F30: =F18+F23+F24+F25+F26+F27+F28+F29 -> 593500 | G30: =G18+G23+G24+G25+G26+G27+G28+G29 -> 593500 | H30: =H18+H23+H24+H25+H26+H27+H28+H29 -> 593500 | I30: =I18+I23+I24+I25+I26+I27+I28+I29 -> 593500 | J30: =J18+J23+J24+J25+J26+J27+J28+J29 -> 593500 | ... AL30: =AL18+AL23+AL24+AL25+AL26+AL27+AL28+AL29 -> 692424
B31: EBITDA | C31: =C16-C30 -> 135620 | D31: =D16-D30 -> 734540 | E31: =E16-E30 -> 1411580 | F31: =F16-F30 -> 1411580 | G31: =G16-G30 -> 1333460 | H31: =H16-H30 -> 1229300 | I31: =I16-I30 -> 1151180 | J31: =J16-J30 -> 1151180 | ... AL31: =AL16-AL30 -> 1494490
B32: Амортизация | C32: ='⚙️ ПАРАМЕТРЫ'!$C$42 -> 17857 | D32: ='⚙️ ПАРАМЕТРЫ'!$C$42 -> 17857 | E32: ='⚙️ ПАРАМЕТРЫ'!$C$42 -> 17857 | F32: ='⚙️ ПАРАМЕТРЫ'!$C$42 -> 17857 | G32: ='⚙️ ПАРАМЕТРЫ'!$C$42 -> 17857 | H32: ='⚙️ ПАРАМЕТРЫ'!$C$42 -> 17857 | I32: ='⚙️ ПАРАМЕТРЫ'!$C$42 -> 17857 | J32: ='⚙️ ПАРАМЕТРЫ'!$C$42 -> 17857 | ... AL32: ='⚙️ ПАРАМЕТРЫ'!$C$42 -> 17857
B33: EBIT | C33: =C31-C32 -> 117763 | D33: =D31-D32 -> 716683 | E33: =E31-E32 -> 1393723 | F33: =F31-F32 -> 1393723 | G33: =G31-G32 -> 1315603 | H33: =H31-H32 -> 1211443 | I33: =I31-I32 -> 1133323 | J33: =J31-J32 -> 1133323 | ... AL33: =AL31-AL32 -> 1476633
B34: Проценты по кредиту | C34: =IF(1<='⚙️ ПАРАМЕТРЫ'!$C$48,ABS(IPMT('⚙️ ПАРАМЕТРЫ'!$C$47/12,1,'⚙️ ПАРАМЕТРЫ'!$C$48,-'⚙️ ПАРАМЕТРЫ'!$C$46)),0) -> 18333.333 | D34: =IF(2<='⚙️ ПАРАМЕТРЫ'!$C$48,ABS(IPMT('⚙️ ПАРАМЕТРЫ'!$C$47/12,2,'⚙️ ПАРАМЕТРЫ'!$C$48,-'⚙️ ПАРАМЕТРЫ'!$C$46)),0) -> 17969.286 | E34: =IF(3<='⚙️ ПАРАМЕТРЫ'!$C$48,ABS(IPMT('⚙️ ПАРАМЕТРЫ'!$C$47/12,3,'⚙️ ПАРАМЕТРЫ'!$C$48,-'⚙️ ПАРАМЕТРЫ'!$C$46)),0) -> 17598.565 | F34: =IF(4<='⚙️ ПАРАМЕТРЫ'!$C$48,ABS(IPMT('⚙️ ПАРАМЕТРЫ'!$C$47/12,4,'⚙️ ПАРАМЕТРЫ'!$C$48,-'⚙️ ПАРАМЕТРЫ'!$C$46)),0) -> 17221.047 | G34: =IF(5<='⚙️ ПАРАМЕТРЫ'!$C$48,ABS(IPMT('⚙️ ПАРАМЕТРЫ'!$C$47/12,5,'⚙️ ПАРАМЕТРЫ'!$C$48,-'⚙️ ПАРАМЕТРЫ'!$C$46)),0) -> 16836.608 | H34: =IF(6<='⚙️ ПАРАМЕТРЫ'!$C$48,ABS(IPMT('⚙️ ПАРАМЕТРЫ'!$C$47/12,6,'⚙️ ПАРАМЕТРЫ'!$C$48,-'⚙️ ПАРАМЕТРЫ'!$C$46)),0) -> 16445.121 | I34: =IF(7<='⚙️ ПАРАМЕТРЫ'!$C$48,ABS(IPMT('⚙️ ПАРАМЕТРЫ'!$C$47/12,7,'⚙️ ПАРАМЕТРЫ'!$C$48,-'⚙️ ПАРАМЕТРЫ'!$C$46)),0) -> 16046.456 | J34: =IF(8<='⚙️ ПАРАМЕТРЫ'!$C$48,ABS(IPMT('⚙️ ПАРАМЕТРЫ'!$C$47/12,8,'⚙️ ПАРАМЕТРЫ'!$C$48,-'⚙️ ПАРАМЕТРЫ'!$C$46)),0) -> 15640.483 | K34: =IF(9<='⚙️ ПАРАМЕТРЫ'!$C$48,ABS(IPMT('⚙️ ПАРАМЕТРЫ'!$C$47/12,9,'⚙️ ПАРАМЕТРЫ'!$C$48,-'⚙️ ПАРАМЕТРЫ'!$C$46)),0) -> 15227.067 | L34: =IF(10<='⚙️ ПАРАМЕТРЫ'!$C$48,ABS(IPMT('⚙️ ПАРАМЕТРЫ'!$C$47/12,10,'⚙️ ПАРАМЕТРЫ'!$C$48,-'⚙️ ПАРАМЕТРЫ'!$C$46)),0) -> 14806.071 | M34: =IF(11<='⚙️ ПАРАМЕТРЫ'!$C$48,ABS(IPMT('⚙️ ПАРАМЕТРЫ'!$C$47/12,11,'⚙️ ПАРАМЕТРЫ'!$C$48,-'⚙️ ПАРАМЕТРЫ'!$C$46)),0) -> 14377.358 | N34: =IF(12<='⚙️ ПАРАМЕТРЫ'!$C$48,ABS(IPMT('⚙️ ПАРАМЕТРЫ'!$C$47/12,12,'⚙️ ПАРАМЕТРЫ'!$C$48,-'⚙️ ПАРАМЕТРЫ'!$C$46)),0) -> 13940.784 | O34: =IF(13<='⚙️ ПАРАМЕТРЫ'!$C$48,ABS(IPMT('⚙️ ПАРАМЕТРЫ'!$C$47/12,13,'⚙️ ПАРАМЕТРЫ'!$C$48,-'⚙️ ПАРАМЕТРЫ'!$C$46)),0) -> 13496.207 | P34: =IF(14<='⚙️ ПАРАМЕТРЫ'!$C$48,ABS(IPMT('⚙️ ПАРАМЕТРЫ'!$C$47/12,14,'⚙️ ПАРАМЕТРЫ'!$C$48,-'⚙️ ПАРАМЕТРЫ'!$C$46)),0) -> 13043.479 | Q34: =IF(15<='⚙️ ПАРАМЕТРЫ'!$C$48,ABS(IPMT('⚙️ ПАРАМЕТРЫ'!$C$47/12,15,'⚙️ ПАРАМЕТРЫ'!$C$48,-'⚙️ ПАРАМЕТРЫ'!$C$46)),0) -> 12582.451 | R34: =IF(16<='⚙️ ПАРАМЕТРЫ'!$C$48,ABS(IPMT('⚙️ ПАРАМЕТРЫ'!$C$47/12,16,'⚙️ ПАРАМЕТРЫ'!$C$48,-'⚙️ ПАРАМЕТРЫ'!$C$46)),0) -> 12112.971 | S34: =IF(17<='⚙️ ПАРАМЕТРЫ'!$C$48,ABS(IPMT('⚙️ ПАРАМЕТРЫ'!$C$47/12,17,'⚙️ ПАРАМЕТРЫ'!$C$48,-'⚙️ ПАРАМЕТРЫ'!$C$46)),0) -> 11634.884 | T34: =IF(18<='⚙️ ПАРАМЕТРЫ'!$C$48,ABS(IPMT('⚙️ ПАРАМЕТРЫ'!$C$47/12,18,'⚙️ ПАРАМЕТРЫ'!$C$48,-'⚙️ ПАРАМЕТРЫ'!$C$46)),0) -> 11148.032 | U34: =IF(19<='⚙️ ПАРАМЕТРЫ'!$C$48,ABS(IPMT('⚙️ ПАРАМЕТРЫ'!$C$47/12,19,'⚙️ ПАРАМЕТРЫ'!$C$48,-'⚙️ ПАРАМЕТРЫ'!$C$46)),0) -> 10652.254 | V34: =IF(20<='⚙️ ПАРАМЕТРЫ'!$C$48,ABS(IPMT('⚙️ ПАРАМЕТРЫ'!$C$47/12,20,'⚙️ ПАРАМЕТРЫ'!$C$48,-'⚙️ ПАРАМЕТРЫ'!$C$46)),0) -> 10147.387 | W34: =IF(21<='⚙️ ПАРАМЕТРЫ'!$C$48,ABS(IPMT('⚙️ ПАРАМЕТРЫ'!$C$47/12,21,'⚙️ ПАРАМЕТРЫ'!$C$48,-'⚙️ ПАРАМЕТРЫ'!$C$46)),0) -> 9633.2643 | X34: =IF(22<='⚙️ ПАРАМЕТРЫ'!$C$48,ABS(IPMT('⚙️ ПАРАМЕТРЫ'!$C$47/12,22,'⚙️ ПАРАМЕТРЫ'!$C$48,-'⚙️ ПАРАМЕТРЫ'!$C$46)),0) -> 9109.7158 | Y34: =IF(23<='⚙️ ПАРАМЕТРЫ'!$C$48,ABS(IPMT('⚙️ ПАРАМЕТРЫ'!$C$47/12,23,'⚙️ ПАРАМЕТРЫ'!$C$48,-'⚙️ ПАРАМЕТРЫ'!$C$46)),0) -> 8576.569 | Z34: =IF(24<='⚙️ ПАРАМЕТРЫ'!$C$48,ABS(IPMT('⚙️ ПАРАМЕТРЫ'!$C$47/12,24,'⚙️ ПАРАМЕТРЫ'!$C$48,-'⚙️ ПАРАМЕТРЫ'!$C$46)),0) -> 8033.6478 | AA34: =IF(25<='⚙️ ПАРАМЕТРЫ'!$C$48,ABS(IPMT('⚙️ ПАРАМЕТРЫ'!$C$47/12,25,'⚙️ ПАРАМЕТРЫ'!$C$48,-'⚙️ ПАРАМЕТРЫ'!$C$46)),0) -> 7480.773 | AB34: =IF(26<='⚙️ ПАРАМЕТРЫ'!$C$48,ABS(IPMT('⚙️ ПАРАМЕТРЫ'!$C$47/12,26,'⚙️ ПАРАМЕТРЫ'!$C$48,-'⚙️ ПАРАМЕТРЫ'!$C$46)),0) -> 6917.7622 | AC34: =IF(27<='⚙️ ПАРАМЕТРЫ'!$C$48,ABS(IPMT('⚙️ ПАРАМЕТРЫ'!$C$47/12,27,'⚙️ ПАРАМЕТРЫ'!$C$48,-'⚙️ ПАРАМЕТРЫ'!$C$46)),0) -> 6344.4295 | AD34: =IF(28<='⚙️ ПАРАМЕТРЫ'!$C$48,ABS(IPMT('⚙️ ПАРАМЕТРЫ'!$C$47/12,28,'⚙️ ПАРАМЕТРЫ'!$C$48,-'⚙️ ПАРАМЕТРЫ'!$C$46)),0) -> 5760.5858 | AE34: =IF(29<='⚙️ ПАРАМЕТРЫ'!$C$48,ABS(IPMT('⚙️ ПАРАМЕТРЫ'!$C$47/12,29,'⚙️ ПАРАМЕТРЫ'!$C$48,-'⚙️ ПАРАМЕТРЫ'!$C$46)),0) -> 5166.0382 | AF34: =IF(30<='⚙️ ПАРАМЕТРЫ'!$C$48,ABS(IPMT('⚙️ ПАРАМЕТРЫ'!$C$47/12,30,'⚙️ ПАРАМЕТРЫ'!$C$48,-'⚙️ ПАРАМЕТРЫ'!$C$46)),0) -> 4560.5906 | AG34: =IF(31<='⚙️ ПАРАМЕТРЫ'!$C$48,ABS(IPMT('⚙️ ПАРАМЕТРЫ'!$C$47/12,31,'⚙️ ПАРАМЕТРЫ'!$C$48,-'⚙️ ПАРАМЕТРЫ'!$C$46)),0) -> 3944.0431 | AH34: =IF(32<='⚙️ ПАРАМЕТРЫ'!$C$48,ABS(IPMT('⚙️ ПАРАМЕТРЫ'!$C$47/12,32,'⚙️ ПАРАМЕТРЫ'!$C$48,-'⚙️ ПАРАМЕТРЫ'!$C$46)),0) -> 3316.1923 | AI34: =IF(33<='⚙️ ПАРАМЕТРЫ'!$C$48,ABS(IPMT('⚙️ ПАРАМЕТРЫ'!$C$47/12,33,'⚙️ ПАРАМЕТРЫ'!$C$48,-'⚙️ ПАРАМЕТРЫ'!$C$46)),0) -> 2676.8308 | AJ34: =IF(34<='⚙️ ПАРАМЕТРЫ'!$C$48,ABS(IPMT('⚙️ ПАРАМЕТРЫ'!$C$47/12,34,'⚙️ ПАРАМЕТРЫ'!$C$48,-'⚙️ ПАРАМЕТРЫ'!$C$46)),0) -> 2025.7477 | AK34: =IF(35<='⚙️ ПАРАМЕТРЫ'!$C$48,ABS(IPMT('⚙️ ПАРАМЕТРЫ'!$C$47/12,35,'⚙️ ПАРАМЕТРЫ'!$C$48,-'⚙️ ПАРАМЕТРЫ'!$C$46)),0) -> 1362.7281 | AL34: =IF(36<='⚙️ ПАРАМЕТРЫ'!$C$48,ABS(IPMT('⚙️ ПАРАМЕТРЫ'!$C$47/12,36,'⚙️ ПАРАМЕТРЫ'!$C$48,-'⚙️ ПАРАМЕТРЫ'!$C$46)),0) -> 687.55317
B35: Налог (КПН/ИПН/УСН) | C35: =IF('📊 ДОПУЩЕНИЯ'!$C$55="УСН",ROUND(MAX(C12,0)*'📊 ДОПУЩЕНИЯ'!$C$58,0),IF('⚙️ ПАРАМЕТРЫ'!$C$5="ТОО",ROUND(MAX(C33-C34,0)*'📊 ДОПУЩЕНИЯ'!$C$45,0),ROUND(MAX(C33-C34,0)*'📊 ДОПУЩЕНИЯ'!$C$46,0))) -> 35280 | D35: =IF('📊 ДОПУЩЕНИЯ'!$C$55="УСН",ROUND(MAX(D12,0)*'📊 ДОПУЩЕНИЯ'!$C$58,0),IF('⚙️ ПАРАМЕТРЫ'!$C$5="ТОО",ROUND(MAX(D33-D34,0)*'📊 ДОПУЩЕНИЯ'!$C$45,0),ROUND(MAX(D33-D34,0)*'📊 ДОПУЩЕНИЯ'!$C$46,0))) -> 64260 | E35: =IF('📊 ДОПУЩЕНИЯ'!$C$55="УСН",ROUND(MAX(E12,0)*'📊 ДОПУЩЕНИЯ'!$C$58,0),IF('⚙️ ПАРАМЕТРЫ'!$C$5="ТОО",ROUND(MAX(E33-E34,0)*'📊 ДОПУЩЕНИЯ'!$C$45,0),ROUND(MAX(E33-E34,0)*'📊 ДОПУЩЕНИЯ'!$C$46,0))) -> 97020 | F35: =IF('📊 ДОПУЩЕНИЯ'!$C$55="УСН",ROUND(MAX(F12,0)*'📊 ДОПУЩЕНИЯ'!$C$58,0),IF('⚙️ ПАРАМЕТРЫ'!$C$5="ТОО",ROUND(MAX(F33-F34,0)*'📊 ДОПУЩЕНИЯ'!$C$45,0),ROUND(MAX(F33-F34,0)*'📊 ДОПУЩЕНИЯ'!$C$46,0))) -> 97020 | G35: =IF('📊 ДОПУЩЕНИЯ'!$C$55="УСН",ROUND(MAX(G12,0)*'📊 ДОПУЩЕНИЯ'!$C$58,0),IF('⚙️ ПАРАМЕТРЫ'!$C$5="ТОО",ROUND(MAX(G33-G34,0)*'📊 ДОПУЩЕНИЯ'!$C$45,0),ROUND(MAX(G33-G34,0)*'📊 ДОПУЩЕНИЯ'!$C$46,0))) -> 93240 | H35: =IF('📊 ДОПУЩЕНИЯ'!$C$55="УСН",ROUND(MAX(H12,0)*'📊 ДОПУЩЕНИЯ'!$C$58,0),IF('⚙️ ПАРАМЕТРЫ'!$C$5="ТОО",ROUND(MAX(H33-H34,0)*'📊 ДОПУЩЕНИЯ'!$C$45,0),ROUND(MAX(H33-H34,0)*'📊 ДОПУЩЕНИЯ'!$C$46,0))) -> 88200 | I35: =IF('📊 ДОПУЩЕНИЯ'!$C$55="УСН",ROUND(MAX(I12,0)*'📊 ДОПУЩЕНИЯ'!$C$58,0),IF('⚙️ ПАРАМЕТРЫ'!$C$5="ТОО",ROUND(MAX(I33-I34,0)*'📊 ДОПУЩЕНИЯ'!$C$45,0),ROUND(MAX(I33-I34,0)*'📊 ДОПУЩЕНИЯ'!$C$46,0))) -> 84420 | J35: =IF('📊 ДОПУЩЕНИЯ'!$C$55="УСН",ROUND(MAX(J12,0)*'📊 ДОПУЩЕНИЯ'!$C$58,0),IF('⚙️ ПАРАМЕТРЫ'!$C$5="ТОО",ROUND(MAX(J33-J34,0)*'📊 ДОПУЩЕНИЯ'!$C$45,0),ROUND(MAX(J33-J34,0)*'📊 ДОПУЩЕНИЯ'!$C$46,0))) -> 84420 | ... AL35: =IF('📊 ДОПУЩЕНИЯ'!$C$55="УСН",ROUND(MAX(AL12,0)*'📊 ДОПУЩЕНИЯ'!$C$58,0),IF('⚙️ ПАРАМЕТРЫ'!$C$5="ТОО",ROUND(MAX(AL33-AL34,0)*'📊 ДОПУЩЕНИЯ'!$C$45,0),ROUND(MAX(AL33-AL34,0)*'📊 ДОПУЩЕНИЯ'!$C$46,0))) -> 105818
B36: НДС к уплате | C36: =IF('📊 ДОПУЩЕНИЯ'!$C$57="Да",ROUND(MAX(C12-C14,0)*16/116,0),0) -> 0
B37: Налог на дивиденды (ТОО) | C37: =IF('⚙️ ПАРАМЕТРЫ'!$C$5="ТОО",ROUND(MAX(C33-C34-C35,0)*'📊 ДОПУЩЕНИЯ'!$C$48,0),0) -> 0 | D37: =IF('⚙️ ПАРАМЕТРЫ'!$C$5="ТОО",ROUND(MAX(D33-D34-D35,0)*'📊 ДОПУЩЕНИЯ'!$C$48,0),0) -> 0 | E37: =IF('⚙️ ПАРАМЕТРЫ'!$C$5="ТОО",ROUND(MAX(E33-E34-E35,0)*'📊 ДОПУЩЕНИЯ'!$C$48,0),0) -> 0 | F37: =IF('⚙️ ПАРАМЕТРЫ'!$C$5="ТОО",ROUND(MAX(F33-F34-F35,0)*'📊 ДОПУЩЕНИЯ'!$C$48,0),0) -> 0 | G37: =IF('⚙️ ПАРАМЕТРЫ'!$C$5="ТОО",ROUND(MAX(G33-G34-G35,0)*'📊 ДОПУЩЕНИЯ'!$C$48,0),0) -> 0 | H37: =IF('⚙️ ПАРАМЕТРЫ'!$C$5="ТОО",ROUND(MAX(H33-H34-H35,0)*'📊 ДОПУЩЕНИЯ'!$C$48,0),0) -> 0 | I37: =IF('⚙️ ПАРАМЕТРЫ'!$C$5="ТОО",ROUND(MAX(I33-I34-I35,0)*'📊 ДОПУЩЕНИЯ'!$C$48,0),0) -> 0 | J37: =IF('⚙️ ПАРАМЕТРЫ'!$C$5="ТОО",ROUND(MAX(J33-J34-J35,0)*'📊 ДОПУЩЕНИЯ'!$C$48,0),0) -> 0 | ... AL37: =IF('⚙️ ПАРАМЕТРЫ'!$C$5="ТОО",ROUND(MAX(AL33-AL34-AL35,0)*'📊 ДОПУЩЕНИЯ'!$C$48,0),0) -> 0
B38: ЧИСТАЯ ПРИБЫЛЬ | C38: =C33-C34-C35-C37 -> 64149.667 | D38: =D33-D34-D35-D37 -> 634453.71 | E38: =E33-E34-E35-E37 -> 1279104.4 | F38: =F33-F34-F35-F37 -> 1279482 | G38: =G33-G34-G35-G37 -> 1205526.4 | H38: =H33-H34-H35-H37 -> 1106797.9 | I38: =I33-I34-I35-I37 -> 1032856.5 | J38: =J33-J34-J35-J37 -> 1033262.5 | ... AL38: =AL33-AL34-AL35-AL37 -> 1370127.4
B39: Рентабельность | C39: =IFERROR(C38/C12,0) -> 0.054549036 | D39: =IFERROR(D38/D12,0) -> 0.29619688 | E39: =IFERROR(E38/E12,0) -> 0.39551776 | F39: =IFERROR(F38/F12,0) -> 0.39563449 | G39: =IFERROR(G38/G12,0) -> 0.3878785 | H39: =IFERROR(H38/H12,0) -> 0.37646186 | I39: =IFERROR(I38/I12,0) -> 0.36704213 | J39: =IFERROR(J38/J12,0) -> 0.3671864 | ... AL39: =IFERROR(AL38/AL12,0) -> 0.38843739
B41: 💡 IPMT = проценты (P&L). PPMT = тело (Cash Flow).

Sheet 💰 CASH FLOW
A1: ДВИЖЕНИЕ ДЕНЕЖНЫХ СРЕДСТВ — КОФЕЙНЯ: КОФЕ С СОБОЙ
A2: 📌 М0 = инвестиции. М1-36 = операционная деятельность.
B4: М0 | C4: М1 | D4: М2 | E4: М3 | F4: М4 | G4: М5 | H4: М6 | I4: М7 | J4: М8 | K4: М9 | L4: М10 | M4: М11 | N4: М12 | O4: М13 | P4: М14 | Q4: М15 | R4: М16 | S4: М17 | T4: М18 | U4: М19 | V4: М20 | W4: М21 | X4: М22 | Y4: М23 | Z4: М24 | AA4: М25 | AB4: М26 | AC4: М27 | AD4: М28 | AE4: М29 | AF4: М30 | AG4: М31 | AH4: М32 | AI4: М33 | AJ4: М34 | AK4: М35 | AL4: М36
B5: ИНВЕСТИЦИОННАЯ ДЕЯТЕЛЬНОСТЬ
B6: =-'⚙️ ПАРАМЕТРЫ'!C37 -> -1500000
B7: =-'⚙️ ПАРАМЕТРЫ'!C23*'⚙️ ПАРАМЕТРЫ'!C38 -> -140000
B8: =-'⚙️ ПАРАМЕТРЫ'!C39 -> -1000000
B9: =B6+B7+B8 -> -2640000
B10: ФИНАНСОВАЯ ДЕЯТЕЛЬНОСТЬ
B11: Получение кредита | C11: ='⚙️ ПАРАМЕТРЫ'!C46 -> 1000000 | D11: 💡 Кредит поступает в М1. Если кредит = 0 — строка нулевая.
