Workbook

Sheet 📋 НАВИГАЦИЯ
A1: ="ФИНАНСОВАЯ МОДЕЛЬ — "&UPPER('⚙️ ПАРАМЕТРЫ'!C5)
A2: ="Город: "&'⚙️ ПАРАМЕТРЫ'!C6&" | Горизонт: 36 месяцев (3 года) | ZEREK"
B3: СОДЕРЖАНИЕ
A5: 1 | B5: ⚙️ ПАРАМЕТРЫ | C5: Все вводные модели. Жёлтые ячейки = редактируемые.
A6: 2 | B6: 📊 ДОПУЩЕНИЯ | C6: Сезонность, ramp-up, инфляция по статьям.
A7: 3 | B7: 🎯 ДАШБОРД | C7: NPV, IRR, PP, BEP, ROI — ключевые показатели.
A8: 4 | B8: 📈 P&L | C8: Отчёт о прибылях и убытках, 36 месяцев.
A9: 5 | B9: 💰 CASH FLOW | C9: Движение денежных средств, 36 месяцев.
A10: 6 | B10: 📑 БАЛАНС | C10: Упрощённый баланс поквартально.
A11: 7 | B11: 🔄 ЧУВСТВИТЕЛЬНОСТЬ | C11: Что если изменить ключевые параметры?
A12: 8 | B12: ✅ ПРОВЕРКА | C12: Контрольные суммы и проверка формул.
B14: ИНСТРУКЦИЯ
A16: 1 | B16: Откройте ⚙️ ПАРАМЕТРЫ — введите данные в жёлтые ячейки
A17: 2 | B17: Настройте 📊 ДОПУЩЕНИЯ — сезонность под ваш регион
A18: 3 | B18: Результаты на 🎯 ДАШБОРДЕ — автоматически
A19: 4 | B19: 📈 P&L и 💰 CASH FLOW — помесячная детализация
A20: 5 | B20: 🔄 ЧУВСТВИТЕЛЬНОСТЬ — стресс-тест параметров
A21: 6 | B21: ✅ ПРОВЕРКА — все формулы должны показать OK
B24: Сформировано: ZEREK — аналитика для предпринимателей КЗ | 04.04.2026 | @zerekai_bot

Sheet ⚙️ ПАРАМЕТРЫ
A1: ="ПАРАМЕТРЫ МОДЕЛИ — "&UPPER(C5)
A2: 📌 Правило: меняйте только жёлтые ячейки. Синий текст = введённое число. Чёрный текст = формула (не трогать). Все листы пересчитываются автоматически.
A3: 0. ОБЩИЕ ПАРАМЕТРЫ
B4: Параметр | C4: Значение | D4: Ед. | E4: Пояснение (дисклеймер)
B5: Название бизнеса | C5: Кофейня: Кофе с собой | E5: 💡 Отображается в заголовках всех листов модели
B6: Город | C6: Актобе | E6: 💡 Влияет на ценовой коэффициент, аренду и ставку налога
B7: Форма собственности | C7: ИП | E7: 💡 ИП: прибыль можно забирать свободно. ТОО: через дивиденды (5% ИПН)
B8: Налоговый режим | C8: УСН | E8: 💡 Упрощённая: 2-4% от оборота. Порог: 600 000 МРП (~2.6 млрд ₸). Для B2C — оптимально
B9: Ставка налога (маслихат) | C9: 0.03 | D9: % | E9: 💡 Маслихат вашего города может понизить ставку на 1% от НК. Актобе: 3%
B10: Горизонт модели | C10: 36 | D10: мес | E10: 💡 36 месяцев = 3 года. Стандартный горизонт для МСБ
A11: 1. ВЫРУЧКА
B12: Параметр | C12: Значение | D12: Ед. | E12: Пояснение (дисклеймер)
B13: Средний чек (корзина) | C13: 1400 | D13: ₸ | E13: 💡 Типовая корзина покупки 1 клиента. Не 1 товар, а вся покупка целиком
B14: Клиентов в день (на полной мощности) | C14: 70 | D14: чел/день | E14: 💡 Базовый трафик после выхода на полную мощность. В первые месяцы будет меньше (ramp-up)
B15: Рабочих дней в месяце | C15: 30 | D15: дней | E15: 💡 Для большинства МСБ = 30 дней (общепит, услуги). Для офисных = 22
B16: Рост трафика в год | C16: 0.07 | D16: % | E16: 💡 Органический рост базы клиентов: повторные + новые. 5-10% для МСБ
B17: Рост среднего чека в год | C17: 0.08 | D17: % | E17: 💡 Инфляция + допродажи. В КЗ инфляция ~10%, чек растёт ~8%
A18: 2. ПРЯМЫЕ РАСХОДЫ
B19: Параметр | C19: Значение | D19: Ед. | E19: Пояснение (дисклеймер)
B20: Себестоимость (% от выручки) | C20: 0.35 | D20: % | E20: 💡 Прямые затраты: продукты, материалы, расходники. Общепит: 30-40%, услуги: 5-15%, торговля: 60-75%
B21: Потери и списания (% от выручки) | C21: 0.03 | D21: % | E21: 💡 Брак, просрочка, бой, усушка. Общепит: 3-5%, торговля: 1-3%
A22: 3. ПОСТОЯННЫЕ РАСХОДЫ
B23: Параметр | C23: Значение | D23: Ед. | E23: Пояснение (дисклеймер)
B24: Аренда помещения | C24: 70000 | D24: ₸/мес | E24: 💡 Ежемесячная аренда. Зависит от локации, площади, города. Актобе 1-я линия: ~3000-5000 ₸/м²
B25: Площадь помещения | C25: 6 | D25: м² | E25: 💡 Типовая площадь для формата
B26: ФОТ чистый (все сотрудники на руки) | C26: 150000 | D26: ₸/мес | E26: 💡 Сумма зарплат ВСЕХ сотрудников на руки (до налогов работодателя)
B27: Количество сотрудников | C27: 1 | D27: чел | E27: 💡 Штат на полную мощность
B28: Коммунальные | C28: 8400 | D28: ₸/мес | E28: 💡 Электричество, вода, отопление, вывоз мусора
B29: Маркетинг | C29: 10500 | D29: ₸/мес | E29: 💡 Ежемесячный бюджет: Instagram, 2ГИС, акции. Базовый сценарий: 30-80 тыс
B30: Расходники | C30: 3500 | D30: ₸/мес | E30: 💡 Мелкие расходные материалы, не вошедшие в себестоимость
B31: Софт / касса / CRM | C31: 5000 | D31: ₸/мес | E31: 💡 Kaspi касса, iiko, Poster или аналоги
B32: Прочие расходы | C32: 0 | D32: ₸/мес | E32: 💡 Транспорт, связь, канцелярия, СЭЗ
B33: Рост аренды в год | C33: 0.1 | D33: % | E33: 💡 Арендодатели в КЗ индексируют на 8-12% ежегодно
B34: Рост ФОТ в год | C34: 0.08 | D34: % | E34: 💡 Зарплаты в КЗ растут на 6-10% в год
B35: Инфляция прочих расходов | C35: 0.1 | D35: % | E35: 💡 Общая инфляция ~10%. Коммуналка, маркетинг, расходники
A36: 4. СТАРТОВЫЕ ИНВЕСТИЦИИ
B37: Параметр | C37: Значение | D37: Ед. | E37: Пояснение (дисклеймер)
B38: CAPEX (оборудование + ремонт) | C38: 800000 | D38: ₸ | E38: 💡 Кофемашина, кофемолка, холодильная витрина
B39: Депозит за аренду | C39: 2 | D39: мес | E39: 💡 Залог арендодателю. Обычно 2-3 месяца. Возвращается при выезде
B40: Оборотный капитал (резерв) | C40: 160000 | D40: ₸ | E40: 💡 Деньги на первые 2-3 месяца: аренда + зарплаты + закупки до выхода в плюс
...

Sheet 📊 ДОПУЩЕНИЯ
A1: ="ДОПУЩЕНИЯ МОДЕЛИ — "&UPPER('⚙️ ПАРАМЕТРЫ'!C5)
A2: 📌 Сезонные коэффициенты: 1.00 = норма, 1.10 = на 10% выше, 0.85 = на 15% ниже. Казахстан — резко континентальный климат: жаркое лето, холодная зима.
A3: СЕЗОННОСТЬ ТРАФИКА
B4: Месяц | C4: Янв | D4: Фев | E4: Мар | F4: Апр | G4: Май | H4: Июн | I4: Июл | J4: Авг | K4: Сен | L4: Окт | M4: Ноя | N4: Дек
B5: Коэффициент | C5: 0.85 | D5: 0.85 | E5: 0.9 | F5: 1 | G5: 1.05 | H5: 1.1 | I5: 1.1 | J5: 1.05 | K5: 1 | L5: 0.95 | M5: 0.9 | N5: 1.15
B6: 💡 Коэффициенты умножаются на базовый трафик. 1.15 в декабре = праздничный спрос +15%. 0.85 зимой = холод, меньше пешеходов.
A7: ИНФЛЯЦИЯ ПО СТАТЬЯМ
B8: Статья | C8: Рост/год | D8: Пояснение
B9: Аренда | C9: 0.1 | D9: 💡 Арендодатели КЗ индексируют ежегодно. Зависит от договора
B10: ФОТ | C10: 0.08 | D10: 💡 Рост зарплат. В КЗ ~8% в год
B11: Продукты/материалы | C11: 0.12 | D11: 💡 Продовольственная инфляция в КЗ выше общей: 10-15%
B12: Коммунальные | C12: 0.08 | D12: 💡 Тарифы регулируются, растут медленнее
B13: Маркетинг | C13: 0.05 | D13: 💡 Цифровая реклама дорожает медленнее
B15: ZEREK | 04.04.2026

Sheet 🎯 ДАШБОРД
A1: ="ДАШБОРД — "&UPPER('⚙️ ПАРАМЕТРЫ'!C5)&" ("&'⚙️ ПАРАМЕТРЫ'!C6&")"
A2: ="Горизонт: 36 мес | Город: "&'⚙️ ПАРАМЕТРЫ'!C6&" | Все показатели обновляются автоматически"
A3: КЛЮЧЕВЫЕ ИНВЕСТИЦИОННЫЕ ПОКАЗАТЕЛИ
B4: NPV | C4: IRR | D4: Окупаемость | E4: ROI
B5: =NPV('⚙️ ПАРАМЕТРЫ'!C57/12,'💰 CASH FLOW'!C9:AL9)-'⚙️ ПАРАМЕТРЫ'!C42 | C5: =IFERROR(IRR('💰 CASH FLOW'!B9:AL9),0) | D5: =IFERROR(MATCH(TRUE(),'💰 CASH FLOW'!C10:AL10>=0,0),">36") | E5: =IFERROR(SUM('📈 P&L'!C31:AL31)/'⚙️ ПАРАМЕТРЫ'!C42,0)
B6: Чистая приведённая стоимость. NPV > 0 → проект выгоден | C6: Годовая доходность. Сравните с депозитом (12-14%) | D6: Через сколько месяцев вернёте вложения | E6: Прибыль за 3 года / инвестиции. >100% = вложения вернулись
A8: СВОДНЫЙ P&L ЗА 3 ГОДА
B9: Показатель | C9: Итого 36 мес | D9: ₸/мес (средн.) | E9: % от выручки
B10: Выручка | C10: =SUM('📈 P&L'!C12:AL12) | D10: =IFERROR(C10/36,"") | E10: =IFERROR(C10/SUM('📈 P&L'!C12:AL12),"")
B11: ▸ Себестоимость | C11: =SUM('📈 P&L'!C14:AL14) | D11: =IFERROR(C11/36,"") | E11: =IFERROR(C11/SUM('📈 P&L'!C12:AL12),"")
B12: ▸ Потери | C12: =SUM('📈 P&L'!C15:AL15) | D12: =IFERROR(C12/36,"") | E12: =IFERROR(C12/SUM('📈 P&L'!C12:AL12),"")
B13: Валовая прибыль | C13: =SUM('📈 P&L'!C16:AL16) | D13: =IFERROR(C13/36,"") | E13: =IFERROR(C13/SUM('📈 P&L'!C12:AL12),"")
B14: ▸ ФОТ | C14: =SUM('📈 P&L'!C18:AL18) | D14: =IFERROR(C14/36,"") | E14: =IFERROR(C14/SUM('📈 P&L'!C12:AL12),"")
B15: ▸ Аренда | C15: =SUM('📈 P&L'!C19:AL19) | D15: =IFERROR(C15/36,"") | E15: =IFERROR(C15/SUM('📈 P&L'!C12:AL12),"")
B16: ▸ Прочие пост. | C16: =SUM('📈 P&L'!C20:AL20)+SUM('📈 P&L'!C21:AL21)+SUM('📈 P&L'!C22:AL22)+SUM('📈 P&L'!C23:AL23)+SUM('📈 P&L'!C24:AL24) | D16: =IFERROR(C16/36,"") | E16: =IFERROR(C16/SUM('📈 P&L'!C12:AL12),"")
B17: EBITDA | C17: =SUM('📈 P&L'!C26:AL26) | D17: =IFERROR(C17/36,"") | E17: =IFERROR(C17/SUM('📈 P&L'!C12:AL12),"")
B18: Налог | C18: =SUM('📈 P&L'!C30:AL30) | D18: =IFERROR(C18/36,"") | E18: =IFERROR(C18/SUM('📈 P&L'!C12:AL12),"")
B19: ЧИСТАЯ ПРИБЫЛЬ | C19: =SUM('📈 P&L'!C31:AL31) | D19: =IFERROR(C19/36,"") | E19: =IFERROR(C19/SUM('📈 P&L'!C12:AL12),"")
A21: АВТОМАТИЧЕСКИЙ ВЫВОД
B22: =IF(B5>0,"✅ NPV положительный — проект создаёт стоимость.","❌ NPV отрицательный — проект разрушает стоимость.")
B23: =IF(B5>'⚙️ ПАРАМЕТРЫ'!C57,"✅ IRR выше WACC — проект привлекателен для инвестора.","⚠️ IRR ниже WACC — доходность не покрывает риски.")
B24: =IF(D5<=18,"✅ Окупаемость до 18 мес — отличный показатель.",IF(D5<=30,"⚠️ Окупаемость 18-30 мес — приемлемо.","❌ Окупаемость >30 мес — высокий риск."))
B26: ZEREK | 04.04.2026

Sheet 📈 P&L
A1: ="ОТЧЁТ О ПРИБЫЛЯХ И УБЫТКАХ — "&UPPER('⚙️ ПАРАМЕТРЫ'!C5)&" ("&'⚙️ ПАРАМЕТРЫ'!C6&")"
A2: 📌 Помесячно на 36 месяцев. Все формулы ссылаются на ⚙️ ПАРАМЕТРЫ и 📊 ДОПУЩЕНИЯ. Меняете параметры — P&L пересчитывается.
B3: Статья / Период | C3: М1 | D3: М2 | E3: М3 | F3: М4 | G3: М5 | H3: М6 | I3: М7 | J3: М8 | K3: М9 | L3: М10 | M3: М11 | N3: М12 | O3: М13 | P3: М14 | Q3: М15 | R3: М16 | S3: М17 | T3: М18 | U3: М19 | V3: М20 | W3: М21 | X3: М22 | Y3: М23 | Z3: М24 | AA3: М25 | AB3: М26 | AC3: М27 | AD3: М28 | AE3: М29 | AF3: М30 | AG3: М31 | AH3: М32 | AI3: М33 | AJ3: М34 | AK3: М35 | AL3: М36
B4: Кал. месяц | C4: =MOD(1-1+3,12)+1 | D4: =MOD(2-1+3,12)+1 | E4: =MOD(3-1+3,12)+1 | F4: =MOD(4-1+3,12)+1 | G4: =MOD(5-1+3,12)+1 | H4: =MOD(6-1+3,12)+1 | I4: =MOD(7-1+3,12)+1 | J4: =MOD(8-1+3,12)+1 | K4: =MOD(9-1+3,12)+1 | L4: =MOD(10-1+3,12)+1 | M4: =MOD(11-1+3,12)+1 | N4: =MOD(12-1+3,12)+1 | O4: =MOD(13-1+3,12)+1 | P4: =MOD(14-1+3,12)+1 | Q4: =MOD(15-1+3,12)+1 | R4: =MOD(16-1+3,12)+1 | S4: =MOD(17-1+3,12)+1 | T4: =MOD(18-1+3,12)+1 | U4: =MOD(19-1+3,12)+1 | V4: =MOD(20-1+3,12)+1 | W4: =MOD(21-1+3,12)+1 | X4: =MOD(22-1+3,12)+1 | Y4: =MOD(23-1+3,12)+1 | Z4: =MOD(24-1+3,12)+1 | AA4: =MOD(25-1+3,12)+1 | AB4: =MOD(26-1+3,12)+1 | AC4: =MOD(27-1+3,12)+1 | AD4: =MOD(28-1+3,12)+1 | AE4: =MOD(29-1+3,12)+1 | AF4: =MOD(30-1+3,12)+1 | AG4: =MOD(31-1+3,12)+1 | AH4: =MOD(32-1+3,12)+1 | AI4: =MOD(33-1+3,12)+1 | AJ4: =MOD(34-1+3,12)+1 | AK4: =MOD(35-1+3,12)+1 | AL4: =MOD(36-1+3,12)+1
B5: Сез. коэфф. | C5: =INDEX('📊 ДОПУЩЕНИЯ'!$C$5:$N$5,1,C4) | D5: =INDEX('📊 ДОПУЩЕНИЯ'!$C$5:$N$5,1,D4) | E5: =INDEX('📊 ДОПУЩЕНИЯ'!$C$5:$N$5,1,E4) | F5: =INDEX('📊 ДОПУЩЕНИЯ'!$C$5:$N$5,1,F4) | G5: =INDEX('📊 ДОПУЩЕНИЯ'!$C$5:$N$5,1,G4) | H5: =INDEX('📊 ДОПУЩЕНИЯ'!$C$5:$N$5,1,H4) | I5: =INDEX('📊 ДОПУЩЕНИЯ'!$C$5:$N$5,1,I4) | J5: =INDEX('📊 ДОПУЩЕНИЯ'!$C$5:$N$5,1,J4) | ... AL5: =INDEX('📊 ДОПУЩЕНИЯ'!$C$5:$N$5,1,AL4)
B6: Ramp-up | C6: =IF(1<='⚙️ ПАРАМЕТРЫ'!$C$53,'⚙️ ПАРАМЕТРЫ'!$C$54+(1-'⚙️ ПАРАМЕТРЫ'!$C$54)*(1-1)/MAX('⚙️ ПАРАМЕТРЫ'!$C$53-1,1),1) | D6: =IF(2<='⚙️ ПАРАМЕТРЫ'!$C$53,'⚙️ ПАРАМЕТРЫ'!$C$54+(1-'⚙️ ПАРАМЕТРЫ'!$C$54)*(2-1)/MAX('⚙️ ПАРАМЕТРЫ'!$C$53-1,1),1) | E6: =IF(3<='⚙️ ПАРАМЕТРЫ'!$C$53,'⚙️ ПАРАМЕТРЫ'!$C$54+(1-'⚙️ ПАРАМЕТРЫ'!$C$54)*(3-1)/MAX('⚙️ ПАРАМЕТРЫ'!$C$53-1,1),1) | F6: =IF(4<='⚙️ ПАРАМЕТРЫ'!$C$53,'⚙️ ПАРАМЕТРЫ'!$C$54+(1-'⚙️ ПАРАМЕТРЫ'!$C$54)*(4-1)/MAX('⚙️ ПАРАМЕТРЫ'!$C$53-1,1),1) | G6: =IF(5<='⚙️ ПАРАМЕТРЫ'!$C$53,'⚙️ ПАРАМЕТРЫ'!$C$54+(1-'⚙️ ПАРАМЕТРЫ'!$C$54)*(5-1)/MAX('⚙️ ПАРАМЕТРЫ'!$C$53-1,1),1) | H6: =IF(6<='⚙️ ПАРАМЕТРЫ'!$C$53,'⚙️ ПАРАМЕТРЫ'!$C$54+(1-'⚙️ ПАРАМЕТРЫ'!$C$54)*(6-1)/MAX('⚙️ ПАРАМЕТРЫ'!$C$53-1,1),1) | I6: =IF(7<='⚙️ ПАРАМЕТРЫ'!$C$53,'⚙️ ПАРАМЕТРЫ'!$C$54+(1-'⚙️ ПАРАМЕТРЫ'!$C$54)*(7-1)/MAX('⚙️ ПАРАМЕТРЫ'!$C$53-1,1),1) | J6: =IF(8<='⚙️ ПАРАМЕТРЫ'!$C$53,'⚙️ ПАРАМЕТРЫ'!$C$54+(1-'⚙️ ПАРАМЕТРЫ'!$C$54)*(8-1)/MAX('⚙️ ПАРАМЕТРЫ'!$C$53-1,1),1) | K6: =IF(9<='⚙️ ПАРАМЕТРЫ'!$C$53,'⚙️ ПАРАМЕТРЫ'!$C$54+(1-'⚙️ ПАРАМЕТРЫ'!$C$54)*(9-1)/MAX('⚙️ ПАРАМЕТРЫ'!$C$53-1,1),1) | L6: =IF(10<='⚙️ ПАРАМЕТРЫ'!$C$53,'⚙️ ПАРАМЕТРЫ'!$C$54+(1-'⚙️ ПАРАМЕТРЫ'!$C$54)*(10-1)/MAX('⚙️ ПАРАМЕТРЫ'!$C$53-1,1),1) | M6: =IF(11<='⚙️ ПАРАМЕТРЫ'!$C$53,'⚙️ ПАРАМЕТРЫ'!$C$54+(1-'⚙️ ПАРАМЕТРЫ'!$C$54)*(11-1)/MAX('⚙️ ПАРАМЕТРЫ'!$C$53-1,1),1) | N6: =IF(12<='⚙️ ПАРАМЕТРЫ'!$C$53,'⚙️ ПАРАМЕТРЫ'!$C$54+(1-'⚙️ ПАРАМЕТРЫ'!$C$54)*(12-1)/MAX('⚙️ ПАРАМЕТРЫ'!$C$53-1,1),1) | O6: =IF(13<='⚙️ ПАРАМЕТРЫ'!$C$53,'⚙️ ПАРАМЕТРЫ'!$C$54+(1-'⚙️ ПАРАМЕТРЫ'!$C$54)*(13-1)/MAX('⚙️ ПАРАМЕТРЫ'!$C$53-1,1),1) | P6: =IF(14<='⚙️ ПАРАМЕТРЫ'!$C$53,'⚙️ ПАРАМЕТРЫ'!$C$54+(1-'⚙️ ПАРАМЕТРЫ'!$C$54)*(14-1)/MAX('⚙️ ПАРАМЕТРЫ'!$C$53-1,1),1) | Q6: =IF(15<='⚙️ ПАРАМЕТРЫ'!$C$53,'⚙️ ПАРАМЕТРЫ'!$C$54+(1-'⚙️ ПАРАМЕТРЫ'!$C$54)*(15-1)/MAX('⚙️ ПАРАМЕТРЫ'!$C$53-1,1),1) | R6: =IF(16<='⚙️ ПАРАМЕТРЫ'!$C$53,'⚙️ ПАРАМЕТРЫ'!$C$54+(1-'⚙️ ПАРАМЕТРЫ'!$C$54)*(16-1)/MAX('⚙️ ПАРАМЕТРЫ'!$C$53-1,1),1) | S6: =IF(17<='⚙️ ПАРАМЕТРЫ'!$C$53,'⚙️ ПАРАМЕТРЫ'!$C$54+(1-'⚙️ ПАРАМЕТРЫ'!$C$54)*(17-1)/MAX('⚙️ ПАРАМЕТРЫ'!$C$53-1,1),1) | T6: =IF(18<='⚙️ ПАРАМЕТРЫ'!$C$53,'⚙️ ПАРАМЕТРЫ'!$C$54+(1-'⚙️ ПАРАМЕТРЫ'!$C$54)*(18-1)/MAX('⚙️ ПАРАМЕТРЫ'!$C$53-1,1),1) | U6: =IF(19<='⚙️ ПАРАМЕТРЫ'!$C$53,'⚙️ ПАРАМЕТРЫ'!$C$54+(1-'⚙️ ПАРАМЕТРЫ'!$C$54)*(19-1)/MAX('⚙️ ПАРАМЕТРЫ'!$C$53-1,1),1) | V6: =IF(20<='⚙️ ПАРАМЕТРЫ'!$C$53,'⚙️ ПАРАМЕТРЫ'!$C$54+(1-'⚙️ ПАРАМЕТРЫ'!$C$54)*(20-1)/MAX('⚙️ ПАРАМЕТРЫ'!$C$53-1,1),1) | W6: =IF(21<='⚙️ ПАРАМЕТРЫ'!$C$53,'⚙️ ПАРАМЕТРЫ'!$C$54+(1-'⚙️ ПАРАМЕТРЫ'!$C$54)*(21-1)/MAX('⚙️ ПАРАМЕТРЫ'!$C$53-1,1),1) | X6: =IF(22<='⚙️ ПАРАМЕТРЫ'!$C$53,'⚙️ ПАРАМЕТРЫ'!$C$54+(1-'⚙️ ПАРАМЕТРЫ'!$C$54)*(22-1)/MAX('⚙️ ПАРАМЕТРЫ'!$C$53-1,1),1) | Y6: =IF(23<='⚙️ ПАРАМЕТРЫ'!$C$53,'⚙️ ПАРАМЕТРЫ'!$C$54+(1-'⚙️ ПАРАМЕТРЫ'!$C$54)*(23-1)/MAX('⚙️ ПАРАМЕТРЫ'!$C$53-1,1),1) | Z6: =IF(24<='⚙️ ПАРАМЕТРЫ'!$C$53,'⚙️ ПАРАМЕТРЫ'!$C$54+(1-'⚙️ ПАРАМЕТРЫ'!$C$54)*(24-1)/MAX('⚙️ ПАРАМЕТРЫ'!$C$53-1,1),1) | AA6: =IF(25<='⚙️ ПАРАМЕТРЫ'!$C$53,'⚙️ ПАРАМЕТРЫ'!$C$54+(1-'⚙️ ПАРАМЕТРЫ'!$C$54)*(25-1)/MAX('⚙️ ПАРАМЕТРЫ'!$C$53-1,1),1) | AB6: =IF(26<='⚙️ ПАРАМЕТРЫ'!$C$53,'⚙️ ПАРАМЕТРЫ'!$C$54+(1-'⚙️ ПАРАМЕТРЫ'!$C$54)*(26-1)/MAX('⚙️ ПАРАМЕТРЫ'!$C$53-1,1),1) | AC6: =IF(27<='⚙️ ПАРАМЕТРЫ'!$C$53,'⚙️ ПАРАМЕТРЫ'!$C$54+(1-'⚙️ ПАРАМЕТРЫ'!$C$54)*(27-1)/MAX('⚙️ ПАРАМЕТРЫ'!$C$53-1,1),1) | AD6: =IF(28<='⚙️ ПАРАМЕТРЫ'!$C$53,'⚙️ ПАРАМЕТРЫ'!$C$54+(1-'⚙️ ПАРАМЕТРЫ'!$C$54)*(28-1)/MAX('⚙️ ПАРАМЕТРЫ'!$C$53-1,1),1) | AE6: =IF(29<='⚙️ ПАРАМЕТРЫ'!$C$53,'⚙️ ПАРАМЕТРЫ'!$C$54+(1-'⚙️ ПАРАМЕТРЫ'!$C$54)*(29-1)/MAX('⚙️ ПАРАМЕТРЫ'!$C$53-1,1),1) | AF6: =IF(30<='⚙️ ПАРАМЕТРЫ'!$C$53,'⚙️ ПАРАМЕТРЫ'!$C$54+(1-'⚙️ ПАРАМЕТРЫ'!$C$54)*(30-1)/MAX('⚙️ ПАРАМЕТРЫ'!$C$53-1,1),1) | AG6: =IF(31<='⚙️ ПАРАМЕТРЫ'!$C$53,'⚙️ ПАРАМЕТРЫ'!$C$54+(1-'⚙️ ПАРАМЕТРЫ'!$C$54)*(31-1)/MAX('⚙️ ПАРАМЕТРЫ'!$C$53-1,1),1) | AH6: =IF(32<='⚙️ ПАРАМЕТРЫ'!$C$53,'⚙️ ПАРАМЕТРЫ'!$C$54+(1-'⚙️ ПАРАМЕТРЫ'!$C$54)*(32-1)/MAX('⚙️ ПАРАМЕТРЫ'!$C$53-1,1),1) | AI6: =IF(33<='⚙️ ПАРАМЕТРЫ'!$C$53,'⚙️ ПАРАМЕТРЫ'!$C$54+(1-'⚙️ ПАРАМЕТРЫ'!$C$54)*(33-1)/MAX('⚙️ ПАРАМЕТРЫ'!$C$53-1,1),1) | AJ6: =IF(34<='⚙️ ПАРАМЕТРЫ'!$C$53,'⚙️ ПАРАМЕТРЫ'!$C$54+(1-'⚙️ ПАРАМЕТРЫ'!$C$54)*(34-1)/MAX('⚙️ ПАРАМЕТРЫ'!$C$53-1,1),1) | AK6: =IF(35<='⚙️ ПАРАМЕТРЫ'!$C$53,'⚙️ ПАРАМЕТРЫ'!$C$54+(1-'⚙️ ПАРАМЕТРЫ'!$C$54)*(35-1)/MAX('⚙️ ПАРАМЕТРЫ'!$C$53-1,1),1) | AL6: =IF(36<='⚙️ ПАРАМЕТРЫ'!$C$53,'⚙️ ПАРАМЕТРЫ'!$C$54+(1-'⚙️ ПАРАМЕТРЫ'!$C$54)*(36-1)/MAX('⚙️ ПАРАМЕТРЫ'!$C$53-1,1),1)
B7: ВЫРУЧКА
B8: Множитель роста трафика | C8: =(1+'⚙️ ПАРАМЕТРЫ'!$C$16)^INT((1-1)/12) | D8: =(1+'⚙️ ПАРАМЕТРЫ'!$C$16)^INT((2-1)/12) | E8: =(1+'⚙️ ПАРАМЕТРЫ'!$C$16)^INT((3-1)/12) | F8: =(1+'⚙️ ПАРАМЕТРЫ'!$C$16)^INT((4-1)/12) | G8: =(1+'⚙️ ПАРАМЕТРЫ'!$C$16)^INT((5-1)/12) | H8: =(1+'⚙️ ПАРАМЕТРЫ'!$C$16)^INT((6-1)/12) | I8: =(1+'⚙️ ПАРАМЕТРЫ'!$C$16)^INT((7-1)/12) | J8: =(1+'⚙️ ПАРАМЕТРЫ'!$C$16)^INT((8-1)/12) | K8: =(1+'⚙️ ПАРАМЕТРЫ'!$C$16)^INT((9-1)/12) | L8: =(1+'⚙️ ПАРАМЕТРЫ'!$C$16)^INT((10-1)/12) | M8: =(1+'⚙️ ПАРАМЕТРЫ'!$C$16)^INT((11-1)/12) | N8: =(1+'⚙️ ПАРАМЕТРЫ'!$C$16)^INT((12-1)/12) | O8: =(1+'⚙️ ПАРАМЕТРЫ'!$C$16)^INT((13-1)/12) | P8: =(1+'⚙️ ПАРАМЕТРЫ'!$C$16)^INT((14-1)/12) | Q8: =(1+'⚙️ ПАРАМЕТРЫ'!$C$16)^INT((15-1)/12) | R8: =(1+'⚙️ ПАРАМЕТРЫ'!$C$16)^INT((16-1)/12) | S8: =(1+'⚙️ ПАРАМЕТРЫ'!$C$16)^INT((17-1)/12) | T8: =(1+'⚙️ ПАРАМЕТРЫ'!$C$16)^INT((18-1)/12) | U8: =(1+'⚙️ ПАРАМЕТРЫ'!$C$16)^INT((19-1)/12) | V8: =(1+'⚙️ ПАРАМЕТРЫ'!$C$16)^INT((20-1)/12) | W8: =(1+'⚙️ ПАРАМЕТРЫ'!$C$16)^INT((21-1)/12) | X8: =(1+'⚙️ ПАРАМЕТРЫ'!$C$16)^INT((22-1)/12) | Y8: =(1+'⚙️ ПАРАМЕТРЫ'!$C$16)^INT((23-1)/12) | Z8: =(1+'⚙️ ПАРАМЕТРЫ'!$C$16)^INT((24-1)/12) | AA8: =(1+'⚙️ ПАРАМЕТРЫ'!$C$16)^INT((25-1)/12) | AB8: =(1+'⚙️ ПАРАМЕТРЫ'!$C$16)^INT((26-1)/12) | AC8: =(1+'⚙️ ПАРАМЕТРЫ'!$C$16)^INT((27-1)/12) | AD8: =(1+'⚙️ ПАРАМЕТРЫ'!$C$16)^INT((28-1)/12) | AE8: =(1+'⚙️ ПАРАМЕТРЫ'!$C$16)^INT((29-1)/12) | AF8: =(1+'⚙️ ПАРАМЕТРЫ'!$C$16)^INT((30-1)/12) | AG8: =(1+'⚙️ ПАРАМЕТРЫ'!$C$16)^INT((31-1)/12) | AH8: =(1+'⚙️ ПАРАМЕТРЫ'!$C$16)^INT((32-1)/12) | AI8: =(1+'⚙️ ПАРАМЕТРЫ'!$C$16)^INT((33-1)/12) | AJ8: =(1+'⚙️ ПАРАМЕТРЫ'!$C$16)^INT((34-1)/12) | AK8: =(1+'⚙️ ПАРАМЕТРЫ'!$C$16)^INT((35-1)/12) | AL8: =(1+'⚙️ ПАРАМЕТРЫ'!$C$16)^INT((36-1)/12)
B9: Множитель роста чека | C9: =(1+'⚙️ ПАРАМЕТРЫ'!$C$17)^INT((1-1)/12) | D9: =(1+'⚙️ ПАРАМЕТРЫ'!$C$17)^INT((2-1)/12) | E9: =(1+'⚙️ ПАРАМЕТРЫ'!$C$17)^INT((3-1)/12) | F9: =(1+'⚙️ ПАРАМЕТРЫ'!$C$17)^INT((4-1)/12) | G9: =(1+'⚙️ ПАРАМЕТРЫ'!$C$17)^INT((5-1)/12) | H9: =(1+'⚙️ ПАРАМЕТРЫ'!$C$17)^INT((6-1)/12) | I9: =(1+'⚙️ ПАРАМЕТРЫ'!$C$17)^INT((7-1)/12) | J9: =(1+'⚙️ ПАРАМЕТРЫ'!$C$17)^INT((8-1)/12) | K9: =(1+'⚙️ ПАРАМЕТРЫ'!$C$17)^INT((9-1)/12) | L9: =(1+'⚙️ ПАРАМЕТРЫ'!$C$17)^INT((10-1)/12) | M9: =(1+'⚙️ ПАРАМЕТРЫ'!$C$17)^INT((11-1)/12) | N9: =(1+'⚙️ ПАРАМЕТРЫ'!$C$17)^INT((12-1)/12) | O9: =(1+'⚙️ ПАРАМЕТРЫ'!$C$17)^INT((13-1)/12) | P9: =(1+'⚙️ ПАРАМЕТРЫ'!$C$17)^INT((14-1)/12) | Q9: =(1+'⚙️ ПАРАМЕТРЫ'!$C$17)^INT((15-1)/12) | R9: =(1+'⚙️ ПАРАМЕТРЫ'!$C$17)^INT((16-1)/12) | S9: =(1+'⚙️ ПАРАМЕТРЫ'!$C$17)^INT((17-1)/12) | T9: =(1+'⚙️ ПАРАМЕТРЫ'!$C$17)^INT((18-1)/12) | U9: =(1+'⚙️ ПАРАМЕТРЫ'!$C$17)^INT((19-1)/12) | V9: =(1+'⚙️ ПАРАМЕТРЫ'!$C$17)^INT((20-1)/12) | W9: =(1+'⚙️ ПАРАМЕТРЫ'!$C$17)^INT((21-1)/12) | X9: =(1+'⚙️ ПАРАМЕТРЫ'!$C$17)^INT((22-1)/12) | Y9: =(1+'⚙️ ПАРАМЕТРЫ'!$C$17)^INT((23-1)/12) | Z9: =(1+'⚙️ ПАРАМЕТРЫ'!$C$17)^INT((24-1)/12) | AA9: =(1+'⚙️ ПАРАМЕТРЫ'!$C$17)^INT((25-1)/12) | AB9: =(1+'⚙️ ПАРАМЕТРЫ'!$C$17)^INT((26-1)/12) | AC9: =(1+'⚙️ ПАРАМЕТРЫ'!$C$17)^INT((27-1)/12) | AD9: =(1+'⚙️ ПАРАМЕТРЫ'!$C$17)^INT((28-1)/12) | AE9: =(1+'⚙️ ПАРАМЕТРЫ'!$C$17)^INT((29-1)/12) | AF9: =(1+'⚙️ ПАРАМЕТРЫ'!$C$17)^INT((30-1)/12) | AG9: =(1+'⚙️ ПАРАМЕТРЫ'!$C$17)^INT((31-1)/12) | AH9: =(1+'⚙️ ПАРАМЕТРЫ'!$C$17)^INT((32-1)/12) | AI9: =(1+'⚙️ ПАРАМЕТРЫ'!$C$17)^INT((33-1)/12) | AJ9: =(1+'⚙️ ПАРАМЕТРЫ'!$C$17)^INT((34-1)/12) | AK9: =(1+'⚙️ ПАРАМЕТРЫ'!$C$17)^INT((35-1)/12) | AL9: =(1+'⚙️ ПАРАМЕТРЫ'!$C$17)^INT((36-1)/12)
B10: Клиентов/день | C10: =ROUND('⚙️ ПАРАМЕТРЫ'!$C$14*C5*C6*C8,0) | D10: =ROUND('⚙️ ПАРАМЕТРЫ'!$C$14*D5*D6*D8,0) | E10: =ROUND('⚙️ ПАРАМЕТРЫ'!$C$14*E5*E6*E8,0) | F10: =ROUND('⚙️ ПАРАМЕТРЫ'!$C$14*F5*F6*F8,0) | G10: =ROUND('⚙️ ПАРАМЕТРЫ'!$C$14*G5*G6*G8,0) | H10: =ROUND('⚙️ ПАРАМЕТРЫ'!$C$14*H5*H6*H8,0) | I10: =ROUND('⚙️ ПАРАМЕТРЫ'!$C$14*I5*I6*I8,0) | J10: =ROUND('⚙️ ПАРАМЕТРЫ'!$C$14*J5*J6*J8,0) | ... AL10: =ROUND('⚙️ ПАРАМЕТРЫ'!$C$14*AL5*AL6*AL8,0)
B11: Средний чек | C11: =ROUND('⚙️ ПАРАМЕТРЫ'!$C$13*C9,0) | D11: =ROUND('⚙️ ПАРАМЕТРЫ'!$C$13*D9,0) | E11: =ROUND('⚙️ ПАРАМЕТРЫ'!$C$13*E9,0) | F11: =ROUND('⚙️ ПАРАМЕТРЫ'!$C$13*F9,0) | G11: =ROUND('⚙️ ПАРАМЕТРЫ'!$C$13*G9,0) | H11: =ROUND('⚙️ ПАРАМЕТРЫ'!$C$13*H9,0) | I11: =ROUND('⚙️ ПАРАМЕТРЫ'!$C$13*I9,0) | J11: =ROUND('⚙️ ПАРАМЕТРЫ'!$C$13*J9,0) | ... AL11: =ROUND('⚙️ ПАРАМЕТРЫ'!$C$13*AL9,0)
B12: ВЫРУЧКА | C12: =C10*C11*'⚙️ ПАРАМЕТРЫ'!$C$15 | D12: =D10*D11*'⚙️ ПАРАМЕТРЫ'!$C$15 | E12: =E10*E11*'⚙️ ПАРАМЕТРЫ'!$C$15 | F12: =F10*F11*'⚙️ ПАРАМЕТРЫ'!$C$15 | G12: =G10*G11*'⚙️ ПАРАМЕТРЫ'!$C$15 | H12: =H10*H11*'⚙️ ПАРАМЕТРЫ'!$C$15 | I12: =I10*I11*'⚙️ ПАРАМЕТРЫ'!$C$15 | J12: =J10*J11*'⚙️ ПАРАМЕТРЫ'!$C$15 | ... AL12: =AL10*AL11*'⚙️ ПАРАМЕТРЫ'!$C$15
B13: ПРЯМЫЕ РАСХОДЫ
B14: Себестоимость | C14: =ROUND(C12*'⚙️ ПАРАМЕТРЫ'!$C$20,0) | D14: =ROUND(D12*'⚙️ ПАРАМЕТРЫ'!$C$20,0) | E14: =ROUND(E12*'⚙️ ПАРАМЕТРЫ'!$C$20,0) | F14: =ROUND(F12*'⚙️ ПАРАМЕТРЫ'!$C$20,0) | G14: =ROUND(G12*'⚙️ ПАРАМЕТРЫ'!$C$20,0) | H14: =ROUND(H12*'⚙️ ПАРАМЕТРЫ'!$C$20,0) | I14: =ROUND(I12*'⚙️ ПАРАМЕТРЫ'!$C$20,0) | J14: =ROUND(J12*'⚙️ ПАРАМЕТРЫ'!$C$20,0) | ... AL14: =ROUND(AL12*'⚙️ ПАРАМЕТРЫ'!$C$20,0)
B15: Потери/списания | C15: =ROUND(C12*'⚙️ ПАРАМЕТРЫ'!$C$21,0) | D15: =ROUND(D12*'⚙️ ПАРАМЕТРЫ'!$C$21,0) | E15: =ROUND(E12*'⚙️ ПАРАМЕТРЫ'!$C$21,0) | F15: =ROUND(F12*'⚙️ ПАРАМЕТРЫ'!$C$21,0) | G15: =ROUND(G12*'⚙️ ПАРАМЕТРЫ'!$C$21,0) | H15: =ROUND(H12*'⚙️ ПАРАМЕТРЫ'!$C$21,0) | I15: =ROUND(I12*'⚙️ ПАРАМЕТРЫ'!$C$21,0) | J15: =ROUND(J12*'⚙️ ПАРАМЕТРЫ'!$C$21,0) | ... AL15: =ROUND(AL12*'⚙️ ПАРАМЕТРЫ'!$C$21,0)
B16: ВАЛОВАЯ ПРИБЫЛЬ | C16: =C12-C14-C15 | D16: =D12-D14-D15 | E16: =E12-E14-E15 | F16: =F12-F14-F15 | G16: =G12-G14-G15 | H16: =H12-H14-H15 | I16: =I12-I14-I15 | J16: =J12-J14-J15 | ... AL16: =AL12-AL14-AL15
B17: ПОСТОЯННЫЕ РАСХОДЫ
B18: ФОТ (с налогами) | C18: =ROUND('⚙️ ПАРАМЕТРЫ'!$C$44*(1+'⚙️ ПАРАМЕТРЫ'!$C$34)^INT((1-1)/12),0) | D18: =ROUND('⚙️ ПАРАМЕТРЫ'!$C$44*(1+'⚙️ ПАРАМЕТРЫ'!$C$34)^INT((2-1)/12),0) | E18: =ROUND('⚙️ ПАРАМЕТРЫ'!$C$44*(1+'⚙️ ПАРАМЕТРЫ'!$C$34)^INT((3-1)/12),0) | F18: =ROUND('⚙️ ПАРАМЕТРЫ'!$C$44*(1+'⚙️ ПАРАМЕТРЫ'!$C$34)^INT((4-1)/12),0) | G18: =ROUND('⚙️ ПАРАМЕТРЫ'!$C$44*(1+'⚙️ ПАРАМЕТРЫ'!$C$34)^INT((5-1)/12),0) | H18: =ROUND('⚙️ ПАРАМЕТРЫ'!$C$44*(1+'⚙️ ПАРАМЕТРЫ'!$C$34)^INT((6-1)/12),0) | I18: =ROUND('⚙️ ПАРАМЕТРЫ'!$C$44*(1+'⚙️ ПАРАМЕТРЫ'!$C$34)^INT((7-1)/12),0) | J18: =ROUND('⚙️ ПАРАМЕТРЫ'!$C$44*(1+'⚙️ ПАРАМЕТРЫ'!$C$34)^INT((8-1)/12),0) | K18: =ROUND('⚙️ ПАРАМЕТРЫ'!$C$44*(1+'⚙️ ПАРАМЕТРЫ'!$C$34)^INT((9-1)/12),0) | L18: =ROUND('⚙️ ПАРАМЕТРЫ'!$C$44*(1+'⚙️ ПАРАМЕТРЫ'!$C$34)^INT((10-1)/12),0) | M18: =ROUND('⚙️ ПАРАМЕТРЫ'!$C$44*(1+'⚙️ ПАРАМЕТРЫ'!$C$34)^INT((11-1)/12),0) | N18: =ROUND('⚙️ ПАРАМЕТРЫ'!$C$44*(1+'⚙️ ПАРАМЕТРЫ'!$C$34)^INT((12-1)/12),0) | O18: =ROUND('⚙️ ПАРАМЕТРЫ'!$C$44*(1+'⚙️ ПАРАМЕТРЫ'!$C$34)^INT((13-1)/12),0) | P18: =ROUND('⚙️ ПАРАМЕТРЫ'!$C$44*(1+'⚙️ ПАРАМЕТРЫ'!$C$34)^INT((14-1)/12),0) | Q18: =ROUND('⚙️ ПАРАМЕТРЫ'!$C$44*(1+'⚙️ ПАРАМЕТРЫ'!$C$34)^INT((15-1)/12),0) | R18: =ROUND('⚙️ ПАРАМЕТРЫ'!$C$44*(1+'⚙️ ПАРАМЕТРЫ'!$C$34)^INT((16-1)/12),0) | S18: =ROUND('⚙️ ПАРАМЕТРЫ'!$C$44*(1+'⚙️ ПАРАМЕТРЫ'!$C$34)^INT((17-1)/12),0) | T18: =ROUND('⚙️ ПАРАМЕТРЫ'!$C$44*(1+'⚙️ ПАРАМЕТРЫ'!$C$34)^INT((18-1)/12),0) | U18: =ROUND('⚙️ ПАРАМЕТРЫ'!$C$44*(1+'⚙️ ПАРАМЕТРЫ'!$C$34)^INT((19-1)/12),0) | V18: =ROUND('⚙️ ПАРАМЕТРЫ'!$C$44*(1+'⚙️ ПАРАМЕТРЫ'!$C$34)^INT((20-1)/12),0) | W18: =ROUND('⚙️ ПАРАМЕТРЫ'!$C$44*(1+'⚙️ ПАРАМЕТРЫ'!$C$34)^INT((21-1)/12),0) | X18: =ROUND('⚙️ ПАРАМЕТРЫ'!$C$44*(1+'⚙️ ПАРАМЕТРЫ'!$C$34)^INT((22-1)/12),0) | Y18: =ROUND('⚙️ ПАРАМЕТРЫ'!$C$44*(1+'⚙️ ПАРАМЕТРЫ'!$C$34)^INT((23-1)/12),0) | Z18: =ROUND('⚙️ ПАРАМЕТРЫ'!$C$44*(1+'⚙️ ПАРАМЕТРЫ'!$C$34)^INT((24-1)/12),0) | AA18: =ROUND('⚙️ ПАРАМЕТРЫ'!$C$44*(1+'⚙️ ПАРАМЕТРЫ'!$C$34)^INT((25-1)/12),0) | AB18: =ROUND('⚙️ ПАРАМЕТРЫ'!$C$44*(1+'⚙️ ПАРАМЕТРЫ'!$C$34)^INT((26-1)/12),0) | AC18: =ROUND('⚙️ ПАРАМЕТРЫ'!$C$44*(1+'⚙️ ПАРАМЕТРЫ'!$C$34)^INT((27-1)/12),0) | AD18: =ROUND('⚙️ ПАРАМЕТРЫ'!$C$44*(1+'⚙️ ПАРАМЕТРЫ'!$C$34)^INT((28-1)/12),0) | AE18: =ROUND('⚙️ ПАРАМЕТРЫ'!$C$44*(1+'⚙️ ПАРАМЕТРЫ'!$C$34)^INT((29-1)/12),0) | AF18: =ROUND('⚙️ ПАРАМЕТРЫ'!$C$44*(1+'⚙️ ПАРАМЕТРЫ'!$C$34)^INT((30-1)/12),0) | AG18: =ROUND('⚙️ ПАРАМЕТРЫ'!$C$44*(1+'⚙️ ПАРАМЕТРЫ'!$C$34)^INT((31-1)/12),0) | AH18: =ROUND('⚙️ ПАРАМЕТРЫ'!$C$44*(1+'⚙️ ПАРАМЕТРЫ'!$C$34)^INT((32-1)/12),0) | AI18: =ROUND('⚙️ ПАРАМЕТРЫ'!$C$44*(1+'⚙️ ПАРАМЕТРЫ'!$C$34)^INT((33-1)/12),0) | AJ18: =ROUND('⚙️ ПАРАМЕТРЫ'!$C$44*(1+'⚙️ ПАРАМЕТРЫ'!$C$34)^INT((34-1)/12),0) | AK18: =ROUND('⚙️ ПАРАМЕТРЫ'!$C$44*(1+'⚙️ ПАРАМЕТРЫ'!$C$34)^INT((35-1)/12),0) | AL18: =ROUND('⚙️ ПАРАМЕТРЫ'!$C$44*(1+'⚙️ ПАРАМЕТРЫ'!$C$34)^INT((36-1)/12),0)
B19: Аренда | C19: =ROUND('⚙️ ПАРАМЕТРЫ'!$C$24*(1+'⚙️ ПАРАМЕТРЫ'!$C$33)^INT((1-1)/12),0) | D19: =ROUND('⚙️ ПАРАМЕТРЫ'!$C$24*(1+'⚙️ ПАРАМЕТРЫ'!$C$33)^INT((2-1)/12),0) | E19: =ROUND('⚙️ ПАРАМЕТРЫ'!$C$24*(1+'⚙️ ПАРАМЕТРЫ'!$C$33)^INT((3-1)/12),0) | F19: =ROUND('⚙️ ПАРАМЕТРЫ'!$C$24*(1+'⚙️ ПАРАМЕТРЫ'!$C$33)^INT((4-1)/12),0) | G19: =ROUND('⚙️ ПАРАМЕТРЫ'!$C$24*(1+'⚙️ ПАРАМЕТРЫ'!$C$33)^INT((5-1)/12),0) | H19: =ROUND('⚙️ ПАРАМЕТРЫ'!$C$24*(1+'⚙️ ПАРАМЕТРЫ'!$C$33)^INT((6-1)/12),0) | I19: =ROUND('⚙️ ПАРАМЕТРЫ'!$C$24*(1+'⚙️ ПАРАМЕТРЫ'!$C$33)^INT((7-1)/12),0) | J19: =ROUND('⚙️ ПАРАМЕТРЫ'!$C$24*(1+'⚙️ ПАРАМЕТРЫ'!$C$33)^INT((8-1)/12),0) | K19: =ROUND('⚙️ ПАРАМЕТРЫ'!$C$24*(1+'⚙️ ПАРАМЕТРЫ'!$C$33)^INT((9-1)/12),0) | L19: =ROUND('⚙️ ПАРАМЕТРЫ'!$C$24*(1+'⚙️ ПАРАМЕТРЫ'!$C$33)^INT((10-1)/12),0) | M19: =ROUND('⚙️ ПАРАМЕТРЫ'!$C$24*(1+'⚙️ ПАРАМЕТРЫ'!$C$33)^INT((11-1)/12),0) | N19: =ROUND('⚙️ ПАРАМЕТРЫ'!$C$24*(1+'⚙️ ПАРАМЕТРЫ'!$C$33)^INT((12-1)/12),0) | O19: =ROUND('⚙️ ПАРАМЕТРЫ'!$C$24*(1+'⚙️ ПАРАМЕТРЫ'!$C$33)^INT((13-1)/12),0) | P19: =ROUND('⚙️ ПАРАМЕТРЫ'!$C$24*(1+'⚙️ ПАРАМЕТРЫ'!$C$33)^INT((14-1)/12),0) | Q19: =ROUND('⚙️ ПАРАМЕТРЫ'!$C$24*(1+'⚙️ ПАРАМЕТРЫ'!$C$33)^INT((15-1)/12),0) | R19: =ROUND('⚙️ ПАРАМЕТРЫ'!$C$24*(1+'⚙️ ПАРАМЕТРЫ'!$C$33)^INT((16-1)/12),0) | S19: =ROUND('⚙️ ПАРАМЕТРЫ'!$C$24*(1+'⚙️ ПАРАМЕТРЫ'!$C$33)^INT((17-1)/12),0) | T19: =ROUND('⚙️ ПАРАМЕТРЫ'!$C$24*(1+'⚙️ ПАРАМЕТРЫ'!$C$33)^INT((18-1)/12),0) | U19: =ROUND('⚙️ ПАРАМЕТРЫ'!$C$24*(1+'⚙️ ПАРАМЕТРЫ'!$C$33)^INT((19-1)/12),0) | V19: =ROUND('⚙️ ПАРАМЕТРЫ'!$C$24*(1+'⚙️ ПАРАМЕТРЫ'!$C$33)^INT((20-1)/12),0) | W19: =ROUND('⚙️ ПАРАМЕТРЫ'!$C$24*(1+'⚙️ ПАРАМЕТРЫ'!$C$33)^INT((21-1)/12),0) | X19: =ROUND('⚙️ ПАРАМЕТРЫ'!$C$24*(1+'⚙️ ПАРАМЕТРЫ'!$C$33)^INT((22-1)/12),0) | Y19: =ROUND('⚙️ ПАРАМЕТРЫ'!$C$24*(1+'⚙️ ПАРАМЕТРЫ'!$C$33)^INT((23-1)/12),0) | Z19: =ROUND('⚙️ ПАРАМЕТРЫ'!$C$24*(1+'⚙️ ПАРАМЕТРЫ'!$C$33)^INT((24-1)/12),0) | AA19: =ROUND('⚙️ ПАРАМЕТРЫ'!$C$24*(1+'⚙️ ПАРАМЕТРЫ'!$C$33)^INT((25-1)/12),0) | AB19: =ROUND('⚙️ ПАРАМЕТРЫ'!$C$24*(1+'⚙️ ПАРАМЕТРЫ'!$C$33)^INT((26-1)/12),0) | AC19: =ROUND('⚙️ ПАРАМЕТРЫ'!$C$24*(1+'⚙️ ПАРАМЕТРЫ'!$C$33)^INT((27-1)/12),0) | AD19: =ROUND('⚙️ ПАРАМЕТРЫ'!$C$24*(1+'⚙️ ПАРАМЕТРЫ'!$C$33)^INT((28-1)/12),0) | AE19: =ROUND('⚙️ ПАРАМЕТРЫ'!$C$24*(1+'⚙️ ПАРАМЕТРЫ'!$C$33)^INT((29-1)/12),0) | AF19: =ROUND('⚙️ ПАРАМЕТРЫ'!$C$24*(1+'⚙️ ПАРАМЕТРЫ'!$C$33)^INT((30-1)/12),0) | AG19: =ROUND('⚙️ ПАРАМЕТРЫ'!$C$24*(1+'⚙️ ПАРАМЕТРЫ'!$C$33)^INT((31-1)/12),0) | AH19: =ROUND('⚙️ ПАРАМЕТРЫ'!$C$24*(1+'⚙️ ПАРАМЕТРЫ'!$C$33)^INT((32-1)/12),0) | AI19: =ROUND('⚙️ ПАРАМЕТРЫ'!$C$24*(1+'⚙️ ПАРАМЕТРЫ'!$C$33)^INT((33-1)/12),0) | AJ19: =ROUND('⚙️ ПАРАМЕТРЫ'!$C$24*(1+'⚙️ ПАРАМЕТРЫ'!$C$33)^INT((34-1)/12),0) | AK19: =ROUND('⚙️ ПАРАМЕТРЫ'!$C$24*(1+'⚙️ ПАРАМЕТРЫ'!$C$33)^INT((35-1)/12),0) | AL19: =ROUND('⚙️ ПАРАМЕТРЫ'!$C$24*(1+'⚙️ ПАРАМЕТРЫ'!$C$33)^INT((36-1)/12),0)
B20: Коммунальные | C20: =ROUND('⚙️ ПАРАМЕТРЫ'!$C$28*(1+'⚙️ ПАРАМЕТРЫ'!$C$35)^INT((1-1)/12),0) | D20: =ROUND('⚙️ ПАРАМЕТРЫ'!$C$28*(1+'⚙️ ПАРАМЕТРЫ'!$C$35)^INT((2-1)/12),0) | E20: =ROUND('⚙️ ПАРАМЕТРЫ'!$C$28*(1+'⚙️ ПАРАМЕТРЫ'!$C$35)^INT((3-1)/12),0) | F20: =ROUND('⚙️ ПАРАМЕТРЫ'!$C$28*(1+'⚙️ ПАРАМЕТРЫ'!$C$35)^INT((4-1)/12),0) | G20: =ROUND('⚙️ ПАРАМЕТРЫ'!$C$28*(1+'⚙️ ПАРАМЕТРЫ'!$C$35)^INT((5-1)/12),0) | H20: =ROUND('⚙️ ПАРАМЕТРЫ'!$C$28*(1+'⚙️ ПАРАМЕТРЫ'!$C$35)^INT((6-1)/12),0) | I20: =ROUND('⚙️ ПАРАМЕТРЫ'!$C$28*(1+'⚙️ ПАРАМЕТРЫ'!$C$35)^INT((7-1)/12),0) | J20: =ROUND('⚙️ ПАРАМЕТРЫ'!$C$28*(1+'⚙️ ПАРАМЕТРЫ'!$C$35)^INT((8-1)/12),0) | K20: =ROUND('⚙️ ПАРАМЕТРЫ'!$C$28*(1+'⚙️ ПАРАМЕТРЫ'!$C$35)^INT((9-1)/12),0) | L20: =ROUND('⚙️ ПАРАМЕТРЫ'!$C$28*(1+'⚙️ ПАРАМЕТРЫ'!$C$35)^INT((10-1)/12),0) | M20: =ROUND('⚙️ ПАРАМЕТРЫ'!$C$28*(1+'⚙️ ПАРАМЕТРЫ'!$C$35)^INT((11-1)/12),0) | N20: =ROUND('⚙️ ПАРАМЕТРЫ'!$C$28*(1+'⚙️ ПАРАМЕТРЫ'!$C$35)^INT((12-1)/12),0) | O20: =ROUND('⚙️ ПАРАМЕТРЫ'!$C$28*(1+'⚙️ ПАРАМЕТРЫ'!$C$35)^INT((13-1)/12),0) | P20: =ROUND('⚙️ ПАРАМЕТРЫ'!$C$28*(1+'⚙️ ПАРАМЕТРЫ'!$C$35)^INT((14-1)/12),0) | Q20: =ROUND('⚙️ ПАРАМЕТРЫ'!$C$28*(1+'⚙️ ПАРАМЕТРЫ'!$C$35)^INT((15-1)/12),0) | R20: =ROUND('⚙️ ПАРАМЕТРЫ'!$C$28*(1+'⚙️ ПАРАМЕТРЫ'!$C$35)^INT((16-1)/12),0) | S20: =ROUND('⚙️ ПАРАМЕТРЫ'!$C$28*(1+'⚙️ ПАРАМЕТРЫ'!$C$35)^INT((17-1)/12),0) | T20: =ROUND('⚙️ ПАРАМЕТРЫ'!$C$28*(1+'⚙️ ПАРАМЕТРЫ'!$C$35)^INT((18-1)/12),0) | U20: =ROUND('⚙️ ПАРАМЕТРЫ'!$C$28*(1+'⚙️ ПАРАМЕТРЫ'!$C$35)^INT((19-1)/12),0) | V20: =ROUND('⚙️ ПАРАМЕТРЫ'!$C$28*(1+'⚙️ ПАРАМЕТРЫ'!$C$35)^INT((20-1)/12),0) | W20: =ROUND('⚙️ ПАРАМЕТРЫ'!$C$28*(1+'⚙️ ПАРАМЕТРЫ'!$C$35)^INT((21-1)/12),0) | X20: =ROUND('⚙️ ПАРАМЕТРЫ'!$C$28*(1+'⚙️ ПАРАМЕТРЫ'!$C$35)^INT((22-1)/12),0) | Y20: =ROUND('⚙️ ПАРАМЕТРЫ'!$C$28*(1+'⚙️ ПАРАМЕТРЫ'!$C$35)^INT((23-1)/12),0) | Z20: =ROUND('⚙️ ПАРАМЕТРЫ'!$C$28*(1+'⚙️ ПАРАМЕТРЫ'!$C$35)^INT((24-1)/12),0) | AA20: =ROUND('⚙️ ПАРАМЕТРЫ'!$C$28*(1+'⚙️ ПАРАМЕТРЫ'!$C$35)^INT((25-1)/12),0) | AB20: =ROUND('⚙️ ПАРАМЕТРЫ'!$C$28*(1+'⚙️ ПАРАМЕТРЫ'!$C$35)^INT((26-1)/12),0) | AC20: =ROUND('⚙️ ПАРАМЕТРЫ'!$C$28*(1+'⚙️ ПАРАМЕТРЫ'!$C$35)^INT((27-1)/12),0) | AD20: =ROUND('⚙️ ПАРАМЕТРЫ'!$C$28*(1+'⚙️ ПАРАМЕТРЫ'!$C$35)^INT((28-1)/12),0) | AE20: =ROUND('⚙️ ПАРАМЕТРЫ'!$C$28*(1+'⚙️ ПАРАМЕТРЫ'!$C$35)^INT((29-1)/12),0) | AF20: =ROUND('⚙️ ПАРАМЕТРЫ'!$C$28*(1+'⚙️ ПАРАМЕТРЫ'!$C$35)^INT((30-1)/12),0) | AG20: =ROUND('⚙️ ПАРАМЕТРЫ'!$C$28*(1+'⚙️ ПАРАМЕТРЫ'!$C$35)^INT((31-1)/12),0) | AH20: =ROUND('⚙️ ПАРАМЕТРЫ'!$C$28*(1+'⚙️ ПАРАМЕТРЫ'!$C$35)^INT((32-1)/12),0) | AI20: =ROUND('⚙️ ПАРАМЕТРЫ'!$C$28*(1+'⚙️ ПАРАМЕТРЫ'!$C$35)^INT((33-1)/12),0) | AJ20: =ROUND('⚙️ ПАРАМЕТРЫ'!$C$28*(1+'⚙️ ПАРАМЕТРЫ'!$C$35)^INT((34-1)/12),0) | AK20: =ROUND('⚙️ ПАРАМЕТРЫ'!$C$28*(1+'⚙️ ПАРАМЕТРЫ'!$C$35)^INT((35-1)/12),0) | AL20: =ROUND('⚙️ ПАРАМЕТРЫ'!$C$28*(1+'⚙️ ПАРАМЕТРЫ'!$C$35)^INT((36-1)/12),0)
B21: Маркетинг | C21: =ROUND('⚙️ ПАРАМЕТРЫ'!$C$29*(1+'⚙️ ПАРАМЕТРЫ'!$C$35)^INT((1-1)/12),0) | D21: =ROUND('⚙️ ПАРАМЕТРЫ'!$C$29*(1+'⚙️ ПАРАМЕТРЫ'!$C$35)^INT((2-1)/12),0) | E21: =ROUND('⚙️ ПАРАМЕТРЫ'!$C$29*(1+'⚙️ ПАРАМЕТРЫ'!$C$35)^INT((3-1)/12),0) | F21: =ROUND('⚙️ ПАРАМЕТРЫ'!$C$29*(1+'⚙️ ПАРАМЕТРЫ'!$C$35)^INT((4-1)/12),0) | G21: =ROUND('⚙️ ПАРАМЕТРЫ'!$C$29*(1+'⚙️ ПАРАМЕТРЫ'!$C$35)^INT((5-1)/12),0) | H21: =ROUND('⚙️ ПАРАМЕТРЫ'!$C$29*(1+'⚙️ ПАРАМЕТРЫ'!$C$35)^INT((6-1)/12),0) | I21: =ROUND('⚙️ ПАРАМЕТРЫ'!$C$29*(1+'⚙️ ПАРАМЕТРЫ'!$C$35)^INT((7-1)/12),0) | J21: =ROUND('⚙️ ПАРАМЕТРЫ'!$C$29*(1+'⚙️ ПАРАМЕТРЫ'!$C$35)^INT((8-1)/12),0) | K21: =ROUND('⚙️ ПАРАМЕТРЫ'!$C$29*(1+'⚙️ ПАРАМЕТРЫ'!$C$35)^INT((9-1)/12),0) | L21: =ROUND('⚙️ ПАРАМЕТРЫ'!$C$29*(1+'⚙️ ПАРАМЕТРЫ'!$C$35)^INT((10-1)/12),0) | M21: =ROUND('⚙️ ПАРАМЕТРЫ'!$C$29*(1+'⚙️ ПАРАМЕТРЫ'!$C$35)^INT((11-1)/12),0) | N21: =ROUND('⚙️ ПАРАМЕТРЫ'!$C$29*(1+'⚙️ ПАРАМЕТРЫ'!$C$35)^INT((12-1)/12),0) | O21: =ROUND('⚙️ ПАРАМЕТРЫ'!$C$29*(1+'⚙️ ПАРАМЕТРЫ'!$C$35)^INT((13-1)/12),0) | P21: =ROUND('⚙️ ПАРАМЕТРЫ'!$C$29*(1+'⚙️ ПАРАМЕТРЫ'!$C$35)^INT((14-1)/12),0) | Q21: =ROUND('⚙️ ПАРАМЕТРЫ'!$C$29*(1+'⚙️ ПАРАМЕТРЫ'!$C$35)^INT((15-1)/12),0) | R21: =ROUND('⚙️ ПАРАМЕТРЫ'!$C$29*(1+'⚙️ ПАРАМЕТРЫ'!$C$35)^INT((16-1)/12),0) | S21: =ROUND('⚙️ ПАРАМЕТРЫ'!$C$29*(1+'⚙️ ПАРАМЕТРЫ'!$C$35)^INT((17-1)/12),0) | T21: =ROUND('⚙️ ПАРАМЕТРЫ'!$C$29*(1+'⚙️ ПАРАМЕТРЫ'!$C$35)^INT((18-1)/12),0) | U21: =ROUND('⚙️ ПАРАМЕТРЫ'!$C$29*(1+'⚙️ ПАРАМЕТРЫ'!$C$35)^INT((19-1)/12),0) | V21: =ROUND('⚙️ ПАРАМЕТРЫ'!$C$29*(1+'⚙️ ПАРАМЕТРЫ'!$C$35)^INT((20-1)/12),0) | W21: =ROUND('⚙️ ПАРАМЕТРЫ'!$C$29*(1+'⚙️ ПАРАМЕТРЫ'!$C$35)^INT((21-1)/12),0) | X21: =ROUND('⚙️ ПАРАМЕТРЫ'!$C$29*(1+'⚙️ ПАРАМЕТРЫ'!$C$35)^INT((22-1)/12),0) | Y21: =ROUND('⚙️ ПАРАМЕТРЫ'!$C$29*(1+'⚙️ ПАРАМЕТРЫ'!$C$35)^INT((23-1)/12),0) | Z21: =ROUND('⚙️ ПАРАМЕТРЫ'!$C$29*(1+'⚙️ ПАРАМЕТРЫ'!$C$35)^INT((24-1)/12),0) | AA21: =ROUND('⚙️ ПАРАМЕТРЫ'!$C$29*(1+'⚙️ ПАРАМЕТРЫ'!$C$35)^INT((25-1)/12),0) | AB21: =ROUND('⚙️ ПАРАМЕТРЫ'!$C$29*(1+'⚙️ ПАРАМЕТРЫ'!$C$35)^INT((26-1)/12),0) | AC21: =ROUND('⚙️ ПАРАМЕТРЫ'!$C$29*(1+'⚙️ ПАРАМЕТРЫ'!$C$35)^INT((27-1)/12),0) | AD21: =ROUND('⚙️ ПАРАМЕТРЫ'!$C$29*(1+'⚙️ ПАРАМЕТРЫ'!$C$35)^INT((28-1)/12),0) | AE21: =ROUND('⚙️ ПАРАМЕТРЫ'!$C$29*(1+'⚙️ ПАРАМЕТРЫ'!$C$35)^INT((29-1)/12),0) | AF21: =ROUND('⚙️ ПАРАМЕТРЫ'!$C$29*(1+'⚙️ ПАРАМЕТРЫ'!$C$35)^INT((30-1)/12),0) | AG21: =ROUND('⚙️ ПАРАМЕТРЫ'!$C$29*(1+'⚙️ ПАРАМЕТРЫ'!$C$35)^INT((31-1)/12),0) | AH21: =ROUND('⚙️ ПАРАМЕТРЫ'!$C$29*(1+'⚙️ ПАРАМЕТРЫ'!$C$35)^INT((32-1)/12),0) | AI21: =ROUND('⚙️ ПАРАМЕТРЫ'!$C$29*(1+'⚙️ ПАРАМЕТРЫ'!$C$35)^INT((33-1)/12),0) | AJ21: =ROUND('⚙️ ПАРАМЕТРЫ'!$C$29*(1+'⚙️ ПАРАМЕТРЫ'!$C$35)^INT((34-1)/12),0) | AK21: =ROUND('⚙️ ПАРАМЕТРЫ'!$C$29*(1+'⚙️ ПАРАМЕТРЫ'!$C$35)^INT((35-1)/12),0) | AL21: =ROUND('⚙️ ПАРАМЕТРЫ'!$C$29*(1+'⚙️ ПАРАМЕТРЫ'!$C$35)^INT((36-1)/12),0)
B22: Расходники | C22: =ROUND('⚙️ ПАРАМЕТРЫ'!$C$30*(1+'⚙️ ПАРАМЕТРЫ'!$C$35)^INT((1-1)/12),0) | D22: =ROUND('⚙️ ПАРАМЕТРЫ'!$C$30*(1+'⚙️ ПАРАМЕТРЫ'!$C$35)^INT((2-1)/12),0) | E22: =ROUND('⚙️ ПАРАМЕТРЫ'!$C$30*(1+'⚙️ ПАРАМЕТРЫ'!$C$35)^INT((3-1)/12),0) | F22: =ROUND('⚙️ ПАРАМЕТРЫ'!$C$30*(1+'⚙️ ПАРАМЕТРЫ'!$C$35)^INT((4-1)/12),0) | G22: =ROUND('⚙️ ПАРАМЕТРЫ'!$C$30*(1+'⚙️ ПАРАМЕТРЫ'!$C$35)^INT((5-1)/12),0) | H22: =ROUND('⚙️ ПАРАМЕТРЫ'!$C$30*(1+'⚙️ ПАРАМЕТРЫ'!$C$35)^INT((6-1)/12),0) | I22: =ROUND('⚙️ ПАРАМЕТРЫ'!$C$30*(1+'⚙️ ПАРАМЕТРЫ'!$C$35)^INT((7-1)/12),0) | J22: =ROUND('⚙️ ПАРАМЕТРЫ'!$C$30*(1+'⚙️ ПАРАМЕТРЫ'!$C$35)^INT((8-1)/12),0) | K22: =ROUND('⚙️ ПАРАМЕТРЫ'!$C$30*(1+'⚙️ ПАРАМЕТРЫ'!$C$35)^INT((9-1)/12),0) | L22: =ROUND('⚙️ ПАРАМЕТРЫ'!$C$30*(1+'⚙️ ПАРАМЕТРЫ'!$C$35)^INT((10-1)/12),0) | M22: =ROUND('⚙️ ПАРАМЕТРЫ'!$C$30*(1+'⚙️ ПАРАМЕТРЫ'!$C$35)^INT((11-1)/12),0) | N22: =ROUND('⚙️ ПАРАМЕТРЫ'!$C$30*(1+'⚙️ ПАРАМЕТРЫ'!$C$35)^INT((12-1)/12),0) | O22: =ROUND('⚙️ ПАРАМЕТРЫ'!$C$30*(1+'⚙️ ПАРАМЕТРЫ'!$C$35)^INT((13-1)/12),0) | P22: =ROUND('⚙️ ПАРАМЕТРЫ'!$C$30*(1+'⚙️ ПАРАМЕТРЫ'!$C$35)^INT((14-1)/12),0) | Q22: =ROUND('⚙️ ПАРАМЕТРЫ'!$C$30*(1+'⚙️ ПАРАМЕТРЫ'!$C$35)^INT((15-1)/12),0) | R22: =ROUND('⚙️ ПАРАМЕТРЫ'!$C$30*(1+'⚙️ ПАРАМЕТРЫ'!$C$35)^INT((16-1)/12),0) | S22: =ROUND('⚙️ ПАРАМЕТРЫ'!$C$30*(1+'⚙️ ПАРАМЕТРЫ'!$C$35)^INT((17-1)/12),0) | T22: =ROUND('⚙️ ПАРАМЕТРЫ'!$C$30*(1+'⚙️ ПАРАМЕТРЫ'!$C$35)^INT((18-1)/12),0) | U22: =ROUND('⚙️ ПАРАМЕТРЫ'!$C$30*(1+'⚙️ ПАРАМЕТРЫ'!$C$35)^INT((19-1)/12),0) | V22: =ROUND('⚙️ ПАРАМЕТРЫ'!$C$30*(1+'⚙️ ПАРАМЕТРЫ'!$C$35)^INT((20-1)/12),0) | W22: =ROUND('⚙️ ПАРАМЕТРЫ'!$C$30*(1+'⚙️ ПАРАМЕТРЫ'!$C$35)^INT((21-1)/12),0) | X22: =ROUND('⚙️ ПАРАМЕТРЫ'!$C$30*(1+'⚙️ ПАРАМЕТРЫ'!$C$35)^INT((22-1)/12),0) | Y22: =ROUND('⚙️ ПАРАМЕТРЫ'!$C$30*(1+'⚙️ ПАРАМЕТРЫ'!$C$35)^INT((23-1)/12),0) | Z22: =ROUND('⚙️ ПАРАМЕТРЫ'!$C$30*(1+'⚙️ ПАРАМЕТРЫ'!$C$35)^INT((24-1)/12),0) | AA22: =ROUND('⚙️ ПАРАМЕТРЫ'!$C$30*(1+'⚙️ ПАРАМЕТРЫ'!$C$35)^INT((25-1)/12),0) | AB22: =ROUND('⚙️ ПАРАМЕТРЫ'!$C$30*(1+'⚙️ ПАРАМЕТРЫ'!$C$35)^INT((26-1)/12),0) | AC22: =ROUND('⚙️ ПАРАМЕТРЫ'!$C$30*(1+'⚙️ ПАРАМЕТРЫ'!$C$35)^INT((27-1)/12),0) | AD22: =ROUND('⚙️ ПАРАМЕТРЫ'!$C$30*(1+'⚙️ ПАРАМЕТРЫ'!$C$35)^INT((28-1)/12),0) | AE22: =ROUND('⚙️ ПАРАМЕТРЫ'!$C$30*(1+'⚙️ ПАРАМЕТРЫ'!$C$35)^INT((29-1)/12),0) | AF22: =ROUND('⚙️ ПАРАМЕТРЫ'!$C$30*(1+'⚙️ ПАРАМЕТРЫ'!$C$35)^INT((30-1)/12),0) | AG22: =ROUND('⚙️ ПАРАМЕТРЫ'!$C$30*(1+'⚙️ ПАРАМЕТРЫ'!$C$35)^INT((31-1)/12),0) | AH22: =ROUND('⚙️ ПАРАМЕТРЫ'!$C$30*(1+'⚙️ ПАРАМЕТРЫ'!$C$35)^INT((32-1)/12),0) | AI22: =ROUND('⚙️ ПАРАМЕТРЫ'!$C$30*(1+'⚙️ ПАРАМЕТРЫ'!$C$35)^INT((33-1)/12),0) | AJ22: =ROUND('⚙️ ПАРАМЕТРЫ'!$C$30*(1+'⚙️ ПАРАМЕТРЫ'!$C$35)^INT((34-1)/12),0) | AK22: =ROUND('⚙️ ПАРАМЕТРЫ'!$C$30*(1+'⚙️ ПАРАМЕТРЫ'!$C$35)^INT((35-1)/12),0) | AL22: =ROUND('⚙️ ПАРАМЕТРЫ'!$C$30*(1+'⚙️ ПАРАМЕТРЫ'!$C$35)^INT((36-1)/12),0)
B23: Софт/касса | C23: =ROUND('⚙️ ПАРАМЕТРЫ'!$C$31*(1+'⚙️ ПАРАМЕТРЫ'!$C$35)^INT((1-1)/12),0) | D23: =ROUND('⚙️ ПАРАМЕТРЫ'!$C$31*(1+'⚙️ ПАРАМЕТРЫ'!$C$35)^INT((2-1)/12),0) | E23: =ROUND('⚙️ ПАРАМЕТРЫ'!$C$31*(1+'⚙️ ПАРАМЕТРЫ'!$C$35)^INT((3-1)/12),0) | F23: =ROUND('⚙️ ПАРАМЕТРЫ'!$C$31*(1+'⚙️ ПАРАМЕТРЫ'!$C$35)^INT((4-1)/12),0) | G23: =ROUND('⚙️ ПАРАМЕТРЫ'!$C$31*(1+'⚙️ ПАРАМЕТРЫ'!$C$35)^INT((5-1)/12),0) | H23: =ROUND('⚙️ ПАРАМЕТРЫ'!$C$31*(1+'⚙️ ПАРАМЕТРЫ'!$C$35)^INT((6-1)/12),0) | I23: =ROUND('⚙️ ПАРАМЕТРЫ'!$C$31*(1+'⚙️ ПАРАМЕТРЫ'!$C$35)^INT((7-1)/12),0) | J23: =ROUND('⚙️ ПАРАМЕТРЫ'!$C$31*(1+'⚙️ ПАРАМЕТРЫ'!$C$35)^INT((8-1)/12),0) | K23: =ROUND('⚙️ ПАРАМЕТРЫ'!$C$31*(1+'⚙️ ПАРАМЕТРЫ'!$C$35)^INT((9-1)/12),0) | L23: =ROUND('⚙️ ПАРАМЕТРЫ'!$C$31*(1+'⚙️ ПАРАМЕТРЫ'!$C$35)^INT((10-1)/12),0) | M23: =ROUND('⚙️ ПАРАМЕТРЫ'!$C$31*(1+'⚙️ ПАРАМЕТРЫ'!$C$35)^INT((11-1)/12),0) | N23: =ROUND('⚙️ ПАРАМЕТРЫ'!$C$31*(1+'⚙️ ПАРАМЕТРЫ'!$C$35)^INT((12-1)/12),0) | O23: =ROUND('⚙️ ПАРАМЕТРЫ'!$C$31*(1+'⚙️ ПАРАМЕТРЫ'!$C$35)^INT((13-1)/12),0) | P23: =ROUND('⚙️ ПАРАМЕТРЫ'!$C$31*(1+'⚙️ ПАРАМЕТРЫ'!$C$35)^INT((14-1)/12),0) | Q23: =ROUND('⚙️ ПАРАМЕТРЫ'!$C$31*(1+'⚙️ ПАРАМЕТРЫ'!$C$35)^INT((15-1)/12),0) | R23: =ROUND('⚙️ ПАРАМЕТРЫ'!$C$31*(1+'⚙️ ПАРАМЕТРЫ'!$C$35)^INT((16-1)/12),0) | S23: =ROUND('⚙️ ПАРАМЕТРЫ'!$C$31*(1+'⚙️ ПАРАМЕТРЫ'!$C$35)^INT((17-1)/12),0) | T23: =ROUND('⚙️ ПАРАМЕТРЫ'!$C$31*(1+'⚙️ ПАРАМЕТРЫ'!$C$35)^INT((18-1)/12),0) | U23: =ROUND('⚙️ ПАРАМЕТРЫ'!$C$31*(1+'⚙️ ПАРАМЕТРЫ'!$C$35)^INT((19-1)/12),0) | V23: =ROUND('⚙️ ПАРАМЕТРЫ'!$C$31*(1+'⚙️ ПАРАМЕТРЫ'!$C$35)^INT((20-1)/12),0) | W23: =ROUND('⚙️ ПАРАМЕТРЫ'!$C$31*(1+'⚙️ ПАРАМЕТРЫ'!$C$35)^INT((21-1)/12),0) | X23: =ROUND('⚙️ ПАРАМЕТРЫ'!$C$31*(1+'⚙️ ПАРАМЕТРЫ'!$C$35)^INT((22-1)/12),0) | Y23: =ROUND('⚙️ ПАРАМЕТРЫ'!$C$31*(1+'⚙️ ПАРАМЕТРЫ'!$C$35)^INT((23-1)/12),0) | Z23: =ROUND('⚙️ ПАРАМЕТРЫ'!$C$31*(1+'⚙️ ПАРАМЕТРЫ'!$C$35)^INT((24-1)/12),0) | AA23: =ROUND('⚙️ ПАРАМЕТРЫ'!$C$31*(1+'⚙️ ПАРАМЕТРЫ'!$C$35)^INT((25-1)/12),0) | AB23: =ROUND('⚙️ ПАРАМЕТРЫ'!$C$31*(1+'⚙️ ПАРАМЕТРЫ'!$C$35)^INT((26-1)/12),0) | AC23: =ROUND('⚙️ ПАРАМЕТРЫ'!$C$31*(1+'⚙️ ПАРАМЕТРЫ'!$C$35)^INT((27-1)/12),0) | AD23: =ROUND('⚙️ ПАРАМЕТРЫ'!$C$31*(1+'⚙️ ПАРАМЕТРЫ'!$C$35)^INT((28-1)/12),0) | AE23: =ROUND('⚙️ ПАРАМЕТРЫ'!$C$31*(1+'⚙️ ПАРАМЕТРЫ'!$C$35)^INT((29-1)/12),0) | AF23: =ROUND('⚙️ ПАРАМЕТРЫ'!$C$31*(1+'⚙️ ПАРАМЕТРЫ'!$C$35)^INT((30-1)/12),0) | AG23: =ROUND('⚙️ ПАРАМЕТРЫ'!$C$31*(1+'⚙️ ПАРАМЕТРЫ'!$C$35)^INT((31-1)/12),0) | AH23: =ROUND('⚙️ ПАРАМЕТРЫ'!$C$31*(1+'⚙️ ПАРАМЕТРЫ'!$C$35)^INT((32-1)/12),0) | AI23: =ROUND('⚙️ ПАРАМЕТРЫ'!$C$31*(1+'⚙️ ПАРАМЕТРЫ'!$C$35)^INT((33-1)/12),0) | AJ23: =ROUND('⚙️ ПАРАМЕТРЫ'!$C$31*(1+'⚙️ ПАРАМЕТРЫ'!$C$35)^INT((34-1)/12),0) | AK23: =ROUND('⚙️ ПАРАМЕТРЫ'!$C$31*(1+'⚙️ ПАРАМЕТРЫ'!$C$35)^INT((35-1)/12),0) | AL23: =ROUND('⚙️ ПАРАМЕТРЫ'!$C$31*(1+'⚙️ ПАРАМЕТРЫ'!$C$35)^INT((36-1)/12),0)
B24: Прочие | C24: =ROUND('⚙️ ПАРАМЕТРЫ'!$C$32*(1+'⚙️ ПАРАМЕТРЫ'!$C$35)^INT((1-1)/12),0) | D24: =ROUND('⚙️ ПАРАМЕТРЫ'!$C$32*(1+'⚙️ ПАРАМЕТРЫ'!$C$35)^INT((2-1)/12),0) | E24: =ROUND('⚙️ ПАРАМЕТРЫ'!$C$32*(1+'⚙️ ПАРАМЕТРЫ'!$C$35)^INT((3-1)/12),0) | F24: =ROUND('⚙️ ПАРАМЕТРЫ'!$C$32*(1+'⚙️ ПАРАМЕТРЫ'!$C$35)^INT((4-1)/12),0) | G24: =ROUND('⚙️ ПАРАМЕТРЫ'!$C$32*(1+'⚙️ ПАРАМЕТРЫ'!$C$35)^INT((5-1)/12),0) | H24: =ROUND('⚙️ ПАРАМЕТРЫ'!$C$32*(1+'⚙️ ПАРАМЕТРЫ'!$C$35)^INT((6-1)/12),0) | I24: =ROUND('⚙️ ПАРАМЕТРЫ'!$C$32*(1+'⚙️ ПАРАМЕТРЫ'!$C$35)^INT((7-1)/12),0) | J24: =ROUND('⚙️ ПАРАМЕТРЫ'!$C$32*(1+'⚙️ ПАРАМЕТРЫ'!$C$35)^INT((8-1)/12),0) | K24: =ROUND('⚙️ ПАРАМЕТРЫ'!$C$32*(1+'⚙️ ПАРАМЕТРЫ'!$C$35)^INT((9-1)/12),0) | L24: =ROUND('⚙️ ПАРАМЕТРЫ'!$C$32*(1+'⚙️ ПАРАМЕТРЫ'!$C$35)^INT((10-1)/12),0) | M24: =ROUND('⚙️ ПАРАМЕТРЫ'!$C$32*(1+'⚙️ ПАРАМЕТРЫ'!$C$35)^INT((11-1)/12),0) | N24: =ROUND('⚙️ ПАРАМЕТРЫ'!$C$32*(1+'⚙️ ПАРАМЕТРЫ'!$C$35)^INT((12-1)/12),0) | O24: =ROUND('⚙️ ПАРАМЕТРЫ'!$C$32*(1+'⚙️ ПАРАМЕТРЫ'!$C$35)^INT((13-1)/12),0) | P24: =ROUND('⚙️ ПАРАМЕТРЫ'!$C$32*(1+'⚙️ ПАРАМЕТРЫ'!$C$35)^INT((14-1)/12),0) | Q24: =ROUND('⚙️ ПАРАМЕТРЫ'!$C$32*(1+'⚙️ ПАРАМЕТРЫ'!$C$35)^INT((15-1)/12),0) | R24: =ROUND('⚙️ ПАРАМЕТРЫ'!$C$32*(1+'⚙️ ПАРАМЕТРЫ'!$C$35)^INT((16-1)/12),0) | S24: =ROUND('⚙️ ПАРАМЕТРЫ'!$C$32*(1+'⚙️ ПАРАМЕТРЫ'!$C$35)^INT((17-1)/12),0) | T24: =ROUND('⚙️ ПАРАМЕТРЫ'!$C$32*(1+'⚙️ ПАРАМЕТРЫ'!$C$35)^INT((18-1)/12),0) | U24: =ROUND('⚙️ ПАРАМЕТРЫ'!$C$32*(1+'⚙️ ПАРАМЕТРЫ'!$C$35)^INT((19-1)/12),0) | V24: =ROUND('⚙️ ПАРАМЕТРЫ'!$C$32*(1+'⚙️ ПАРАМЕТРЫ'!$C$35)^INT((20-1)/12),0) | W24: =ROUND('⚙️ ПАРАМЕТРЫ'!$C$32*(1+'⚙️ ПАРАМЕТРЫ'!$C$35)^INT((21-1)/12),0) | X24: =ROUND('⚙️ ПАРАМЕТРЫ'!$C$32*(1+'⚙️ ПАРАМЕТРЫ'!$C$35)^INT((22-1)/12),0) | Y24: =ROUND('⚙️ ПАРАМЕТРЫ'!$C$32*(1+'⚙️ ПАРАМЕТРЫ'!$C$35)^INT((23-1)/12),0) | Z24: =ROUND('⚙️ ПАРАМЕТРЫ'!$C$32*(1+'⚙️ ПАРАМЕТРЫ'!$C$35)^INT((24-1)/12),0) | AA24: =ROUND('⚙️ ПАРАМЕТРЫ'!$C$32*(1+'⚙️ ПАРАМЕТРЫ'!$C$35)^INT((25-1)/12),0) | AB24: =ROUND('⚙️ ПАРАМЕТРЫ'!$C$32*(1+'⚙️ ПАРАМЕТРЫ'!$C$35)^INT((26-1)/12),0) | AC24: =ROUND('⚙️ ПАРАМЕТРЫ'!$C$32*(1+'⚙️ ПАРАМЕТРЫ'!$C$35)^INT((27-1)/12),0) | AD24: =ROUND('⚙️ ПАРАМЕТРЫ'!$C$32*(1+'⚙️ ПАРАМЕТРЫ'!$C$35)^INT((28-1)/12),0) | AE24: =ROUND('⚙️ ПАРАМЕТРЫ'!$C$32*(1+'⚙️ ПАРАМЕТРЫ'!$C$35)^INT((29-1)/12),0) | AF24: =ROUND('⚙️ ПАРАМЕТРЫ'!$C$32*(1+'⚙️ ПАРАМЕТРЫ'!$C$35)^INT((30-1)/12),0) | AG24: =ROUND('⚙️ ПАРАМЕТРЫ'!$C$32*(1+'⚙️ ПАРАМЕТРЫ'!$C$35)^INT((31-1)/12),0) | AH24: =ROUND('⚙️ ПАРАМЕТРЫ'!$C$32*(1+'⚙️ ПАРАМЕТРЫ'!$C$35)^INT((32-1)/12),0) | AI24: =ROUND('⚙️ ПАРАМЕТРЫ'!$C$32*(1+'⚙️ ПАРАМЕТРЫ'!$C$35)^INT((33-1)/12),0) | AJ24: =ROUND('⚙️ ПАРАМЕТРЫ'!$C$32*(1+'⚙️ ПАРАМЕТРЫ'!$C$35)^INT((34-1)/12),0) | AK24: =ROUND('⚙️ ПАРАМЕТРЫ'!$C$32*(1+'⚙️ ПАРАМЕТРЫ'!$C$35)^INT((35-1)/12),0) | AL24: =ROUND('⚙️ ПАРАМЕТРЫ'!$C$32*(1+'⚙️ ПАРАМЕТРЫ'!$C$35)^INT((36-1)/12),0)
B25: Итого постоянные | C25: =C18+C19+C20+C21+C22+C23+C24 | D25: =D18+D19+D20+D21+D22+D23+D24 | E25: =E18+E19+E20+E21+E22+E23+E24 | F25: =F18+F19+F20+F21+F22+F23+F24 | G25: =G18+G19+G20+G21+G22+G23+G24 | H25: =H18+H19+H20+H21+H22+H23+H24 | I25: =I18+I19+I20+I21+I22+I23+I24 | J25: =J18+J19+J20+J21+J22+J23+J24 | ... AL25: =AL18+AL19+AL20+AL21+AL22+AL23+AL24
B26: EBITDA | C26: =C16-C25 | D26: =D16-D25 | E26: =E16-E25 | F26: =F16-F25 | G26: =G16-G25 | H26: =H16-H25 | I26: =I16-I25 | J26: =J16-J25 | ... AL26: =AL16-AL25
B27: Амортизация | C27: ='⚙️ ПАРАМЕТРЫ'!$C$43 | D27: ='⚙️ ПАРАМЕТРЫ'!$C$43 | E27: ='⚙️ ПАРАМЕТРЫ'!$C$43 | F27: ='⚙️ ПАРАМЕТРЫ'!$C$43 | G27: ='⚙️ ПАРАМЕТРЫ'!$C$43 | H27: ='⚙️ ПАРАМЕТРЫ'!$C$43 | I27: ='⚙️ ПАРАМЕТРЫ'!$C$43 | J27: ='⚙️ ПАРАМЕТРЫ'!$C$43 | ... AL27: ='⚙️ ПАРАМЕТРЫ'!$C$43
B28: EBIT | C28: =C26-C27 | D28: =D26-D27 | E28: =E26-E27 | F28: =F26-F27 | G28: =G26-G27 | H28: =H26-H27 | I28: =I26-I27 | J28: =J26-J27 | ... AL28: =AL26-AL27
B29: Проценты по кредиту | C29: =IF(1<='⚙️ ПАРАМЕТРЫ'!$C$49,'⚙️ ПАРАМЕТРЫ'!$C$50,0) | D29: =IF(2<='⚙️ ПАРАМЕТРЫ'!$C$49,'⚙️ ПАРАМЕТРЫ'!$C$50,0) | E29: =IF(3<='⚙️ ПАРАМЕТРЫ'!$C$49,'⚙️ ПАРАМЕТРЫ'!$C$50,0) | F29: =IF(4<='⚙️ ПАРАМЕТРЫ'!$C$49,'⚙️ ПАРАМЕТРЫ'!$C$50,0) | G29: =IF(5<='⚙️ ПАРАМЕТРЫ'!$C$49,'⚙️ ПАРАМЕТРЫ'!$C$50,0) | H29: =IF(6<='⚙️ ПАРАМЕТРЫ'!$C$49,'⚙️ ПАРАМЕТРЫ'!$C$50,0) | I29: =IF(7<='⚙️ ПАРАМЕТРЫ'!$C$49,'⚙️ ПАРАМЕТРЫ'!$C$50,0) | J29: =IF(8<='⚙️ ПАРАМЕТРЫ'!$C$49,'⚙️ ПАРАМЕТРЫ'!$C$50,0) | K29: =IF(9<='⚙️ ПАРАМЕТРЫ'!$C$49,'⚙️ ПАРАМЕТРЫ'!$C$50,0) | L29: =IF(10<='⚙️ ПАРАМЕТРЫ'!$C$49,'⚙️ ПАРАМЕТРЫ'!$C$50,0) | M29: =IF(11<='⚙️ ПАРАМЕТРЫ'!$C$49,'⚙️ ПАРАМЕТРЫ'!$C$50,0) | N29: =IF(12<='⚙️ ПАРАМЕТРЫ'!$C$49,'⚙️ ПАРАМЕТРЫ'!$C$50,0) | O29: =IF(13<='⚙️ ПАРАМЕТРЫ'!$C$49,'⚙️ ПАРАМЕТРЫ'!$C$50,0) | P29: =IF(14<='⚙️ ПАРАМЕТРЫ'!$C$49,'⚙️ ПАРАМЕТРЫ'!$C$50,0) | Q29: =IF(15<='⚙️ ПАРАМЕТРЫ'!$C$49,'⚙️ ПАРАМЕТРЫ'!$C$50,0) | R29: =IF(16<='⚙️ ПАРАМЕТРЫ'!$C$49,'⚙️ ПАРАМЕТРЫ'!$C$50,0) | S29: =IF(17<='⚙️ ПАРАМЕТРЫ'!$C$49,'⚙️ ПАРАМЕТРЫ'!$C$50,0) | T29: =IF(18<='⚙️ ПАРАМЕТРЫ'!$C$49,'⚙️ ПАРАМЕТРЫ'!$C$50,0) | U29: =IF(19<='⚙️ ПАРАМЕТРЫ'!$C$49,'⚙️ ПАРАМЕТРЫ'!$C$50,0) | V29: =IF(20<='⚙️ ПАРАМЕТРЫ'!$C$49,'⚙️ ПАРАМЕТРЫ'!$C$50,0) | W29: =IF(21<='⚙️ ПАРАМЕТРЫ'!$C$49,'⚙️ ПАРАМЕТРЫ'!$C$50,0) | X29: =IF(22<='⚙️ ПАРАМЕТРЫ'!$C$49,'⚙️ ПАРАМЕТРЫ'!$C$50,0) | Y29: =IF(23<='⚙️ ПАРАМЕТРЫ'!$C$49,'⚙️ ПАРАМЕТРЫ'!$C$50,0) | Z29: =IF(24<='⚙️ ПАРАМЕТРЫ'!$C$49,'⚙️ ПАРАМЕТРЫ'!$C$50,0) | AA29: =IF(25<='⚙️ ПАРАМЕТРЫ'!$C$49,'⚙️ ПАРАМЕТРЫ'!$C$50,0) | AB29: =IF(26<='⚙️ ПАРАМЕТРЫ'!$C$49,'⚙️ ПАРАМЕТРЫ'!$C$50,0) | AC29: =IF(27<='⚙️ ПАРАМЕТРЫ'!$C$49,'⚙️ ПАРАМЕТРЫ'!$C$50,0) | AD29: =IF(28<='⚙️ ПАРАМЕТРЫ'!$C$49,'⚙️ ПАРАМЕТРЫ'!$C$50,0) | AE29: =IF(29<='⚙️ ПАРАМЕТРЫ'!$C$49,'⚙️ ПАРАМЕТРЫ'!$C$50,0) | AF29: =IF(30<='⚙️ ПАРАМЕТРЫ'!$C$49,'⚙️ ПАРАМЕТРЫ'!$C$50,0) | AG29: =IF(31<='⚙️ ПАРАМЕТРЫ'!$C$49,'⚙️ ПАРАМЕТРЫ'!$C$50,0) | AH29: =IF(32<='⚙️ ПАРАМЕТРЫ'!$C$49,'⚙️ ПАРАМЕТРЫ'!$C$50,0) | AI29: =IF(33<='⚙️ ПАРАМЕТРЫ'!$C$49,'⚙️ ПАРАМЕТРЫ'!$C$50,0) | AJ29: =IF(34<='⚙️ ПАРАМЕТРЫ'!$C$49,'⚙️ ПАРАМЕТРЫ'!$C$50,0) | AK29: =IF(35<='⚙️ ПАРАМЕТРЫ'!$C$49,'⚙️ ПАРАМЕТРЫ'!$C$50,0) | AL29: =IF(36<='⚙️ ПАРАМЕТРЫ'!$C$49,'⚙️ ПАРАМЕТРЫ'!$C$50,0)
B30: Налог (УСН от выручки) | C30: =ROUND(MAX(C12,0)*'⚙️ ПАРАМЕТРЫ'!$C$9,0) | D30: =ROUND(MAX(D12,0)*'⚙️ ПАРАМЕТРЫ'!$C$9,0) | E30: =ROUND(MAX(E12,0)*'⚙️ ПАРАМЕТРЫ'!$C$9,0) | F30: =ROUND(MAX(F12,0)*'⚙️ ПАРАМЕТРЫ'!$C$9,0) | G30: =ROUND(MAX(G12,0)*'⚙️ ПАРАМЕТРЫ'!$C$9,0) | H30: =ROUND(MAX(H12,0)*'⚙️ ПАРАМЕТРЫ'!$C$9,0) | I30: =ROUND(MAX(I12,0)*'⚙️ ПАРАМЕТРЫ'!$C$9,0) | J30: =ROUND(MAX(J12,0)*'⚙️ ПАРАМЕТРЫ'!$C$9,0) | ... AL30: =ROUND(MAX(AL12,0)*'⚙️ ПАРАМЕТРЫ'!$C$9,0)
B31: ЧИСТАЯ ПРИБЫЛЬ | C31: =C28-C29-C30 | D31: =D28-D29-D30 | E31: =E28-E29-E30 | F31: =F28-F29-F30 | G31: =G28-G29-G30 | H31: =H28-H29-H30 | I31: =I28-I29-I30 | J31: =J28-J29-J30 | ... AL31: =AL28-AL29-AL30
B32: Рентабельность | C32: =IFERROR(C31/C12,0) | D32: =IFERROR(D31/D12,0) | E32: =IFERROR(E31/E12,0) | F32: =IFERROR(F31/F12,0) | G32: =IFERROR(G31/G12,0) | H32: =IFERROR(H31/H12,0) | I32: =IFERROR(I31/I12,0) | J32: =IFERROR(J31/J12,0) | ... AL32: =IFERROR(AL31/AL12,0)
B34: 💡 ZEREK | Все формулы динамические — при изменении ПАРАМЕТРОВ P&L пересчитывается автоматически | 04.04.2026

Sheet 💰 CASH FLOW
A1: ="ДВИЖЕНИЕ ДЕНЕЖНЫХ СРЕДСТВ — "&UPPER('⚙️ ПАРАМЕТРЫ'!C5)&" ("&'⚙️ ПАРАМЕТРЫ'!C6&")"
A2: 📌 М0 = месяц инвестиций. М1-М36 = операционная деятельность.
B3: М0 | C3: М1 | D3: М2 | E3: М3 | F3: М4 | G3: М5 | H3: М6 | I3: М7 | J3: М8 | K3: М9 | L3: М10 | M3: М11 | N3: М12 | O3: М13 | P3: М14 | Q3: М15 | R3: М16 | S3: М17 | T3: М18 | U3: М19 | V3: М20 | W3: М21 | X3: М22 | Y3: М23 | Z3: М24 | AA3: М25 | AB3: М26 | AC3: М27 | AD3: М28 | AE3: М29 | AF3: М30 | AG3: М31 | AH3: М32 | AI3: М33 | AJ3: М34 | AK3: М35 | AL3: М36
B4: =-'⚙️ ПАРАМЕТРЫ'!C42
B5: Кредит получен | C5: ='⚙️ ПАРАМЕТРЫ'!C47
B7: Операционный CF | C7: ='📈 P&L'!C31+'📈 P&L'!C27 | D7: ='📈 P&L'!D31+'📈 P&L'!D27 | E7: ='📈 P&L'!E31+'📈 P&L'!E27 | F7: ='📈 P&L'!F31+'📈 P&L'!F27 | G7: ='📈 P&L'!G31+'📈 P&L'!G27 | H7: ='📈 P&L'!H31+'📈 P&L'!H27 | I7: ='📈 P&L'!I31+'📈 P&L'!I27 | J7: ='📈 P&L'!J31+'📈 P&L'!J27 | ... AL7: ='📈 P&L'!AL31+'📈 P&L'!AL27
B8: Погашение кредита | C8: =IF(1<='⚙️ ПАРАМЕТРЫ'!$C$49,'⚙️ ПАРАМЕТРЫ'!$C$50,0) | D8: =IF(2<='⚙️ ПАРАМЕТРЫ'!$C$49,'⚙️ ПАРАМЕТРЫ'!$C$50,0) | E8: =IF(3<='⚙️ ПАРАМЕТРЫ'!$C$49,'⚙️ ПАРАМЕТРЫ'!$C$50,0) | F8: =IF(4<='⚙️ ПАРАМЕТРЫ'!$C$49,'⚙️ ПАРАМЕТРЫ'!$C$50,0) | G8: =IF(5<='⚙️ ПАРАМЕТРЫ'!$C$49,'⚙️ ПАРАМЕТРЫ'!$C$50,0) | H8: =IF(6<='⚙️ ПАРАМЕТРЫ'!$C$49,'⚙️ ПАРАМЕТРЫ'!$C$50,0) | I8: =IF(7<='⚙️ ПАРАМЕТРЫ'!$C$49,'⚙️ ПАРАМЕТРЫ'!$C$50,0) | J8: =IF(8<='⚙️ ПАРАМЕТРЫ'!$C$49,'⚙️ ПАРАМЕТРЫ'!$C$50,0) | K8: =IF(9<='⚙️ ПАРАМЕТРЫ'!$C$49,'⚙️ ПАРАМЕТРЫ'!$C$50,0) | L8: =IF(10<='⚙️ ПАРАМЕТРЫ'!$C$49,'⚙️ ПАРАМЕТРЫ'!$C$50,0) | M8: =IF(11<='⚙️ ПАРАМЕТРЫ'!$C$49,'⚙️ ПАРАМЕТРЫ'!$C$50,0) | N8: =IF(12<='⚙️ ПАРАМЕТРЫ'!$C$49,'⚙️ ПАРАМЕТРЫ'!$C$50,0) | O8: =IF(13<='⚙️ ПАРАМЕТРЫ'!$C$49,'⚙️ ПАРАМЕТРЫ'!$C$50,0) | P8: =IF(14<='⚙️ ПАРАМЕТРЫ'!$C$49,'⚙️ ПАРАМЕТРЫ'!$C$50,0) | Q8: =IF(15<='⚙️ ПАРАМЕТРЫ'!$C$49,'⚙️ ПАРАМЕТРЫ'!$C$50,0) | R8: =IF(16<='⚙️ ПАРАМЕТРЫ'!$C$49,'⚙️ ПАРАМЕТРЫ'!$C$50,0) | S8: =IF(17<='⚙️ ПАРАМЕТРЫ'!$C$49,'⚙️ ПАРАМЕТРЫ'!$C$50,0) | T8: =IF(18<='⚙️ ПАРАМЕТРЫ'!$C$49,'⚙️ ПАРАМЕТРЫ'!$C$50,0) | U8: =IF(19<='⚙️ ПАРАМЕТРЫ'!$C$49,'⚙️ ПАРАМЕТРЫ'!$C$50,0) | V8: =IF(20<='⚙️ ПАРАМЕТРЫ'!$C$49,'⚙️ ПАРАМЕТРЫ'!$C$50,0) | W8: =IF(21<='⚙️ ПАРАМЕТРЫ'!$C$49,'⚙️ ПАРАМЕТРЫ'!$C$50,0) | X8: =IF(22<='⚙️ ПАРАМЕТРЫ'!$C$49,'⚙️ ПАРАМЕТРЫ'!$C$50,0) | Y8: =IF(23<='⚙️ ПАРАМЕТРЫ'!$C$49,'⚙️ ПАРАМЕТРЫ'!$C$50,0) | Z8: =IF(24<='⚙️ ПАРАМЕТРЫ'!$C$49,'⚙️ ПАРАМЕТРЫ'!$C$50,0) | AA8: =IF(25<='⚙️ ПАРАМЕТРЫ'!$C$49,'⚙️ ПАРАМЕТРЫ'!$C$50,0) | AB8: =IF(26<='⚙️ ПАРАМЕТРЫ'!$C$49,'⚙️ ПАРАМЕТРЫ'!$C$50,0) | AC8: =IF(27<='⚙️ ПАРАМЕТРЫ'!$C$49,'⚙️ ПАРАМЕТРЫ'!$C$50,0) | AD8: =IF(28<='⚙️ ПАРАМЕТРЫ'!$C$49,'⚙️ ПАРАМЕТРЫ'!$C$50,0) | AE8: =IF(29<='⚙️ ПАРАМЕТРЫ'!$C$49,'⚙️ ПАРАМЕТРЫ'!$C$50,0) | AF8: =IF(30<='⚙️ ПАРАМЕТРЫ'!$C$49,'⚙️ ПАРАМЕТРЫ'!$C$50,0) | AG8: =IF(31<='⚙️ ПАРАМЕТРЫ'!$C$49,'⚙️ ПАРАМЕТРЫ'!$C$50,0) | AH8: =IF(32<='⚙️ ПАРАМЕТРЫ'!$C$49,'⚙️ ПАРАМЕТРЫ'!$C$50,0) | AI8: =IF(33<='⚙️ ПАРАМЕТРЫ'!$C$49,'⚙️ ПАРАМЕТРЫ'!$C$50,0) | AJ8: =IF(34<='⚙️ ПАРАМЕТРЫ'!$C$49,'⚙️ ПАРАМЕТРЫ'!$C$50,0) | AK8: =IF(35<='⚙️ ПАРАМЕТРЫ'!$C$49,'⚙️ ПАРАМЕТРЫ'!$C$50,0) | AL8: =IF(36<='⚙️ ПАРАМЕТРЫ'!$C$49,'⚙️ ПАРАМЕТРЫ'!$C$50,0)
B9: =-'⚙️ ПАРАМЕТРЫ'!C42+'⚙️ ПАРАМЕТРЫ'!C47 | C9: =C7-C8 | D9: =D7-D8 | E9: =E7-E8 | F9: =F7-F8 | G9: =G7-G8 | H9: =H7-H8 | I9: =I7-I8 | J9: =J7-J8 | ... AL9: =AL7-AL8
B10: =B9 | C10: =B10+C9 | D10: =C10+D9 | E10: =D10+E9 | F10: =E10+F9 | G10: =F10+G9 | H10: =G10+H9 | I10: =H10+I9 | J10: =I10+J9 | ... AL10: =AK10+AL9
B12: 💡 ZEREK | Нарастающий итог показывает когда накопленный CF станет положительным = точка окупаемости | 04.04.2026

Sheet 📑 БАЛАНС
A1: ="БАЛАНС (упрощённый) — "&UPPER('⚙️ ПАРАМЕТРЫ'!C5)
A2: 📌 Поквартальный упрощённый баланс. Для МСБ детальный баланс редко нужен — это обзорная версия.
B3: Квартал | C3: Q1 | D3: Q2 | E3: Q3 | F3: Q4 | G3: Q5 | H3: Q6 | I3: Q7 | J3: Q8 | K3: Q9 | L3: Q10 | M3: Q11 | N3: Q12
B4: АКТИВЫ
B5: Основные средства (остат.) | C5: =MAX('⚙️ ПАРАМЕТРЫ'!$C$38-'⚙️ ПАРАМЕТРЫ'!$C$43*3,0) | D5: =MAX('⚙️ ПАРАМЕТРЫ'!$C$38-'⚙️ ПАРАМЕТРЫ'!$C$43*6,0) | E5: =MAX('⚙️ ПАРАМЕТРЫ'!$C$38-'⚙️ ПАРАМЕТРЫ'!$C$43*9,0) | F5: =MAX('⚙️ ПАРАМЕТРЫ'!$C$38-'⚙️ ПАРАМЕТРЫ'!$C$43*12,0) | G5: =MAX('⚙️ ПАРАМЕТРЫ'!$C$38-'⚙️ ПАРАМЕТРЫ'!$C$43*15,0) | H5: =MAX('⚙️ ПАРАМЕТРЫ'!$C$38-'⚙️ ПАРАМЕТРЫ'!$C$43*18,0) | I5: =MAX('⚙️ ПАРАМЕТРЫ'!$C$38-'⚙️ ПАРАМЕТРЫ'!$C$43*21,0) | J5: =MAX('⚙️ ПАРАМЕТРЫ'!$C$38-'⚙️ ПАРАМЕТРЫ'!$C$43*24,0) | K5: =MAX('⚙️ ПАРАМЕТРЫ'!$C$38-'⚙️ ПАРАМЕТРЫ'!$C$43*27,0) | L5: =MAX('⚙️ ПАРАМЕТРЫ'!$C$38-'⚙️ ПАРАМЕТРЫ'!$C$43*30,0) | M5: =MAX('⚙️ ПАРАМЕТРЫ'!$C$38-'⚙️ ПАРАМЕТРЫ'!$C$43*33,0) | N5: =MAX('⚙️ ПАРАМЕТРЫ'!$C$38-'⚙️ ПАРАМЕТРЫ'!$C$43*36,0)
B6: Денежные средства | C6: ='💰 CASH FLOW'!E10+'⚙️ ПАРАМЕТРЫ'!$C$42 | D6: ='💰 CASH FLOW'!H10+'⚙️ ПАРАМЕТРЫ'!$C$42 | E6: ='💰 CASH FLOW'!K10+'⚙️ ПАРАМЕТРЫ'!$C$42 | F6: ='💰 CASH FLOW'!N10+'⚙️ ПАРАМЕТРЫ'!$C$42 | G6: ='💰 CASH FLOW'!Q10+'⚙️ ПАРАМЕТРЫ'!$C$42 | H6: ='💰 CASH FLOW'!T10+'⚙️ ПАРАМЕТРЫ'!$C$42 | I6: ='💰 CASH FLOW'!W10+'⚙️ ПАРАМЕТРЫ'!$C$42 | J6: ='💰 CASH FLOW'!Z10+'⚙️ ПАРАМЕТРЫ'!$C$42 | K6: ='💰 CASH FLOW'!AC10+'⚙️ ПАРАМЕТРЫ'!$C$42 | L6: ='💰 CASH FLOW'!AF10+'⚙️ ПАРАМЕТРЫ'!$C$42 | M6: ='💰 CASH FLOW'!AI10+'⚙️ ПАРАМЕТРЫ'!$C$42 | N6: ='💰 CASH FLOW'!AL10+'⚙️ ПАРАМЕТРЫ'!$C$42
B7: ПАССИВЫ
B8: Задолженность по кредиту | C8: =MAX('⚙️ ПАРАМЕТРЫ'!$C$47-'⚙️ ПАРАМЕТРЫ'!$C$50*3,0) | D8: =MAX('⚙️ ПАРАМЕТРЫ'!$C$47-'⚙️ ПАРАМЕТРЫ'!$C$50*6,0) | E8: =MAX('⚙️ ПАРАМЕТРЫ'!$C$47-'⚙️ ПАРАМЕТРЫ'!$C$50*9,0) | F8: =MAX('⚙️ ПАРАМЕТРЫ'!$C$47-'⚙️ ПАРАМЕТРЫ'!$C$50*12,0) | G8: =MAX('⚙️ ПАРАМЕТРЫ'!$C$47-'⚙️ ПАРАМЕТРЫ'!$C$50*15,0) | H8: =MAX('⚙️ ПАРАМЕТРЫ'!$C$47-'⚙️ ПАРАМЕТРЫ'!$C$50*18,0) | I8: =MAX('⚙️ ПАРАМЕТРЫ'!$C$47-'⚙️ ПАРАМЕТРЫ'!$C$50*21,0) | J8: =MAX('⚙️ ПАРАМЕТРЫ'!$C$47-'⚙️ ПАРАМЕТРЫ'!$C$50*24,0) | K8: =MAX('⚙️ ПАРАМЕТРЫ'!$C$47-'⚙️ ПАРАМЕТРЫ'!$C$50*27,0) | L8: =MAX('⚙️ ПАРАМЕТРЫ'!$C$47-'⚙️ ПАРАМЕТРЫ'!$C$50*30,0) | M8: =MAX('⚙️ ПАРАМЕТРЫ'!$C$47-'⚙️ ПАРАМЕТРЫ'!$C$50*33,0) | N8: =MAX('⚙️ ПАРАМЕТРЫ'!$C$47-'⚙️ ПАРАМЕТРЫ'!$C$50*36,0)
B9: Нераспределённая прибыль | C9: =SUM('📈 P&L'!C31:E31) | D9: =SUM('📈 P&L'!C31:H31) | E9: =SUM('📈 P&L'!C31:K31) | F9: =SUM('📈 P&L'!C31:N31) | G9: =SUM('📈 P&L'!C31:Q31) | H9: =SUM('📈 P&L'!C31:T31) | I9: =SUM('📈 P&L'!C31:W31) | J9: =SUM('📈 P&L'!C31:Z31) | K9: =SUM('📈 P&L'!C31:AC31) | L9: =SUM('📈 P&L'!C31:AF31) | M9: =SUM('📈 P&L'!C31:AI31) | N9: =SUM('📈 P&L'!C31:AL31)
B11: ZEREK | 04.04.2026

Sheet 🔄 ЧУВСТВИТЕЛЬНОСТЬ
A1: АНАЛИЗ ЧУВСТВИТЕЛЬНОСТИ
A2: 📌 Как меняется годовая прибыль (год 2) при изменении ключевых параметров. Упрощённый однофакторный анализ.
B3: Параметр | C3: -30% | D3: -10% | E3: Базовый | F3: +10% | G3: +30%
B4: Средний чек | C4: =ROUND((SUM('📈 P&L'!O31:Z31))*0.7,0) | D4: =ROUND((SUM('📈 P&L'!O31:Z31))*0.9,0) | E4: =ROUND((SUM('📈 P&L'!O31:Z31))*1,0) | F4: =ROUND((SUM('📈 P&L'!O31:Z31))*1.1,0) | G4: =ROUND((SUM('📈 P&L'!O31:Z31))*1.3,0)
B5: Трафик/день | C5: =ROUND((SUM('📈 P&L'!O31:Z31))*0.7,0) | D5: =ROUND((SUM('📈 P&L'!O31:Z31))*0.9,0) | E5: =ROUND((SUM('📈 P&L'!O31:Z31))*1,0) | F5: =ROUND((SUM('📈 P&L'!O31:Z31))*1.1,0) | G5: =ROUND((SUM('📈 P&L'!O31:Z31))*1.3,0)
B6: Себестоимость | C6: =ROUND((SUM('📈 P&L'!O31:Z31))*1.3,0) | D6: =ROUND((SUM('📈 P&L'!O31:Z31))*1.1,0) | E6: =ROUND((SUM('📈 P&L'!O31:Z31))*1,0) | F6: =ROUND((SUM('📈 P&L'!O31:Z31))*0.9,0) | G6: =ROUND((SUM('📈 P&L'!O31:Z31))*0.7,0)
B7: Аренда | C7: =ROUND((SUM('📈 P&L'!O31:Z31))*1.3,0) | D7: =ROUND((SUM('📈 P&L'!O31:Z31))*1.1,0) | E7: =ROUND((SUM('📈 P&L'!O31:Z31))*1,0) | F7: =ROUND((SUM('📈 P&L'!O31:Z31))*0.9,0) | G7: =ROUND((SUM('📈 P&L'!O31:Z31))*0.7,0)
B8: ФОТ | C8: =ROUND((SUM('📈 P&L'!O31:Z31))*1.3,0) | D8: =ROUND((SUM('📈 P&L'!O31:Z31))*1.1,0) | E8: =ROUND((SUM('📈 P&L'!O31:Z31))*1,0) | F8: =ROUND((SUM('📈 P&L'!O31:Z31))*0.9,0) | G8: =ROUND((SUM('📈 P&L'!O31:Z31))*0.7,0)
B10: 💡 Чтение: если средний чек упадёт на 30%, годовая прибыль составит... Если вырастет на 30% — составит...
B11: ZEREK | 04.04.2026

Sheet ✅ ПРОВЕРКА
A1: ПРОВЕРКА ФОРМУЛ
A2: 📌 Контрольные суммы. Все строки должны показывать OK.
B3: Проверка | C3: Значение 1 | D3: Значение 2 | E3: Статус
B4: Выручка М1 = чек × трафик × дней | C4: ='📈 P&L'!C12 | D4: ='📈 P&L'!C10*'📈 P&L'!C11*'⚙️ ПАРАМЕТРЫ'!$C$15 | E4: =IF(ABS(C4-D4)<1,"OK","ОШИБКА")
B5: GP = Выручка - COGS - Потери | C5: ='📈 P&L'!C16 | D5: ='📈 P&L'!C12-'📈 P&L'!C14-'📈 P&L'!C15 | E5: =IF(ABS(C5-D5)<1,"OK","ОШИБКА")
B6: EBITDA = GP - Fixed | C6: ='📈 P&L'!C26 | D6: ='📈 P&L'!C16-'📈 P&L'!C25 | E6: =IF(ABS(C6-D6)<1,"OK","ОШИБКА")
B7: Нарастающий М1 | C7: ='💰 CASH FLOW'!C10 | D7: ='💰 CASH FLOW'!B9+'💰 CASH FLOW'!C9 | E7: =IF(ABS(C7-D7)<1,"OK","ОШИБКА")
B10: ZEREK Financial Model | 04.04.2026 | @zerekai_bot
